Workbook

Sheet EVALUASI
A1: EVALUASI PER PEMBIMBING
A3: No | B3: Pembimbing | C3: Jumlah Pemagang | D3: Total Hari Kerja | E3: Total Hadir | F3: % Kehadiran | G3: Total Hari Terlambat | H3: % Tepat Waktu | I3: Tanpa Absen Pulang | J3: % Laporan Aktivitas | K3: Rata-rata Skor | L3: Predikat | M3: Skor Terendah | N3: Pemagang Skor Terendah | O3: key
A4: 1 | B4: =EVALUASI!D80 -> AHMAD JALALUDDIN BASYAR | C4: =COUNTIF(EVALUASI!$D$79:$D$132,$B4) -> 7 | D4: =SUMIFS(EVALUASI!$I$79:$I$132,EVALUASI!$D$79:$D$132,$B4) -> 408 | E4: =SUMIFS(EVALUASI!$J$79:$J$132,EVALUASI!$D$79:$D$132,$B4) -> 399 | F4: =IFERROR(E4/D4,0) -> 0.97794118 | G4: =SUMIFS(EVALUASI!$M$79:$M$132,EVALUASI!$D$79:$D$132,$B4) -> 64 | H4: =IFERROR(1-G4/SUMIFS(DETAIL!$M$2:$M$137,DETAIL!$C$2:$C$137,$B4),0) -> 0.84615385 | I4: =SUMIFS(EVALUASI!$P$79:$P$132,EVALUASI!$D$79:$D$132,$B4) -> 20 | J4: =IFERROR(SUMIFS(DETAIL!$Q$2:$Q$137,DETAIL!$C$2:$C$137,$B4)/SUMIFS(DETAIL!$M$2:$M$137,DETAIL!$C$2:$C$137,$B4),0) -> 0.87980769 | K4: =ROUND(AVERAGEIF(EVALUASI!$D$79:$D$132,$B4,EVALUASI!$W$79:$W$132),1) -> 85.1 | L4: =IF(K4>=100*SUMMARY!$C$14,"Sangat Baik",IF(K4>=100*SUMMARY!$C$15,"Baik",IF(K4>=100*SUMMARY!$C$16,"Cukup","Perlu Pembinaan"))) -> Baik | M4: =MIN(EVALUASI!$W$80:$W$86) -> 65.4 | N4: =INDEX(EVALUASI!$C$80:$C$86,MATCH(M4,EVALUASI!$W$80:$W$86,0)) -> WIDIYA DESY MAWAR SARI | O4: =K4-ROW()/100000 -> 85.09996
A5: 2 | B5: =EVALUASI!D88 -> AKHMAT ABIDIN | C5: =COUNTIF(EVALUASI!$D$79:$D$132,$B5) -> 1 | D5: =SUMIFS(EVALUASI!$I$79:$I$132,EVALUASI!$D$79:$D$132,$B5) -> 52 | E5: =SUMIFS(EVALUASI!$J$79:$J$132,EVALUASI!$D$79:$D$132,$B5) -> 48 | F5: =IFERROR(E5/D5,0) -> 0.92307692 | G5: =SUMIFS(EVALUASI!$M$79:$M$132,EVALUASI!$D$79:$D$132,$B5) -> 3 | H5: =IFERROR(1-G5/SUMIFS(DETAIL!$M$2:$M$137,DETAIL!$C$2:$C$137,$B5),0) -> 0.94444444 | I5: =SUMIFS(EVALUASI!$P$79:$P$132,EVALUASI!$D$79:$D$132,$B5) -> 5 | J5: =IFERROR(SUMIFS(DETAIL!$Q$2:$Q$137,DETAIL!$C$2:$C$137,$B5)/SUMIFS(DETAIL!$M$2:$M$137,DETAIL!$C$2:$C$137,$B5),0) -> 0.94444444 | K5: =ROUND(AVERAGEIF(EVALUASI!$D$79:$D$132,$B5,EVALUASI!$W$79:$W$132),1) -> 95.5 | L5: =IF(K5>=100*SUMMARY!$C$14,"Sangat Baik",IF(K5>=100*SUMMARY!$C$15,"Baik",IF(K5>=100*SUMMARY!$C$16,"Cukup","Perlu Pembinaan"))) -> Sangat Baik | M5: =MIN(EVALUASI!$W$88:$W$88) -> 95.5 | N5: =INDEX(EVALUASI!$C$88:$C$88,MATCH(M5,EVALUASI!$W$88:$W$88,0)) -> NURIKA AMELIA ROSYIDAH | O5: =K5-ROW()/100000 -> 95.49995
A6: 3 | B6: =EVALUASI!D90 -> ARIFANO KUSUMA BAYU | C6: =COUNTIF(EVALUASI!$D$79:$D$132,$B6) -> 1 | D6: =SUMIFS(EVALUASI!$I$79:$I$132,EVALUASI!$D$79:$D$132,$B6) -> 75 | E6: =SUMIFS(EVALUASI!$J$79:$J$132,EVALUASI!$D$79:$D$132,$B6) -> 71 | F6: =IFERROR(E6/D6,0) -> 0.94666667 | G6: =SUMIFS(EVALUASI!$M$79:$M$132,EVALUASI!$D$79:$D$132,$B6) -> 28 | H6: =IFERROR(1-G6/SUMIFS(DETAIL!$M$2:$M$137,DETAIL!$C$2:$C$137,$B6),0) -> 0.63636364 | I6: =SUMIFS(EVALUASI!$P$79:$P$132,EVALUASI!$D$79:$D$132,$B6) -> 3 | J6: =IFERROR(SUMIFS(DETAIL!$Q$2:$Q$137,DETAIL!$C$2:$C$137,$B6)/SUMIFS(DETAIL!$M$2:$M$137,DETAIL!$C$2:$C$137,$B6),0) -> 0.98701299 | K6: =ROUND(AVERAGEIF(EVALUASI!$D$79:$D$132,$B6,EVALUASI!$W$79:$W$132),1) -> 90.9 | L6: =IF(K6>=100*SUMMARY!$C$14,"Sangat Baik",IF(K6>=100*SUMMARY!$C$15,"Baik",IF(K6>=100*SUMMARY!$C$16,"Cukup","Perlu Pembinaan"))) -> Sangat Baik | M6: =MIN(EVALUASI!$W$90:$W$90) -> 90.9 | N6: =INDEX(EVALUASI!$C$90:$C$90,MATCH(M6,EVALUASI!$W$90:$W$90,0)) -> JANU PRASTYO | O6: =K6-ROW()/100000 -> 90.89994
A7: 4 | B7: =EVALUASI!D92 -> DIAN RIZKA SARI | C7: =COUNTIF(EVALUASI!$D$79:$D$132,$B7) -> 2 | D7: =SUMIFS(EVALUASI!$I$79:$I$132,EVALUASI!$D$79:$D$132,$B7) -> 65 | E7: =SUMIFS(EVALUASI!$J$79:$J$132,EVALUASI!$D$79:$D$132,$B7) -> 58 | F7: =IFERROR(E7/D7,0) -> 0.89230769 | G7: =SUMIFS(EVALUASI!$M$79:$M$132,EVALUASI!$D$79:$D$132,$B7) -> 0 | H7: =IFERROR(1-G7/SUMIFS(DETAIL!$M$2:$M$137,DETAIL!$C$2:$C$137,$B7),0) -> 1 | I7: =SUMIFS(EVALUASI!$P$79:$P$132,EVALUASI!$D$79:$D$132,$B7) -> 3 | J7: =IFERROR(SUMIFS(DETAIL!$Q$2:$Q$137,DETAIL!$C$2:$C$137,$B7)/SUMIFS(DETAIL!$M$2:$M$137,DETAIL!$C$2:$C$137,$B7),0) -> 0.98275862 | K7: =ROUND(AVERAGEIF(EVALUASI!$D$79:$D$132,$B7,EVALUASI!$W$79:$W$132),1) -> 81.4 | L7: =IF(K7>=100*SUMMARY!$C$14,"Sangat Baik",IF(K7>=100*SUMMARY!$C$15,"Baik",IF(K7>=100*SUMMARY!$C$16,"Cukup","Perlu Pembinaan"))) -> Baik | M7: =MIN(EVALUASI!$W$92:$W$93) -> 81.3 | N7: =INDEX(EVALUASI!$C$92:$C$93,MATCH(M7,EVALUASI!$W$92:$W$93,0)) -> NIKEN AURELIA SAPUTRI | O7: =K7-ROW()/100000 -> 81.39993
A8: 5 | B8: =EVALUASI!D95 -> DWI SULIASTARI | C8: =COUNTIF(EVALUASI!$D$79:$D$132,$B8) -> 2 | D8: =SUMIFS(EVALUASI!$I$79:$I$132,EVALUASI!$D$79:$D$132,$B8) -> 148 | E8: =SUMIFS(EVALUASI!$J$79:$J$132,EVALUASI!$D$79:$D$132,$B8) -> 138 | F8: =IFERROR(E8/D8,0) -> 0.93243243 | G8: =SUMIFS(EVALUASI!$M$79:$M$132,EVALUASI!$D$79:$D$132,$B8) -> 7 | H8: =IFERROR(1-G8/SUMIFS(DETAIL!$M$2:$M$137,DETAIL!$C$2:$C$137,$B8),0) -> 0.94927536 | I8: =SUMIFS(EVALUASI!$P$79:$P$132,EVALUASI!$D$79:$D$132,$B8) -> 6 | J8: =IFERROR(SUMIFS(DETAIL!$Q$2:$Q$137,DETAIL!$C$2:$C$137,$B8)/SUMIFS(DETAIL!$M$2:$M$137,DETAIL!$C$2:$C$137,$B8),0) -> 0.95652174 | K8: =ROUND(AVERAGEIF(EVALUASI!$D$79:$D$132,$B8,EVALUASI!$W$79:$W$132),1) -> 80.4 | L8: =IF(K8>=100*SUMMARY!$C$14,"Sangat Baik",IF(K8>=100*SUMMARY!$C$15,"Baik",IF(K8>=100*SUMMARY!$C$16,"Cukup","Perlu Pembinaan"))) -> Baik | M8: =MIN(EVALUASI!$W$95:$W$96) -> 77.7 | N8: =INDEX(EVALUASI!$C$95:$C$96,MATCH(M8,EVALUASI!$W$95:$W$96,0)) -> EKA PUTRI FEBRIANTI | O8: =K8-ROW()/100000 -> 80.39992
A9: 6 | B9: =EVALUASI!D98 -> ELFANO RANGGA PRATAMA | C9: =COUNTIF(EVALUASI!$D$79:$D$132,$B9) -> 1 | D9: =SUMIFS(EVALUASI!$I$79:$I$132,EVALUASI!$D$79:$D$132,$B9) -> 75 | E9: =SUMIFS(EVALUASI!$J$79:$J$132,EVALUASI!$D$79:$D$132,$B9) -> 70 | F9: =IFERROR(E9/D9,0) -> 0.93333333 | G9: =SUMIFS(EVALUASI!$M$79:$M$132,EVALUASI!$D$79:$D$132,$B9) -> 59 | H9: =IFERROR(1-G9/SUMIFS(DETAIL!$M$2:$M$137,DETAIL!$C$2:$C$137,$B9),0) -> 0.37234043 | I9: =SUMIFS(EVALUASI!$P$79:$P$132,EVALUASI!$D$79:$D$132,$B9) -> 1 | J9: =IFERROR(SUMIFS(DETAIL!$Q$2:$Q$137,DETAIL!$C$2:$C$137,$B9)/SUMIFS(DETAIL!$M$2:$M$137,DETAIL!$C$2:$C$137,$B9),0) -> 0.91489362 | K9: =ROUND(AVERAGEIF(EVALUASI!$D$79:$D$132,$B9,EVALUASI!$W$79:$W$132),1) -> 74.5 | L9: =IF(K9>=100*SUMMARY!$C$14,"Sangat Baik",IF(K9>=100*SUMMARY!$C$15,"Baik",IF(K9>=100*SUMMARY!$C$16,"Cukup","Perlu Pembinaan"))) -> Cukup | M9: =MIN(EVALUASI!$W$98:$W$98) -> 74.5 | N9: =INDEX(EVALUASI!$C$98:$C$98,MATCH(M9,EVALUASI!$W$98:$W$98,0)) -> FETI FATMAWATI | O9: =K9-ROW()/100000 -> 74.49991
A10: 7 | B10: =EVALUASI!D100 -> ENDAH YUNIA SRI WINDARI | C10: =COUNTIF(EVALUASI!$D$79:$D$132,$B10) -> 2 | D10: =SUMIFS(EVALUASI!$I$79:$I$132,EVALUASI!$D$79:$D$132,$B10) -> 72 | E10: =SUMIFS(EVALUASI!$J$79:$J$132,EVALUASI!$D$79:$D$132,$B10) -> 68 | F10: =IFERROR(E10/D10,0) -> 0.94444444 | G10: =SUMIFS(EVALUASI!$M$79:$M$132,EVALUASI!$D$79:$D$132,$B10) -> 2 | H10: =IFERROR(1-G10/SUMIFS(DETAIL!$M$2:$M$137,DETAIL!$C$2:$C$137,$B10),0) -> 0.97058824 | I10: =SUMIFS(EVALUASI!$P$79:$P$132,EVALUASI!$D$79:$D$132,$B10) -> 5 | J10: =IFERROR(SUMIFS(DETAIL!$Q$2:$Q$137,DETAIL!$C$2:$C$137,$B10)/SUMIFS(DETAIL!$M$2:$M$137,DETAIL!$C$2:$C$137,$B10),0) -> 1 | K10: =ROUND(AVERAGEIF(EVALUASI!$D$79:$D$132,$B10,EVALUASI!$W$79:$W$132),1) -> 97.8 | L10: =IF(K10>=100*SUMMARY!$C$14,"Sangat Baik",IF(K10>=100*SUMMARY!$C$15,"Baik",IF(K10>=100*SUMMARY!$C$16,"Cukup","Perlu Pembinaan"))) -> Sangat Baik | M10: =MIN(EVALUASI!$W$100:$W$101) -> 96.9 | N10: =INDEX(EVALUASI!$C$100:$C$101,MATCH(M10,EVALUASI!$W$100:$W$101,0)) -> AHMAD NOVAN JUNIARDY | O10: =K10-ROW()/100000 -> 97.7999
A11: 8 | B11: =EVALUASI!D103 -> FETI MUBAIYINI | C11: =COUNTIF(EVALUASI!$D$79:$D$132,$B11) -> 2 | D11: =SUMIFS(EVALUASI!$I$79:$I$132,EVALUASI!$D$79:$D$132,$B11) -> 90 | E11: =SUMIFS(EVALUASI!$J$79:$J$132,EVALUASI!$D$79:$D$132,$B11) -> 85 | F11: =IFERROR(E11/D11,0) -> 0.94444444 | G11: =SUMIFS(EVALUASI!$M$79:$M$132,EVALUASI!$D$79:$D$132,$B11) -> 3 | H11: =IFERROR(1-G11/SUMIFS(DETAIL!$M$2:$M$137,DETAIL!$C$2:$C$137,$B11),0) -> 0.96470588 | I11: =SUMIFS(EVALUASI!$P$79:$P$132,EVALUASI!$D$79:$D$132,$B11) -> 8 | J11: =IFERROR(SUMIFS(DETAIL!$Q$2:$Q$137,DETAIL!$C$2:$C$137,$B11)/SUMIFS(DETAIL!$M$2:$M$137,DETAIL!$C$2:$C$137,$B11),0) -> 0.95294118 | K11: =ROUND(AVERAGEIF(EVALUASI!$D$79:$D$132,$B11,EVALUASI!$W$79:$W$132),1) -> 84.9 | L11: =IF(K11>=100*SUMMARY!$C$14,"Sangat Baik",IF(K11>=100*SUMMARY!$C$15,"Baik",IF(K11>=100*SUMMARY!$C$16,"Cukup","Perlu Pembinaan"))) -> Baik | M11: =MIN(EVALUASI!$W$103:$W$104) -> 76.7 | N11: =INDEX(EVALUASI!$C$103:$C$104,MATCH(M11,EVALUASI!$W$103:$W$104,0)) -> SYACHIRA FARA NABILA | O11: =K11-ROW()/100000 -> 84.89989
A12: 9 | B12: =EVALUASI!D106 -> GANANG MUSYAFFA FAHMI | C12: =COUNTIF(EVALUASI!$D$79:$D$132,$B12) -> 1 | D12: =SUMIFS(EVALUASI!$I$79:$I$132,EVALUASI!$D$79:$D$132,$B12) -> 75 | E12: =SUMIFS(EVALUASI!$J$79:$J$132,EVALUASI!$D$79:$D$132,$B12) -> 71 | F12: =IFERROR(E12/D12,0) -> 0.94666667 | G12: =SUMIFS(EVALUASI!$M$79:$M$132,EVALUASI!$D$79:$D$132,$B12) -> 0 | H12: =IFERROR(1-G12/SUMIFS(DETAIL!$M$2:$M$137,DETAIL!$C$2:$C$137,$B12),0) -> 1 | I12: =SUMIFS(EVALUASI!$P$79:$P$132,EVALUASI!$D$79:$D$132,$B12) -> 5 | J12: =IFERROR(SUMIFS(DETAIL!$Q$2:$Q$137,DETAIL!$C$2:$C$137,$B12)/SUMIFS(DETAIL!$M$2:$M$137,DETAIL!$C$2:$C$137,$B12),0) -> 0.97368421 | K12: =ROUND(AVERAGEIF(EVALUASI!$D$79:$D$132,$B12,EVALUASI!$W$79:$W$132),1) -> 97.9 | L12: =IF(K12>=100*SUMMARY!$C$14,"Sangat Baik",IF(K12>=100*SUMMARY!$C$15,"Baik",IF(K12>=100*SUMMARY!$C$16,"Cukup","Perlu Pembinaan"))) -> Sangat Baik | M12: =MIN(EVALUASI!$W$106:$W$106) -> 97.9 | N12: =INDEX(EVALUASI!$C$106:$C$106,MATCH(M12,EVALUASI!$W$106:$W$106,0)) -> SELVI NURUL HASANAH | O12: =K12-ROW()/100000 -> 97.89988
A13: 10 | B13: =EVALUASI!D108 -> HASKIN AVIONATA | C13: =COUNTIF(EVALUASI!$D$79:$D$132,$B13) -> 1 | D13: =SUMIFS(EVALUASI!$I$79:$I$132,EVALUASI!$D$79:$D$132,$B13) -> 75 | E13: =SUMIFS(EVALUASI!$J$79:$J$132,EVALUASI!$D$79:$D$132,$B13) -> 64 | F13: =IFERROR(E13/D13,0) -> 0.85333333 | G13: =SUMIFS(EVALUASI!$M$79:$M$132,EVALUASI!$D$79:$D$132,$B13) -> 17 | H13: =IFERROR(1-G13/SUMIFS(DETAIL!$M$2:$M$137,DETAIL!$C$2:$C$137,$B13),0) -> 0.73846154 | I13: =SUMIFS(EVALUASI!$P$79:$P$132,EVALUASI!$D$79:$D$132,$B13) -> 3 | J13: =IFERROR(SUMIFS(DETAIL!$Q$2:$Q$137,DETAIL!$C$2:$C$137,$B13)/SUMIFS(DETAIL!$M$2:$M$137,DETAIL!$C$2:$C$137,$B13),0) -> 0.96923077 | K13: =ROUND(AVERAGEIF(EVALUASI!$D$79:$D$132,$B13,EVALUASI!$W$79:$W$132),1) -> 78.1 | L13: =IF(K13>=100*SUMMARY!$C$14,"Sangat Baik",IF(K13>=100*SUMMARY!$C$15,"Baik",IF(K13>=100*SUMMARY!$C$16,"Cukup","Perlu Pembinaan"))) -> Cukup | M13: =MIN(EVALUASI!$W$108:$W$108) -> 78.1 | N13: =INDEX(EVALUASI!$C$108:$C$108,MATCH(M13,EVALUASI!$W$108:$W$108,0)) -> FARREL ALWIN RAHMADHAN | O13: =K13-ROW()/100000 -> 78.09987
A14: 11 | B14: =EVALUASI!D110 -> IMAM SUBEKTI | C14: =COUNTIF(EVALUASI!$D$79:$D$132,$B14) -> 1 | D14: =SUMIFS(EVALUASI!$I$79:$I$132,EVALUASI!$D$79:$D$132,$B14) -> 20 | E14: =SUMIFS(EVALUASI!$J$79:$J$132,EVALUASI!$D$79:$D$132,$B14) -> 15 | F14: =IFERROR(E14/D14,0) -> 0.75 | G14: =SUMIFS(EVALUASI!$M$79:$M$132,EVALUASI!$D$79:$D$132,$B14) -> 8 | H14: =IFERROR(1-G14/SUMIFS(DETAIL!$M$2:$M$137,DETAIL!$C$2:$C$137,$B14),0) -> 0.46666667 | I14: =SUMIFS(EVALUASI!$P$79:$P$132,EVALUASI!$D$79:$D$132,$B14) -> 12 | J14: =IFERROR(SUMIFS(DETAIL!$Q$2:$Q$137,DETAIL!$C$2:$C$137,$B14)/SUMIFS(DETAIL!$M$2:$M$137,DETAIL!$C$2:$C$137,$B14),0) -> 0 | K14: =ROUND(AVERAGEIF(EVALUASI!$D$79:$D$132,$B14,EVALUASI!$W$79:$W$132),1) -> 31.8 | L14: =IF(K14>=100*SUMMARY!$C$14,"Sangat Baik",IF(K14>=100*SUMMARY!$C$15,"Baik",IF(K14>=100*SUMMARY!$C$16,"Cukup","Perlu Pembinaan"))) -> Perlu Pembinaan | M14: =MIN(EVALUASI!$W$110:$W$110) -> 31.8 | N14: =INDEX(EVALUASI!$C$110:$C$110,MATCH(M14,EVALUASI!$W$110:$W$110,0)) -> MASDUQI MUHAMMAD | O14: =K14-ROW()/100000 -> 31.79986
A15: 12 | B15: =EVALUASI!D112 -> IMANIAR PUTRI UTAMI | C15: =COUNTIF(EVALUASI!$D$79:$D$132,$B15) -> 1 | D15: =SUMIFS(EVALUASI!$I$79:$I$132,EVALUASI!$D$79:$D$132,$B15) -> 13 | E15: =SUMIFS(EVALUASI!$J$79:$J$132,EVALUASI!$D$79:$D$132,$B15) -> 13 | F15: =IFERROR(E15/D15,0) -> 1 | G15: =SUMIFS(EVALUASI!$M$79:$M$132,EVALUASI!$D$79:$D$132,$B15) -> 1 | H15: =IFERROR(1-G15/SUMIFS(DETAIL!$M$2:$M$137,DETAIL!$C$2:$C$137,$B15),0) -> 0.92307692 | I15: =SUMIFS(EVALUASI!$P$79:$P$132,EVALUASI!$D$79:$D$132,$B15) -> 0 | J15: =IFERROR(SUMIFS(DETAIL!$Q$2:$Q$137,DETAIL!$C$2:$C$137,$B15)/SUMIFS(DETAIL!$M$2:$M$137,DETAIL!$C$2:$C$137,$B15),0) -> 1 | K15: =ROUND(AVERAGEIF(EVALUASI!$D$79:$D$132,$B15,EVALUASI!$W$79:$W$132),1) -> 91.8 | L15: =IF(K15>=100*SUMMARY!$C$14,"Sangat Baik",IF(K15>=100*SUMMARY!$C$15,"Baik",IF(K15>=100*SUMMARY!$C$16,"Cukup","Perlu Pembinaan"))) -> Sangat Baik | M15: =MIN(EVALUASI!$W$112:$W$112) -> 91.8 | N15: =INDEX(EVALUASI!$C$112:$C$112,MATCH(M15,EVALUASI!$W$112:$W$112,0)) -> CITRA ANGGRAINI | O15: =K15-ROW()/100000 -> 91.79985
A16: 13 | B16: =EVALUASI!D114 -> M. RIZAD FAHRURI | C16: =COUNTIF(EVALUASI!$D$79:$D$132,$B16) -> 1 | D16: =SUMIFS(EVALUASI!$I$79:$I$132,EVALUASI!$D$79:$D$132,$B16) -> 75 | E16: =SUMIFS(EVALUASI!$J$79:$J$132,EVALUASI!$D$79:$D$132,$B16) -> 72 | F16: =IFERROR(E16/D16,0) -> 0.96 | G16: =SUMIFS(EVALUASI!$M$79:$M$132,EVALUASI!$D$79:$D$132,$B16) -> 0 | H16: =IFERROR(1-G16/SUMIFS(DETAIL!$M$2:$M$137,DETAIL!$C$2:$C$137,$B16),0) -> 1 | I16: =SUMIFS(EVALUASI!$P$79:$P$132,EVALUASI!$D$79:$D$132,$B16) -> 3 | J16: =IFERROR(SUMIFS(DETAIL!$Q$2:$Q$137,DETAIL!$C$2:$C$137,$B16)/SUMIFS(DETAIL!$M$2:$M$137,DETAIL!$C$2:$C$137,$B16),0) -> 0.98717949 | K16: =ROUND(AVERAGEIF(EVALUASI!$D$79:$D$132,$B16,EVALUASI!$W$79:$W$132),1) -> 98.5 | L16: =IF(K16>=100*SUMMARY!$C$14,"Sangat Baik",IF(K16>=100*SUMMARY!$C$15,"Baik",IF(K16>=100*SUMMARY!$C$16,"Cukup","Perlu Pembinaan"))) -> Sangat Baik | M16: =MIN(EVALUASI!$W$114:$W$114) -> 98.5 | N16: =INDEX(EVALUASI!$C$114:$C$114,MATCH(M16,EVALUASI!$W$114:$W$114,0)) -> KHOFIFATUNNABILAH | O16: =K16-ROW()/100000 -> 98.49984
A17: 14 | B17: =EVALUASI!D116 -> MOH. AGUS EFENDI | C17: =COUNTIF(EVALUASI!$D$79:$D$132,$B17) -> 2 | D17: =SUMIFS(EVALUASI!$I$79:$I$132,EVALUASI!$D$79:$D$132,$B17) -> 134 | E17: =SUMIFS(EVALUASI!$J$79:$J$132,EVALUASI!$D$79:$D$132,$B17) -> 128 | F17: =IFERROR(E17/D17,0) -> 0.95522388 | G17: =SUMIFS(EVALUASI!$M$79:$M$132,EVALUASI!$D$79:$D$132,$B17) -> 3 | H17: =IFERROR(1-G17/SUMIFS(DETAIL!$M$2:$M$137,DETAIL!$C$2:$C$137,$B17),0) -> 0.97794118 | I17: =SUMIFS(EVALUASI!$P$79:$P$132,EVALUASI!$D$79:$D$132,$B17) -> 3 | J17: =IFERROR(SUMIFS(DETAIL!$Q$2:$Q$137,DETAIL!$C$2:$C$137,$B17)/SUMIFS(DETAIL!$M$2:$M$137,DETAIL!$C$2:$C$137,$B17),0) -> 0.99264706 | K17: =ROUND(AVERAGEIF(EVALUASI!$D$79:$D$132,$B17,EVALUASI!$W$79:$W$132),1) -> 92.3 | L17: =IF(K17>=100*SUMMARY!$C$14,"Sangat Baik",IF(K17>=100*SUMMARY!$C$15,"Baik",IF(K17>=100*SUMMARY!$C$16,"Cukup","Perlu Pembinaan"))) -> Sangat Baik | M17: =MIN(EVALUASI!$W$116:$W$117) -> 85.6 | N17: =INDEX(EVALUASI!$C$116:$C$117,MATCH(M17,EVALUASI!$W$116:$W$117,0)) -> MUHAMMAD FATCHUL ALAM | O17: =K17-ROW()/100000 -> 92.29983
A18: 15 | B18: =EVALUASI!D119 -> MUHAMMAD SADULLAH | C18: =COUNTIF(EVALUASI!$D$79:$D$132,$B18) -> 1 | D18: =SUMIFS(EVALUASI!$I$79:$I$132,EVALUASI!$D$79:$D$132,$B18) -> 38 | E18: =SUMIFS(EVALUASI!$J$79:$J$132,EVALUASI!$D$79:$D$132,$B18) -> 38 | F18: =IFERROR(E18/D18,0) -> 1 | G18: =SUMIFS(EVALUASI!$M$79:$M$132,EVALUASI!$D$79:$D$132,$B18) -> 7 | H18: =IFERROR(1-G18/SUMIFS(DETAIL!$M$2:$M$137,DETAIL!$C$2:$C$137,$B18),0) -> 0.83333333 | I18: =SUMIFS(EVALUASI!$P$79:$P$132,EVALUASI!$D$79:$D$132,$B18) -> 2 | J18: =IFERROR(SUMIFS(DETAIL!$Q$2:$Q$137,DETAIL!$C$2:$C$137,$B18)/SUMIFS(DETAIL!$M$2:$M$137,DETAIL!$C$2:$C$137,$B18),0) -> 0.95238095 | K18: =ROUND(AVERAGEIF(EVALUASI!$D$79:$D$132,$B18,EVALUASI!$W$79:$W$132),1) -> 84.5 | L18: =IF(K18>=100*SUMMARY!$C$14,"Sangat Baik",IF(K18>=100*SUMMARY!$C$15,"Baik",IF(K18>=100*SUMMARY!$C$16,"Cukup","Perlu Pembinaan"))) -> Baik | M18: =MIN(EVALUASI!$W$119:$W$119) -> 84.5 | N18: =INDEX(EVALUASI!$C$119:$C$119,MATCH(M18,EVALUASI!$W$119:$W$119,0)) -> ASA AGHNIA ZAHIDA | O18: =K18-ROW()/100000 -> 84.49982
A19: 16 | B19: =EVALUASI!D121 -> SITI MUJAYANAH | C19: =COUNTIF(EVALUASI!$D$79:$D$132,$B19) -> 4 | D19: =SUMIFS(EVALUASI!$I$79:$I$132,EVALUASI!$D$79:$D$132,$B19) -> 166 | E19: =SUMIFS(EVALUASI!$J$79:$J$132,EVALUASI!$D$79:$D$132,$B19) -> 160 | F19: =IFERROR(E19/D19,0) -> 0.96385542 | G19: =SUMIFS(EVALUASI!$M$79:$M$132,EVALUASI!$D$79:$D$132,$B19) -> 6 | H19: =IFERROR(1-G19/SUMIFS(DETAIL!$M$2:$M$137,DETAIL!$C$2:$C$137,$B19),0) -> 0.96363636 | I19: =SUMIFS(EVALUASI!$P$79:$P$132,EVALUASI!$D$79:$D$132,$B19) -> 11 | J19: =IFERROR(SUMIFS(DETAIL!$Q$2:$Q$137,DETAIL!$C$2:$C$137,$B19)/SUMIFS(DETAIL!$M$2:$M$137,DETAIL!$C$2:$C$137,$B19),0) -> 0.95757576 | K19: =ROUND(AVERAGEIF(EVALUASI!$D$79:$D$132,$B19,EVALUASI!$W$79:$W$132),1) -> 90.8 | L19: =IF(K19>=100*SUMMARY!$C$14,"Sangat Baik",IF(K19>=100*SUMMARY!$C$15,"Baik",IF(K19>=100*SUMMARY!$C$16,"Cukup","Perlu Pembinaan"))) -> Sangat Baik | M19: =MIN(EVALUASI!$W$121:$W$124) -> 77.9 | N19: =INDEX(EVALUASI!$C$121:$C$124,MATCH(M19,EVALUASI!$W$121:$W$124,0)) -> RIZAL AKBAR ARDIANSYAH | O19: =K19-ROW()/100000 -> 90.79981
A20: 17 | B20: =EVALUASI!D126 -> TRI HARTANTO | C20: =COUNTIF(EVALUASI!$D$79:$D$132,$B20) -> 1 | D20: =SUMIFS(EVALUASI!$I$79:$I$132,EVALUASI!$D$79:$D$132,$B20) -> 13 | E20: =SUMIFS(EVALUASI!$J$79:$J$132,EVALUASI!$D$79:$D$132,$B20) -> 9 | F20: =IFERROR(E20/D20,0) -> 0.69230769 | G20: =SUMIFS(EVALUASI!$M$79:$M$132,EVALUASI!$D$79:$D$132,$B20) -> 2 | H20: =IFERROR(1-G20/SUMIFS(DETAIL!$M$2:$M$137,DETAIL!$C$2:$C$137,$B20),0) -> 0.77777778 | I20: =SUMIFS(EVALUASI!$P$79:$P$132,EVALUASI!$D$79:$D$132,$B20) -> 3 | J20: =IFERROR(SUMIFS(DETAIL!$Q$2:$Q$137,DETAIL!$C$2:$C$137,$B20)/SUMIFS(DETAIL!$M$2:$M$137,DETAIL!$C$2:$C$137,$B20),0) -> 0.77777778 | K20: =ROUND(AVERAGEIF(EVALUASI!$D$79:$D$132,$B20,EVALUASI!$W$79:$W$132),1) -> 67.3 | L20: =IF(K20>=100*SUMMARY!$C$14,"Sangat Baik",IF(K20>=100*SUMMARY!$C$15,"Baik",IF(K20>=100*SUMMARY!$C$16,"Cukup","Perlu Pembinaan"))) -> Perlu Pembinaan | M20: =MIN(EVALUASI!$W$126:$W$126) -> 67.3 | N20: =INDEX(EVALUASI!$C$126:$C$126,MATCH(M20,EVALUASI!$W$126:$W$126,0)) -> ALFINA ZAKYA ULA | O20: =K20-ROW()/100000 -> 67.2998
A21: 18 | B21: =EVALUASI!D128 -> WATIN UTARI | C21: =COUNTIF(EVALUASI!$D$79:$D$132,$B21) -> 1 | D21: =SUMIFS(EVALUASI!$I$79:$I$132,EVALUASI!$D$79:$D$132,$B21) -> 7 | E21: =SUMIFS(EVALUASI!$J$79:$J$132,EVALUASI!$D$79:$D$132,$B21) -> 6 | F21: =IFERROR(E21/D21,0) -> 0.85714286 | G21: =SUMIFS(EVALUASI!$M$79:$M$132,EVALUASI!$D$79:$D$132,$B21) -> 1 | H21: =IFERROR(1-G21/SUMIFS(DETAIL!$M$2:$M$137,DETAIL!$C$2:$C$137,$B21),0) -> 0.83333333 | I21: =SUMIFS(EVALUASI!$P$79:$P$132,EVALUASI!$D$79:$D$132,$B21) -> 0 | J21: =IFERROR(SUMIFS(DETAIL!$Q$2:$Q$137,DETAIL!$C$2:$C$137,$B21)/SUMIFS(DETAIL!$M$2:$M$137,DETAIL!$C$2:$C$137,$B21),0) -> 1 | K21: =ROUND(AVERAGEIF(EVALUASI!$D$79:$D$132,$B21,EVALUASI!$W$79:$W$132),1) -> 92.4 | L21: =IF(K21>=100*SUMMARY!$C$14,"Sangat Baik",IF(K21>=100*SUMMARY!$C$15,"Baik",IF(K21>=100*SUMMARY!$C$16,"Cukup","Perlu Pembinaan"))) -> Sangat Baik | M21: =MIN(EVALUASI!$W$128:$W$128) -> 92.4 | N21: =INDEX(EVALUASI!$C$128:$C$128,MATCH(M21,EVALUASI!$W$128:$W$128,0)) -> AMELIA KURNIA FITRI | O21: =K21-ROW()/100000 -> 92.39979
A22: 19 | B22: =EVALUASI!D130 -> WAWAN SETIAWAN | C22: =COUNTIF(EVALUASI!$D$79:$D$132,$B22) -> 1 | D22: =SUMIFS(EVALUASI!$I$79:$I$132,EVALUASI!$D$79:$D$132,$B22) -> 75 | E22: =SUMIFS(EVALUASI!$J$79:$J$132,EVALUASI!$D$79:$D$132,$B22) -> 75 | F22: =IFERROR(E22/D22,0) -> 1 | G22: =SUMIFS(EVALUASI!$M$79:$M$132,EVALUASI!$D$79:$D$132,$B22) -> 12 | H22: =IFERROR(1-G22/SUMIFS(DETAIL!$M$2:$M$137,DETAIL!$C$2:$C$137,$B22),0) -> 0.85 | I22: =SUMIFS(EVALUASI!$P$79:$P$132,EVALUASI!$D$79:$D$132,$B22) -> 6 | J22: =IFERROR(SUMIFS(DETAIL!$Q$2:$Q$137,DETAIL!$C$2:$C$137,$B22)/SUMIFS(DETAIL!$M$2:$M$137,DETAIL!$C$2:$C$137,$B22),0) -> 0.9875 | K22: =ROUND(AVERAGEIF(EVALUASI!$D$79:$D$132,$B22,EVALUASI!$W$79:$W$132),1) -> 96.8 | L22: =IF(K22>=100*SUMMARY!$C$14,"Sangat Baik",IF(K22>=100*SUMMARY!$C$15,"Baik",IF(K22>=100*SUMMARY!$C$16,"Cukup","Perlu Pembinaan"))) -> Sangat Baik | M22: =MIN(EVALUASI!$W$130:$W$130) -> 96.8 | N22: =INDEX(EVALUASI!$C$130:$C$130,MATCH(M22,EVALUASI!$W$130:$W$130,0)) -> PUTRI WIDYOWATI | O22: =K22-ROW()/100000 -> 96.79978
A23: 20 | B23: =EVALUASI!D132 -> YUSUF REZA MUHAMMAD | C23: =COUNTIF(EVALUASI!$D$79:$D$132,$B23) -> 1 | D23: =SUMIFS(EVALUASI!$I$79:$I$132,EVALUASI!$D$79:$D$132,$B23) -> 36 | E23: =SUMIFS(EVALUASI!$J$79:$J$132,EVALUASI!$D$79:$D$132,$B23) -> 33 | F23: =IFERROR(E23/D23,0) -> 0.91666667 | G23: =SUMIFS(EVALUASI!$M$79:$M$132,EVALUASI!$D$79:$D$132,$B23) -> 3 | H23: =IFERROR(1-G23/SUMIFS(DETAIL!$M$2:$M$137,DETAIL!$C$2:$C$137,$B23),0) -> 0.90909091 | I23: =SUMIFS(EVALUASI!$P$79:$P$132,EVALUASI!$D$79:$D$132,$B23) -> 1 | J23: =IFERROR(SUMIFS(DETAIL!$Q$2:$Q$137,DETAIL!$C$2:$C$137,$B23)/SUMIFS(DETAIL!$M$2:$M$137,DETAIL!$C$2:$C$137,$B23),0) -> 0.90909091 | K23: =ROUND(AVERAGEIF(EVALUASI!$D$79:$D$132,$B23,EVALUASI!$W$79:$W$132),1) -> 93.9 | L23: =IF(K23>=100*SUMMARY!$C$14,"Sangat Baik",IF(K23>=100*SUMMARY!$C$15,"Baik",IF(K23>=100*SUMMARY!$C$16,"Cukup","Perlu Pembinaan"))) -> Sangat Baik | M23: =MIN(EVALUASI!$W$132:$W$132) -> 93.9 | N23: =INDEX(EVALUASI!$C$132:$C$132,MATCH(M23,EVALUASI!$W$132:$W$132,0)) -> MUHAMMAD QAIRUL UMAM | O23: =K23-ROW()/100000 -> 93.89977
B24: TOTAL / RATA-RATA | C24: =SUM(C4:C23) -> 34 | D24: =SUM(D4:D23) -> 1712 | E24: =SUM(E4:E23) -> 1621 | F24: =IFERROR(E24/D24,0) -> 0.94684579 | G24: =SUM(G4:G23) -> 226 | H24: =IFERROR(1-G24/SUM(DETAIL!$M$2:$M$137),0) -> 0.8676815 | I24: =SUM(I4:I23) -> 100 | J24: =IFERROR(SUM(DETAIL!$Q$2:$Q$137)/SUM(DETAIL!$M$2:$M$137),0) -> 0.93618267 | K24: =ROUND(AVERAGE(EVALUASI!$W$79:$W$132),1) -> 86.1
A26: ANALISIS EFEKTIVITAS PEMAGANG & REKOMENDASI KUOTA PER DEPARTEMEN
A27: Rekomendasi kuota dihitung dari beban kerja nyata (laporan aktivitas)
B28: Bobot jumlah entri laporan | C28: 0.5
B29: Bobot panjang laporan (karakter) | C29: 0.5
B30: Minimal hari hadir agar rekomendasi meyakinkan | C30: 20
B31: Kuota minimal per departemen | C31: 1
A33: No | B33: Departemen Penempatan | C33: Jumlah Pemagang (periode) | D33: Pemagang Aktif Akhir Periode | E33: Rata-rata Pemagang Aktif (bulan berjalan) | F33: Total Hari Hadir | G33: Total Entri Laporan | H33: Entri / Hari Hadir | I33: Karakter Laporan / Hari Hadir | J33: Indeks Beban per Pemagang | K33: % Hari dgn Laporan | L33: % Kehadiran | M33: Rata-rata Skor | N33: Kebutuhan Pemagang (hitungan) | O33: REKOMENDASI KUOTA | P33: Selisih vs Aktif Saat Ini | Q33: Indikasi | R33: Rekomendasi | S33: Keyakinan Data
A34: 1 | B34: CENTRAL JAVA CURAH ADMINISTRATION JR. OFFICER | C34: =COUNTIF(PEMAGANG!$F$3:$F$36,$B34) -> 2 | D34: =COUNTIFS(PEMAGANG!$F$3:$F$36,$B34,PEMAGANG!$K$3:$K$36,SUMMARY!$C$7) -> 1 | E34: =IFERROR(AVERAGEIF(G57:J57,">0"),0) -> 1.234375 | F34: =SUMIFS(DETAIL!$M$2:$M$137,DETAIL!$S$2:$S$137,$B34) -> 85 | G34: =SUMIFS(DETAIL!$R$2:$R$137,DETAIL!$S$2:$S$137,$B34) -> 195 | H34: =IFERROR(G34/F34,0) -> 2.2941176 | I34: =IFERROR(SUMIFS(DETAIL!$T$2:$T$137,DETAIL!$S$2:$S$137,$B34)/F34,0) -> 26.094118 | J34: =IFERROR($C$28*H34/$H$52+$C$29*I34/$I$52,0) -> 0.77643822 | K34: =IFERROR(SUMIFS(DETAIL!$Q$2:$Q$137,DETAIL!$S$2:$S$137,$B34)/F34,0) -> 0.95294118 | L34: =IFERROR(SUMIFS(DETAIL!$K$2:$K$137,DETAIL!$S$2:$S$137,$B34)/SUMIFS(DETAIL!$I$2:$I$137,DETAIL!$S$2:$S$137,$B34),0) -> 0.94444444 | M34: =IFERROR(ROUND(AVERAGEIF(EVALUASI!$F$79:$F$132,$B34,EVALUASI!$W$79:$W$132),1),"-") -> 84.9 | N34: =E34*J34 -> 0.95841593 | O34: =IF(OR(F34=0,G34=0),"-",MAX($C$31,ROUND(N34,0))) -> 1 | P34: =IF(ISNUMBER(O34),O34-D34,"-") -> 0 | Q34: =IF(F34=0,"Belum ada data",IF(G34=0,"Tidak dapat dihitung",IF(P34<0,"Kelebihan pemagang",IF(P34>0,"Kekurangan pemagang","Seimbang")))) -> Seimbang | R34: =IF(Q34="Kelebihan pemagang","Kuota disarankan "&O34&" (kurangi "&-P34&"). Beban per pemagang "&TEXT(J34,"0.00")&"x rata-rata; alihkan pemagang atau tambah variasi tugas.",IF(AND(Q34="Kekurangan pemagang",D34=0),"Saat ini tidak ada pemagang aktif; isi kembali "&O34&" pemagang.",IF(Q34="Kekurangan pemagang","Kuota disarankan "&O34&" (tambah "&P34&"). Beban per pemagang "&TEXT(J34,"0.00")&"x rata-rata.",IF(Q34="Seimbang","Pertahankan "&O34&" pemagang.",IF(Q34="Tidak dapat dihitung","Pemagang tidak mengisi laporan aktivitas; wajibkan laporan harian dulu.","-"))))) -> Pertahankan 1 pemagang. | S34: =IF(F34=0,"-",IF(F34<$C$30,"Rendah (hari hadir < "&$C$30&")","Cukup")) -> Cukup
A35: 2 | B35: EQUALISATION OFFICER (SID) | C35: =COUNTIF(PEMAGANG!$F$3:$F$36,$B35) -> 1 | D35: =COUNTIFS(PEMAGANG!$F$3:$F$36,$B35,PEMAGANG!$K$3:$K$36,SUMMARY!$C$7) -> 1 | E35: =IFERROR(AVERAGEIF(G58:J58,">0"),0) -> 1 | F35: =SUMIFS(DETAIL!$M$2:$M$137,DETAIL!$S$2:$S$137,$B35) -> 65 | G35: =SUMIFS(DETAIL!$R$2:$R$137,DETAIL!$S$2:$S$137,$B35) -> 108 | H35: =IFERROR(G35/F35,0) -> 1.6615385 | I35: =IFERROR(SUMIFS(DETAIL!$T$2:$T$137,DETAIL!$S$2:$S$137,$B35)/F35,0) -> 28.353846 | J35: =IFERROR($C$28*H35/$H$52+$C$29*I35/$I$52,0) -> 0.61100401 | K35: =IFERROR(SUMIFS(DETAIL!$Q$2:$Q$137,DETAIL!$S$2:$S$137,$B35)/F35,0) -> 0.96923077 | L35: =IFERROR(SUMIFS(DETAIL!$K$2:$K$137,DETAIL!$S$2:$S$137,$B35)/SUMIFS(DETAIL!$I$2:$I$137,DETAIL!$S$2:$S$137,$B35),0) -> 0.85333333 | M35: =IFERROR(ROUND(AVERAGEIF(EVALUASI!$F$79:$F$132,$B35,EVALUASI!$W$79:$W$132),1),"-") -> 78.1 | N35: =E35*J35 -> 0.61100401 | O35: =IF(OR(F35=0,G35=0),"-",MAX($C$31,ROUND(N35,0))) -> 1 | P35: =IF(ISNUMBER(O35),O35-D35,"-") -> 0 | Q35: =IF(F35=0,"Belum ada data",IF(G35=0,"Tidak dapat dihitung",IF(P35<0,"Kelebihan pemagang",IF(P35>0,"Kekurangan pemagang","Seimbang")))) -> Seimbang | R35: =IF(Q35="Kelebihan pemagang","Kuota disarankan "&O35&" (kurangi "&-P35&"). Beban per pemagang "&TEXT(J35,"0.00")&"x rata-rata; alihkan pemagang atau tambah variasi tugas.",IF(AND(Q35="Kekurangan pemagang",D35=0),"Saat ini tidak ada pemagang aktif; isi kembali "&O35&" pemagang.",IF(Q35="Kekurangan pemagang","Kuota disarankan "&O35&" (tambah "&P35&"). Beban per pemagang "&TEXT(J35,"0.00")&"x rata-rata.",IF(Q35="Seimbang","Pertahankan "&O35&" pemagang.",IF(Q35="Tidak dapat dihitung","Pemagang tidak mengisi laporan aktivitas; wajibkan laporan harian dulu.","-"))))) -> Pertahankan 1 pemagang. | S35: =IF(F35=0,"-",IF(F35<$C$30,"Rendah (hari hadir < "&$C$30&")","Cukup")) -> Cukup
A36: 3 | B36: GM OF TAX & ACCOUNTING | C36: =COUNTIF(PEMAGANG!$F$3:$F$36,$B36) -> 1 | D36: =COUNTIFS(PEMAGANG!$F$3:$F$36,$B36,PEMAGANG!$K$3:$K$36,SUMMARY!$C$7) -> 1 | E36: =IFERROR(AVERAGEIF(G59:J59,">0"),0) -> 0.86842105 | F36: =SUMIFS(DETAIL!$M$2:$M$137,DETAIL!$S$2:$S$137,$B36) -> 33 | G36: =SUMIFS(DETAIL!$R$2:$R$137,DETAIL!$S$2:$S$137,$B36) -> 49 | H36: =IFERROR(G36/F36,0) -> 1.4848485 | I36: =IFERROR(SUMIFS(DETAIL!$T$2:$T$137,DETAIL!$S$2:$S$137,$B36)/F36,0) -> 156.36364 | J36: =IFERROR($C$28*H36/$H$52+$C$29*I36/$I$52,0) -> 1.2203614 | K36: =IFERROR(SUMIFS(DETAIL!$Q$2:$Q$137,DETAIL!$S$2:$S$137,$B36)/F36,0) -> 0.90909091 | L36: =IFERROR(SUMIFS(DETAIL!$K$2:$K$137,DETAIL!$S$2:$S$137,$B36)/SUMIFS(DETAIL!$I$2:$I$137,DETAIL!$S$2:$S$137,$B36),0) -> 0.91666667 | M36: =IFERROR(ROUND(AVERAGEIF(EVALUASI!$F$79:$F$132,$B36,EVALUASI!$W$79:$W$132),1),"-") -> 93.9 | N36: =E36*J36 -> 1.0597875 | O36: =IF(OR(F36=0,G36=0),"-",MAX($C$31,ROUND(N36,0))) -> 1 | P36: =IF(ISNUMBER(O36),O36-D36,"-") -> 0 | Q36: =IF(F36=0,"Belum ada data",IF(G36=0,"Tidak dapat dihitung",IF(P36<0,"Kelebihan pemagang",IF(P36>0,"Kekurangan pemagang","Seimbang")))) -> Seimbang | R36: =IF(Q36="Kelebihan pemagang","Kuota disarankan "&O36&" (kurangi "&-P36&"). Beban per pemagang "&TEXT(J36,"0.00")&"x rata-rata; alihkan pemagang atau tambah variasi tugas.",IF(AND(Q36="Kekurangan pemagang",D36=0),"Saat ini tidak ada pemagang aktif; isi kembali "&O36&" pemagang.",IF(Q36="Kekurangan pemagang","Kuota disarankan "&O36&" (tambah "&P36&"). Beban per pemagang "&TEXT(J36,"0.00")&"x rata-rata.",IF(Q36="Seimbang","Pertahankan "&O36&" pemagang.",IF(Q36="Tidak dapat dihitung","Pemagang tidak mengisi laporan aktivitas; wajibkan laporan harian dulu.","-"))))) -> Pertahankan 1 pemagang. | S36: =IF(F36=0,"-",IF(F36<$C$30,"Rendah (hari hadir < "&$C$30&")","Cukup")) -> Cukup
A37: 4 | B37: MANAGER OF TRANSPORTATION | C37: =COUNTIF(PEMAGANG!$F$3:$F$36,$B37) -> 2 | D37: =COUNTIFS(PEMAGANG!$F$3:$F$36,$B37,PEMAGANG!$K$3:$K$36,SUMMARY!$C$7) -> 2 | E37: =IFERROR(AVERAGEIF(G60:J60,">0"),0) -> 1.75 | F37: =SUMIFS(DETAIL!$M$2:$M$137,DETAIL!$S$2:$S$137,$B37) -> 136 | G37: =SUMIFS(DETAIL!$R$2:$R$137,DETAIL!$S$2:$S$137,$B37) -> 296 | H37: =IFERROR(G37/F37,0) -> 2.1764706 | I37: =IFERROR(SUMIFS(DETAIL!$T$2:$T$137,DETAIL!$S$2:$S$137,$B37)/F37,0) -> 87.757353 | J37: =IFERROR($C$28*H37/$H$52+$C$29*I37/$I$52,0) -> 1.0608634 | K37: =IFERROR(SUMIFS(DETAIL!$Q$2:$Q$137,DETAIL!$S$2:$S$137,$B37)/F37,0) -> 0.99264706 | L37: =IFERROR(SUMIFS(DETAIL!$K$2:$K$137,DETAIL!$S$2:$S$137,$B37)/SUMIFS(DETAIL!$I$2:$I$137,DETAIL!$S$2:$S$137,$B37),0) -> 0.95522388 | M37: =IFERROR(ROUND(AVERAGEIF(EVALUASI!$F$79:$F$132,$B37,EVALUASI!$W$79:$W$132),1),"-") -> 92.3 | N37: =E37*J37 -> 1.856511 | O37: =IF(OR(F37=0,G37=0),"-",MAX($C$31,ROUND(N37,0))) -> 2 | P37: =IF(ISNUMBER(O37),O37-D37,"-") -> 0 | Q37: =IF(F37=0,"Belum ada data",IF(G37=0,"Tidak dapat dihitung",IF(P37<0,"Kelebihan pemagang",IF(P37>0,"Kekurangan pemagang","Seimbang")))) -> Seimbang | R37: =IF(Q37="Kelebihan pemagang","Kuota disarankan "&O37&" (kurangi "&-P37&"). Beban per pemagang "&TEXT(J37,"0.00")&"x rata-rata; alihkan pemagang atau tambah variasi tugas.",IF(AND(Q37="Kekurangan pemagang",D37=0),"Saat ini tidak ada pemagang aktif; isi kembali "&O37&" pemagang.",IF(Q37="Kekurangan pemagang","Kuota disarankan "&O37&" (tambah "&P37&"). Beban per pemagang "&TEXT(J37,"0.00")&"x rata-rata.",IF(Q37="Seimbang","Pertahankan "&O37&" pemagang.",IF(Q37="Tidak dapat dihitung","Pemagang tidak mengisi laporan aktivitas; wajibkan laporan harian dulu.","-"))))) -> Pertahankan 2 pemagang. | S37: =IF(F37=0,"-",IF(F37<$C$30,"Rendah (hari hadir < "&$C$30&")","Cukup")) -> Cukup
A38: 5 | B38: MANAGER OF VERIFICATION | C38: =COUNTIF(PEMAGANG!$F$3:$F$36,$B38) -> 1 | D38: =COUNTIFS(PEMAGANG!$F$3:$F$36,$B38,PEMAGANG!$K$3:$K$36,SUMMARY!$C$7) -> 1 | E38: =IFERROR(AVERAGEIF(G61:J61,">0"),0) -> 0.59090909 | F38: =SUMIFS(DETAIL!$M$2:$M$137,DETAIL!$S$2:$S$137,$B38) -> 13 | G38: =SUMIFS(DETAIL!$R$2:$R$137,DETAIL!$S$2:$S$137,$B38) -> 13 | H38: =IFERROR(G38/F38,0) -> 1 | I38: =IFERROR(SUMIFS(DETAIL!$T$2:$T$137,DETAIL!$S$2:$S$137,$B38)/F38,0) -> 97 | J38: =IFERROR($C$28*H38/$H$52+$C$29*I38/$I$52,0) -> 0.7791278 | K38: =IFERROR(SUMIFS(DETAIL!$Q$2:$Q$137,DETAIL!$S$2:$S$137,$B38)/F38,0) -> 1 | L38: =IFERROR(SUMIFS(DETAIL!$K$2:$K$137,DETAIL!$S$2:$S$137,$B38)/SUMIFS(DETAIL!$I$2:$I$137,DETAIL!$S$2:$S$137,$B38),0) -> 1 | M38: =IFERROR(ROUND(AVERAGEIF(EVALUASI!$F$79:$F$132,$B38,EVALUASI!$W$79:$W$132),1),"-") -> 91.8 | N38: =E38*J38 -> 0.4603937 | O38: =IF(OR(F38=0,G38=0),"-",MAX($C$31,ROUND(N38,0))) -> 1 | P38: =IF(ISNUMBER(O38),O38-D38,"-") -> 0 | Q38: =IF(F38=0,"Belum ada data",IF(G38=0,"Tidak dapat dihitung",IF(P38<0,"Kelebihan pemagang",IF(P38>0,"Kekurangan pemagang","Seimbang")))) -> Seimbang | R38: =IF(Q38="Kelebihan pemagang","Kuota disarankan "&O38&" (kurangi "&-P38&"). Beban per pemagang "&TEXT(J38,"0.00")&"x rata-rata; alihkan pemagang atau tambah variasi tugas.",IF(AND(Q38="Kekurangan pemagang",D38=0),"Saat ini tidak ada pemagang aktif; isi kembali "&O38&" pemagang.",IF(Q38="Kekurangan pemagang","Kuota disarankan "&O38&" (tambah "&P38&"). Beban per pemagang "&TEXT(J38,"0.00")&"x rata-rata.",IF(Q38="Seimbang","Pertahankan "&O38&" pemagang.",IF(Q38="Tidak dapat dihitung","Pemagang tidak mengisi laporan aktivitas; wajibkan laporan harian dulu.","-"))))) -> Pertahankan 1 pemagang. | S38: =IF(F38=0,"-",IF(F38<$C$30,"Rendah (hari hadir < "&$C$30&")","Cukup")) -> Rendah (hari hadir < 20)
A39: 6 | B39: MARKETING & EXPANSION MODERN RETAIL OFFICER | C39: =COUNTIF(PEMAGANG!$F$3:$F$36,$B39) -> 1 | D39: =COUNTIFS(PEMAGANG!$F$3:$F$36,$B39,PEMAGANG!$K$3:$K$36,SUMMARY!$C$7) -> 1 | E39: =IFERROR(AVERAGEIF(G62:J62,">0"),0) -> 1 | F39: =SUMIFS(DETAIL!$M$2:$M$137,DETAIL!$S$2:$S$137,$B39) -> 94 | G39: =SUMIFS(DETAIL!$R$2:$R$137,DETAIL!$S$2:$S$137,$B39) -> 154 | H39: =IFERROR(G39/F39,0) -> 1.6382979 | I39: =IFERROR(SUMIFS(DETAIL!$T$2:$T$137,DETAIL!$S$2:$S$137,$B39)/F39,0) -> 45.510638 | J39: =IFERROR($C$28*H39/$H$52+$C$29*I39/$I$52,0) -> 0.69279781 | K39: =IFERROR(SUMIFS(DETAIL!$Q$2:$Q$137,DETAIL!$S$2:$S$137,$B39)/F39,0) -> 0.91489362 | L39: =IFERROR(SUMIFS(DETAIL!$K$2:$K$137,DETAIL!$S$2:$S$137,$B39)/SUMIFS(DETAIL!$I$2:$I$137,DETAIL!$S$2:$S$137,$B39),0) -> 0.93333333 | M39: =IFERROR(ROUND(AVERAGEIF(EVALUASI!$F$79:$F$132,$B39,EVALUASI!$W$79:$W$132),1),"-") -> 74.5 | N39: =E39*J39 -> 0.69279781 | O39: =IF(OR(F39=0,G39=0),"-",MAX($C$31,ROUND(N39,0))) -> 1 | P39: =IF(ISNUMBER(O39),O39-D39,"-") -> 0 | Q39: =IF(F39=0,"Belum ada data",IF(G39=0,"Tidak dapat dihitung",IF(P39<0,"Kelebihan pemagang",IF(P39>0,"Kekurangan pemagang","Seimbang")))) -> Seimbang | R39: =IF(Q39="Kelebihan pemagang","Kuota disarankan "&O39&" (kurangi "&-P39&"). Beban per pemagang "&TEXT(J39,"0.00")&"x rata-rata; alihkan pemagang atau tambah variasi tugas.",IF(AND(Q39="Kekurangan pemagang",D39=0),"Saat ini tidak ada pemagang aktif; isi kembali "&O39&" pemagang.",IF(Q39="Kekurangan pemagang","Kuota disarankan "&O39&" (tambah "&P39&"). Beban per pemagang "&TEXT(J39,"0.00")&"x rata-rata.",IF(Q39="Seimbang","Pertahankan "&O39&" pemagang.",IF(Q39="Tidak dapat dihitung","Pemagang tidak mengisi laporan aktivitas; wajibkan laporan harian dulu.","-"))))) -> Pertahankan 1 pemagang. | S39: =IF(F39=0,"-",IF(F39<$C$30,"Rendah (hari hadir < "&$C$30&")","Cukup")) -> Cukup
A40: 7 | B40: PGS FINANCIAL ANALYSIS OFFICER | C40: =COUNTIF(PEMAGANG!$F$3:$F$36,$B40) -> 1 | D40: =COUNTIFS(PEMAGANG!$F$3:$F$36,$B40,PEMAGANG!$K$3:$K$36,SUMMARY!$C$7) -> 1 | E40: =IFERROR(AVERAGEIF(G63:J63,">0"),0) -> 1 | F40: =SUMIFS(DETAIL!$M$2:$M$137,DETAIL!$S$2:$S$137,$B40) -> 78 | G40: =SUMIFS(DETAIL!$R$2:$R$137,DETAIL!$S$2:$S$137,$B40) -> 248 | H40: =IFERROR(G40/F40,0) -> 3.1794872 | I40: =IFERROR(SUMIFS(DETAIL!$T$2:$T$137,DETAIL!$S$2:$S$137,$B40)/F40,0) -> 206.92308 | J40: =IFERROR($C$28*H40/$H$52+$C$29*I40/$I$52,0) -> 1.9549136 | K40: =IFERROR(SUMIFS(DETAIL!$Q$2:$Q$137,DETAIL!$S$2:$S$137,$B40)/F40,0) -> 0.98717949 | L40: =IFERROR(SUMIFS(DETAIL!$K$2:$K$137,DETAIL!$S$2:$S$137,$B40)/SUMIFS(DETAIL!$I$2:$I$137,DETAIL!$S$2:$S$137,$B40),0) -> 0.96 | M40: =IFERROR(ROUND(AVERAGEIF(EVALUASI!$F$79:$F$132,$B40,EVALUASI!$W$79:$W$132),1),"-") -> 98.5 | N40: =E40*J40 -> 1.9549136 | O40: =IF(OR(F40=0,G40=0),"-",MAX($C$31,ROUND(N40,0))) -> 2 | P40: =IF(ISNUMBER(O40),O40-D40,"-") -> 1 | Q40: =IF(F40=0,"Belum ada data",IF(G40=0,"Tidak dapat dihitung",IF(P40<0,"Kelebihan pemagang",IF(P40>0,"Kekurangan pemagang","Seimbang")))) -> Kekurangan pemagang | R40: =IF(Q40="Kelebihan pemagang","Kuota disarankan "&O40&" (kurangi "&-P40&"). Beban per pemagang "&TEXT(J40,"0.00")&"x rata-rata; alihkan pemagang atau tambah variasi tugas.",IF(AND(Q40="Kekurangan pemagang",D40=0),"Saat ini tidak ada pemagang aktif; isi kembali "&O40&" pemagang.",IF(Q40="Kekurangan pemagang","Kuota disarankan "&O40&" (tambah "&P40&"). Beban per pemagang "&TEXT(J40,"0.00")&"x rata-rata.",IF(Q40="Seimbang","Pertahankan "&O40&" pemagang.",IF(Q40="Tidak dapat dihitung","Pemagang tidak mengisi laporan aktivitas; wajibkan laporan harian dulu.","-"))))) -> Kuota disarankan 2 (tambah 1). Beban per pemagang 1.95x rata-rata. | S40: =IF(F40=0,"-",IF(F40<$C$30,"Rendah (hari hadir < "&$C$30&")","Cukup")) -> Cukup
A41: 8 | B41: PGS MANAGER OF LAMONGAN BRANCH | C41: =COUNTIF(PEMAGANG!$F$3:$F$36,$B41) -> 1 | D41: =COUNTIFS(PEMAGANG!$F$3:$F$36,$B41,PEMAGANG!$K$3:$K$36,SUMMARY!$C$7) -> 1 | E41: =IFERROR(AVERAGEIF(G64:J64,">0"),0) -> 0.90909091 | F41: =SUMIFS(DETAIL!$M$2:$M$137,DETAIL!$S$2:$S$137,$B41) -> 15 | G41: =SUMIFS(DETAIL!$R$2:$R$137,DETAIL!$S$2:$S$137,$B41) -> 0 | H41: =IFERROR(G41/F41,0) -> 0 | I41: =IFERROR(SUMIFS(DETAIL!$T$2:$T$137,DETAIL!$S$2:$S$137,$B41)/F41,0) -> 0 | J41: =IFERROR($C$28*H41/$H$52+$C$29*I41/$I$52,0) -> 0 | K41: =IFERROR(SUMIFS(DETAIL!$Q$2:$Q$137,DETAIL!$S$2:$S$137,$B41)/F41,0) -> 0 | L41: =IFERROR(SUMIFS(DETAIL!$K$2:$K$137,DETAIL!$S$2:$S$137,$B41)/SUMIFS(DETAIL!$I$2:$I$137,DETAIL!$S$2:$S$137,$B41),0) -> 0.75 | M41: =IFERROR(ROUND(AVERAGEIF(EVALUASI!$F$79:$F$132,$B41,EVALUASI!$W$79:$W$132),1),"-") -> 31.8 | N41: =E41*J41 -> 0 | O41: =IF(OR(F41=0,G41=0),"-",MAX($C$31,ROUND(N41,0))) -> - | P41: =IF(ISNUMBER(O41),O41-D41,"-") -> - | Q41: =IF(F41=0,"Belum ada data",IF(G41=0,"Tidak dapat dihitung",IF(P41<0,"Kelebihan pemagang",IF(P41>0,"Kekurangan pemagang","Seimbang")))) -> Tidak dapat dihitung | R41: =IF(Q41="Kelebihan pemagang","Kuota disarankan "&O41&" (kurangi "&-P41&"). Beban per pemagang "&TEXT(J41,"0.00")&"x rata-rata; alihkan pemagang atau tambah variasi tugas.",IF(AND(Q41="Kekurangan pemagang",D41=0),"Saat ini tidak ada pemagang aktif; isi kembali "&O41&" pemagang.",IF(Q41="Kekurangan pemagang","Kuota disarankan "&O41&" (tambah "&P41&"). Beban per pemagang "&TEXT(J41,"0.00")&"x rata-rata.",IF(Q41="Seimbang","Pertahankan "&O41&" pemagang.",IF(Q41="Tidak dapat dihitung","Pemagang tidak mengisi laporan aktivitas; wajibkan laporan harian dulu.","-"))))) -> Pemagang tidak mengisi laporan aktivitas; wajibkan laporan harian dulu. | S41: =IF(F41=0,"-",IF(F41<$C$30,"Rendah (hari hadir < "&$C$30&")","Cukup")) -> Rendah (hari hadir < 20)
A42: 9 | B42: PGS SM OF DIGITAL BUSSINES | C42: =COUNTIF(PEMAGANG!$F$3:$F$36,$B42) -> 8 | D42: =COUNTIFS(PEMAGANG!$F$3:$F$36,$B42,PEMAGANG!$K$3:$K$36,SUMMARY!$C$7) -> 8 | E42: =IFERROR(AVERAGEIF(G65:J65,">0"),0) -> 6.3026316 | F42: =SUMIFS(DETAIL!$M$2:$M$137,DETAIL!$S$2:$S$137,$B42) -> 493 | G42: =SUMIFS(DETAIL!$R$2:$R$137,DETAIL!$S$2:$S$137,$B42) -> 898 | H42: =IFERROR(G42/F42,0) -> 1.821501 | I42: =IFERROR(SUMIFS(DETAIL!$T$2:$T$137,DETAIL!$S$2:$S$137,$B42)/F42,0) -> 85.046653 | J42: =IFERROR($C$28*H42/$H$52+$C$29*I42/$I$52,0) -> 0.94755368 | K42: =IFERROR(SUMIFS(DETAIL!$Q$2:$Q$137,DETAIL!$S$2:$S$137,$B42)/F42,0) -> 0.89655172 | L42: =IFERROR(SUMIFS(DETAIL!$K$2:$K$137,DETAIL!$S$2:$S$137,$B42)/SUMIFS(DETAIL!$I$2:$I$137,DETAIL!$S$2:$S$137,$B42),0) -> 0.97308489 | M42: =IFERROR(ROUND(AVERAGEIF(EVALUASI!$F$79:$F$132,$B42,EVALUASI!$W$79:$W$132),1),"-") -> 85.8 | N42: =E42*J42 -> 5.9720817 | O42: =IF(OR(F42=0,G42=0),"-",MAX($C$31,ROUND(N42,0))) -> 6 | P42: =IF(ISNUMBER(O42),O42-D42,"-") -> -2 | Q42: =IF(F42=0,"Belum ada data",IF(G42=0,"Tidak dapat dihitung",IF(P42<0,"Kelebihan pemagang",IF(P42>0,"Kekurangan pemagang","Seimbang")))) -> Kelebihan pemagang | R42: =IF(Q42="Kelebihan pemagang","Kuota disarankan "&O42&" (kurangi "&-P42&"). Beban per pemagang "&TEXT(J42,"0.00")&"x rata-rata; alihkan pemagang atau tambah variasi tugas.",IF(AND(Q42="Kekurangan pemagang",D42=0),"Saat ini tidak ada pemagang aktif; isi kembali "&O42&" pemagang.",IF(Q42="Kekurangan pemagang","Kuota disarankan "&O42&" (tambah "&P42&"). Beban per pemagang "&TEXT(J42,"0.00")&"x rata-rata.",IF(Q42="Seimbang","Pertahankan "&O42&" pemagang.",IF(Q42="Tidak dapat dihitung","Pemagang tidak mengisi laporan aktivitas; wajibkan laporan harian dulu.","-"))))) -> Kuota disarankan 6 (kurangi 2). Beban per pemagang 0.95x rata-rata; alihkan pemagang atau tambah variasi tugas. | S42: =IF(F42=0,"-",IF(F42<$C$30,"Rendah (hari hadir < "&$C$30&")","Cukup")) -> Cukup
A43: 10 | B43: PGS TREASURY (SID) OFFICER | C43: =COUNTIF(PEMAGANG!$F$3:$F$36,$B43) -> 2 | D43: =COUNTIFS(PEMAGANG!$F$3:$F$36,$B43,PEMAGANG!$K$3:$K$36,SUMMARY!$C$7) -> 1 | E43: =IFERROR(AVERAGEIF(G66:J66,">0"),0) -> 0.86111111 | F43: =SUMIFS(DETAIL!$M$2:$M$137,DETAIL!$S$2:$S$137,$B43) -> 58 | G43: =SUMIFS(DETAIL!$R$2:$R$137,DETAIL!$S$2:$S$137,$B43) -> 60 | H43: =IFERROR(G43/F43,0) -> 1.0344828 | I43: =IFERROR(SUMIFS(DETAIL!$T$2:$T$137,DETAIL!$S$2:$S$137,$B43)/F43,0) -> 39.931034 | J43: =IFERROR($C$28*H43/$H$52+$C$29*I43/$I$52,0) -> 0.49506904 | K43: =IFERROR(SUMIFS(DETAIL!$Q$2:$Q$137,DETAIL!$S$2:$S$137,$B43)/F43,0) -> 0.98275862 | L43: =IFERROR(SUMIFS(DETAIL!$K$2:$K$137,DETAIL!$S$2:$S$137,$B43)/SUMIFS(DETAIL!$I$2:$I$137,DETAIL!$S$2:$S$137,$B43),0) -> 0.89230769 | M43: =IFERROR(ROUND(AVERAGEIF(EVALUASI!$F$79:$F$132,$B43,EVALUASI!$W$79:$W$132),1),"-") -> 81.4 | N43: =E43*J43 -> 0.42630945 | O43: =IF(OR(F43=0,G43=0),"-",MAX($C$31,ROUND(N43,0))) -> 1 | P43: =IF(ISNUMBER(O43),O43-D43,"-") -> 0 | Q43: =IF(F43=0,"Belum ada data",IF(G43=0,"Tidak dapat dihitung",IF(P43<0,"Kelebihan pemagang",IF(P43>0,"Kekurangan pemagang","Seimbang")))) -> Seimbang | R43: =IF(Q43="Kelebihan pemagang","Kuota disarankan "&O43&" (kurangi "&-P43&"). Beban per pemagang "&TEXT(J43,"0.00")&"x rata-rata; alihkan pemagang atau tambah variasi tugas.",IF(AND(Q43="Kekurangan pemagang",D43=0),"Saat ini tidak ada pemagang aktif; isi kembali "&O43&" pemagang.",IF(Q43="Kekurangan pemagang","Kuota disarankan "&O43&" (tambah "&P43&"). Beban per pemagang "&TEXT(J43,"0.00")&"x rata-rata.",IF(Q43="Seimbang","Pertahankan "&O43&" pemagang.",IF(Q43="Tidak dapat dihitung","Pemagang tidak mengisi laporan aktivitas; wajibkan laporan harian dulu.","-"))))) -> Pertahankan 1 pemagang. | S43: =IF(F43=0,"-",IF(F43<$C$30,"Rendah (hari hadir < "&$C$30&")","Cukup")) -> Cukup
...

Sheet PRODUKTIVITAS
A1: ANALISIS PRODUKTIVITAS PEMAGANG
B2: Bobot jumlah entri laporan | C2: =EVALUASI!$C$28 -> 0.5 | D2: Batas "Sangat Tinggi" (indeks ≥) | E2: 1.5
B3: Bobot panjang laporan | C3: =EVALUASI!$C$29 -> 0.5 | D3: Batas "Tinggi" (indeks ≥) | E3: 1
B4: Indeks untuk nilai penuh | C4: =SUMMARY!$C$18 -> 1 | D4: Batas "Sedang" (indeks ≥) | E4: 0.7
B5: Rata-rata entri / hari hadir (semua pemagang) | C5: =SUM(DETAIL!$R$2:$R$137)/SUM(DETAIL!$M$2:$M$137) -> 1.7862998
B6: Rata-rata karakter / hari hadir (semua pemagang) | C6: =SUM(DETAIL!$T$2:$T$137)/SUM(DETAIL!$M$2:$M$137) -> 97.151639
A8: A. PRODUKTIVITAS PER PEMAGANG
A9: No | B9: Nama Pemagang | C9: Pembimbing | D9: Departemen Penempatan | E9: Hari Hadir (dlm masa magang) | F9: Entri Laporan | G9: Karakter Laporan | H9: Entri / Hari | I9: Karakter / Hari | J9: Indeks Produktivitas | K9: Nilai Produktivitas | L9: Kategori | M9: Peringkat | N9: Indeks Jun | O9: Indeks Jul | P9: Indeks Agu | Q9: Indeks Sep | R9: Skor Akhir | S9: Predikat | T9: key
A10: 1 | B10: =PEMAGANG!C3 -> ARINDA PUTRI AULIA | C10: =PEMAGANG!D3 -> AHMAD JALALUDDIN BASYAR | D10: =PEMAGANG!F3 -> PGS SM OF DIGITAL BUSSINES | E10: =SUMIFS(DETAIL!$M$2:$M$137,DETAIL!$B$2:$B$137,$B10) -> 75 | F10: =SUMIFS(DETAIL!$R$2:$R$137,DETAIL!$B$2:$B$137,$B10) -> 86 | G10: =SUMIFS(DETAIL!$T$2:$T$137,DETAIL!$B$2:$B$137,$B10) -> 1799 | H10: =IFERROR(F10/E10,0) -> 1.1466667 | I10: =IFERROR(G10/E10,0) -> 23.986667 | J10: =IFERROR($C$2*H10/$C$5+$C$3*I10/$C$6,0) -> 0.44441106 | K10: =MIN(1,IFERROR(J10/$C$4,0)) -> 0.44441106 | L10: =IF(E10=0,"-",IF(F10=0,"Tidak ada laporan",IF(J10>=$E$2,"Sangat Tinggi",IF(J10>=$E$3,"Tinggi",IF(J10>=$E$4,"Sedang","Rendah"))))) -> Rendah | M10: =RANK(T10,$T$10:$T$43) -> 28 | N10: =IFERROR($C$2*(SUMIFS(DETAIL!$R$2:$R$137,DETAIL!$B$2:$B$137,$B10,DETAIL!$F$2:$F$137,MONTH(DATE(YEAR(SUMMARY!$C$6),MONTH(SUMMARY!$C$6)+0,1)))/SUMIFS(DETAIL!$M$2:$M$137,DETAIL!$B$2:$B$137,$B10,DETAIL!$F$2:$F$137,MONTH(DATE(YEAR(SUMMARY!$C$6),MONTH(SUMMARY!$C$6)+0,1))))/$C$5+$C$3*(SUMIFS(DETAIL!$T$2:$T$137,DETAIL!$B$2:$B$137,$B10,DETAIL!$F$2:$F$137,MONTH(DATE(YEAR(SUMMARY!$C$6),MONTH(SUMMARY!$C$6)+0,1)))/SUMIFS(DETAIL!$M$2:$M$137,DETAIL!$B$2:$B$137,$B10,DETAIL!$F$2:$F$137,MONTH(DATE(YEAR(SUMMARY!$C$6),MONTH(SUMMARY!$C$6)+0,1))))/$C$6,"-") -> 0.34243104 | O10: =IFERROR($C$2*(SUMIFS(DETAIL!$R$2:$R$137,DETAIL!$B$2:$B$137,$B10,DETAIL!$F$2:$F$137,MONTH(DATE(YEAR(SUMMARY!$C$6),MONTH(SUMMARY!$C$6)+1,1)))/SUMIFS(DETAIL!$M$2:$M$137,DETAIL!$B$2:$B$137,$B10,DETAIL!$F$2:$F$137,MONTH(DATE(YEAR(SUMMARY!$C$6),MONTH(SUMMARY!$C$6)+1,1))))/$C$5+$C$3*(SUMIFS(DETAIL!$T$2:$T$137,DETAIL!$B$2:$B$137,$B10,DETAIL!$F$2:$F$137,MONTH(DATE(YEAR(SUMMARY!$C$6),MONTH(SUMMARY!$C$6)+1,1)))/SUMIFS(DETAIL!$M$2:$M$137,DETAIL!$B$2:$B$137,$B10,DETAIL!$F$2:$F$137,MONTH(DATE(YEAR(SUMMARY!$C$6),MONTH(SUMMARY!$C$6)+1,1))))/$C$6,"-") -> 0.37808672 | P10: =IFERROR($C$2*(SUMIFS(DETAIL!$R$2:$R$137,DETAIL!$B$2:$B$137,$B10,DETAIL!$F$2:$F$137,MONTH(DATE(YEAR(SUMMARY!$C$6),MONTH(SUMMARY!$C$6)+2,1)))/SUMIFS(DETAIL!$M$2:$M$137,DETAIL!$B$2:$B$137,$B10,DETAIL!$F$2:$F$137,MONTH(DATE(YEAR(SUMMARY!$C$6),MONTH(SUMMARY!$C$6)+2,1))))/$C$5+$C$3*(SUMIFS(DETAIL!$T$2:$T$137,DETAIL!$B$2:$B$137,$B10,DETAIL!$F$2:$F$137,MONTH(DATE(YEAR(SUMMARY!$C$6),MONTH(SUMMARY!$C$6)+2,1)))/SUMIFS(DETAIL!$M$2:$M$137,DETAIL!$B$2:$B$137,$B10,DETAIL!$F$2:$F$137,MONTH(DATE(YEAR(SUMMARY!$C$6),MONTH(SUMMARY!$C$6)+2,1))))/$C$6,"-") -> 0.31057809 | Q10: =IFERROR($C$2*(SUMIFS(DETAIL!$R$2:$R$137,DETAIL!$B$2:$B$137,$B10,DETAIL!$F$2:$F$137,MONTH(DATE(YEAR(SUMMARY!$C$6),MONTH(SUMMARY!$C$6)+3,1)))/SUMIFS(DETAIL!$M$2:$M$137,DETAIL!$B$2:$B$137,$B10,DETAIL!$F$2:$F$137,MONTH(DATE(YEAR(SUMMARY!$C$6),MONTH(SUMMARY!$C$6)+3,1))))/$C$5+$C$3*(SUMIFS(DETAIL!$T$2:$T$137,DETAIL!$B$2:$B$137,$B10,DETAIL!$F$2:$F$137,MONTH(DATE(YEAR(SUMMARY!$C$6),MONTH(SUMMARY!$C$6)+3,1)))/SUMIFS(DETAIL!$M$2:$M$137,DETAIL!$B$2:$B$137,$B10,DETAIL!$F$2:$F$137,MONTH(DATE(YEAR(SUMMARY!$C$6),MONTH(SUMMARY!$C$6)+3,1))))/$C$6,"-") -> 0.68680602 | R10: =IFERROR(INDEX(EVALUASI!$W$79:$W$132,MATCH($B10,EVALUASI!$C$79:$C$132,0)),"-") -> 75.5 | S10: =IFERROR(INDEX(EVALUASI!$X$79:$X$132,MATCH($B10,EVALUASI!$C$79:$C$132,0)),"-") -> Cukup | T10: =J10-ROW()/1000000 -> 0.44440106
A11: 2 | B11: =PEMAGANG!C4 -> BERLIAN AURELYA RAHMA | C11: =PEMAGANG!D4 -> AHMAD JALALUDDIN BASYAR | D11: =PEMAGANG!F4 -> PGS SM OF DIGITAL BUSSINES | E11: =SUMIFS(DETAIL!$M$2:$M$137,DETAIL!$B$2:$B$137,$B11) -> 36 | F11: =SUMIFS(DETAIL!$R$2:$R$137,DETAIL!$B$2:$B$137,$B11) -> 54 | G11: =SUMIFS(DETAIL!$T$2:$T$137,DETAIL!$B$2:$B$137,$B11) -> 3241 | H11: =IFERROR(F11/E11,0) -> 1.5 | I11: =IFERROR(G11/E11,0) -> 90.027778 | J11: =IFERROR($C$2*H11/$C$5+$C$3*I11/$C$6,0) -> 0.88319872 | K11: =MIN(1,IFERROR(J11/$C$4,0)) -> 0.88319872 | L11: =IF(E11=0,"-",IF(F11=0,"Tidak ada laporan",IF(J11>=$E$2,"Sangat Tinggi",IF(J11>=$E$3,"Tinggi",IF(J11>=$E$4,"Sedang","Rendah"))))) -> Sedang | M11: =RANK(T11,$T$10:$T$43) -> 16 | N11: =IFERROR($C$2*(SUMIFS(DETAIL!$R$2:$R$137,DETAIL!$B$2:$B$137,$B11,DETAIL!$F$2:$F$137,MONTH(DATE(YEAR(SUMMARY!$C$6),MONTH(SUMMARY!$C$6)+0,1)))/SUMIFS(DETAIL!$M$2:$M$137,DETAIL!$B$2:$B$137,$B11,DETAIL!$F$2:$F$137,MONTH(DATE(YEAR(SUMMARY!$C$6),MONTH(SUMMARY!$C$6)+0,1))))/$C$5+$C$3*(SUMIFS(DETAIL!$T$2:$T$137,DETAIL!$B$2:$B$137,$B11,DETAIL!$F$2:$F$137,MONTH(DATE(YEAR(SUMMARY!$C$6),MONTH(SUMMARY!$C$6)+0,1)))/SUMIFS(DETAIL!$M$2:$M$137,DETAIL!$B$2:$B$137,$B11,DETAIL!$F$2:$F$137,MONTH(DATE(YEAR(SUMMARY!$C$6),MONTH(SUMMARY!$C$6)+0,1))))/$C$6,"-") -> - | O11: =IFERROR($C$2*(SUMIFS(DETAIL!$R$2:$R$137,DETAIL!$B$2:$B$137,$B11,DETAIL!$F$2:$F$137,MONTH(DATE(YEAR(SUMMARY!$C$6),MONTH(SUMMARY!$C$6)+1,1)))/SUMIFS(DETAIL!$M$2:$M$137,DETAIL!$B$2:$B$137,$B11,DETAIL!$F$2:$F$137,MONTH(DATE(YEAR(SUMMARY!$C$6),MONTH(SUMMARY!$C$6)+1,1))))/$C$5+$C$3*(SUMIFS(DETAIL!$T$2:$T$137,DETAIL!$B$2:$B$137,$B11,DETAIL!$F$2:$F$137,MONTH(DATE(YEAR(SUMMARY!$C$6),MONTH(SUMMARY!$C$6)+1,1)))/SUMIFS(DETAIL!$M$2:$M$137,DETAIL!$B$2:$B$137,$B11,DETAIL!$F$2:$F$137,MONTH(DATE(YEAR(SUMMARY!$C$6),MONTH(SUMMARY!$C$6)+1,1))))/$C$6,"-") -> - | P11: =IFERROR($C$2*(SUMIFS(DETAIL!$R$2:$R$137,DETAIL!$B$2:$B$137,$B11,DETAIL!$F$2:$F$137,MONTH(DATE(YEAR(SUMMARY!$C$6),MONTH(SUMMARY!$C$6)+2,1)))/SUMIFS(DETAIL!$M$2:$M$137,DETAIL!$B$2:$B$137,$B11,DETAIL!$F$2:$F$137,MONTH(DATE(YEAR(SUMMARY!$C$6),MONTH(SUMMARY!$C$6)+2,1))))/$C$5+$C$3*(SUMIFS(DETAIL!$T$2:$T$137,DETAIL!$B$2:$B$137,$B11,DETAIL!$F$2:$F$137,MONTH(DATE(YEAR(SUMMARY!$C$6),MONTH(SUMMARY!$C$6)+2,1)))/SUMIFS(DETAIL!$M$2:$M$137,DETAIL!$B$2:$B$137,$B11,DETAIL!$F$2:$F$137,MONTH(DATE(YEAR(SUMMARY!$C$6),MONTH(SUMMARY!$C$6)+2,1))))/$C$6,"-") -> 0.79771007 | Q11: =IFERROR($C$2*(SUMIFS(DETAIL!$R$2:$R$137,DETAIL!$B$2:$B$137,$B11,DETAIL!$F$2:$F$137,MONTH(DATE(YEAR(SUMMARY!$C$6),MONTH(SUMMARY!$C$6)+3,1)))/SUMIFS(DETAIL!$M$2:$M$137,DETAIL!$B$2:$B$137,$B11,DETAIL!$F$2:$F$137,MONTH(DATE(YEAR(SUMMARY!$C$6),MONTH(SUMMARY!$C$6)+3,1))))/$C$5+$C$3*(SUMIFS(DETAIL!$T$2:$T$137,DETAIL!$B$2:$B$137,$B11,DETAIL!$F$2:$F$137,MONTH(DATE(YEAR(SUMMARY!$C$6),MONTH(SUMMARY!$C$6)+3,1)))/SUMIFS(DETAIL!$M$2:$M$137,DETAIL!$B$2:$B$137,$B11,DETAIL!$F$2:$F$137,MONTH(DATE(YEAR(SUMMARY!$C$6),MONTH(SUMMARY!$C$6)+3,1))))/$C$6,"-") -> 0.93760059 | R11: =IFERROR(INDEX(EVALUASI!$W$79:$W$132,MATCH($B11,EVALUASI!$C$79:$C$132,0)),"-") -> 89.8 | S11: =IFERROR(INDEX(EVALUASI!$X$79:$X$132,MATCH($B11,EVALUASI!$C$79:$C$132,0)),"-") -> Baik | T11: =J11-ROW()/1000000 -> 0.88318772
A12: 3 | B12: =PEMAGANG!C5 -> CLARA OKTAVIA FIRDAUS | C12: =PEMAGANG!D5 -> AHMAD JALALUDDIN BASYAR | D12: =PEMAGANG!F5 -> PGS SM OF DIGITAL BUSSINES | E12: =SUMIFS(DETAIL!$M$2:$M$137,DETAIL!$B$2:$B$137,$B12) -> 33 | F12: =SUMIFS(DETAIL!$R$2:$R$137,DETAIL!$B$2:$B$137,$B12) -> 49 | G12: =SUMIFS(DETAIL!$T$2:$T$137,DETAIL!$B$2:$B$137,$B12) -> 1869 | H12: =IFERROR(F12/E12,0) -> 1.4848485 | I12: =IFERROR(G12/E12,0) -> 56.636364 | J12: =IFERROR($C$2*H12/$C$5+$C$3*I12/$C$6,0) -> 0.70710565 | K12: =MIN(1,IFERROR(J12/$C$4,0)) -> 0.70710565 | L12: =IF(E12=0,"-",IF(F12=0,"Tidak ada laporan",IF(J12>=$E$2,"Sangat Tinggi",IF(J12>=$E$3,"Tinggi",IF(J12>=$E$4,"Sedang","Rendah"))))) -> Sedang | M12: =RANK(T12,$T$10:$T$43) -> 19 | N12: =IFERROR($C$2*(SUMIFS(DETAIL!$R$2:$R$137,DETAIL!$B$2:$B$137,$B12,DETAIL!$F$2:$F$137,MONTH(DATE(YEAR(SUMMARY!$C$6),MONTH(SUMMARY!$C$6)+0,1)))/SUMIFS(DETAIL!$M$2:$M$137,DETAIL!$B$2:$B$137,$B12,DETAIL!$F$2:$F$137,MONTH(DATE(YEAR(SUMMARY!$C$6),MONTH(SUMMARY!$C$6)+0,1))))/$C$5+$C$3*(SUMIFS(DETAIL!$T$2:$T$137,DETAIL!$B$2:$B$137,$B12,DETAIL!$F$2:$F$137,MONTH(DATE(YEAR(SUMMARY!$C$6),MONTH(SUMMARY!$C$6)+0,1)))/SUMIFS(DETAIL!$M$2:$M$137,DETAIL!$B$2:$B$137,$B12,DETAIL!$F$2:$F$137,MONTH(DATE(YEAR(SUMMARY!$C$6),MONTH(SUMMARY!$C$6)+0,1))))/$C$6,"-") -> - | O12: =IFERROR($C$2*(SUMIFS(DETAIL!$R$2:$R$137,DETAIL!$B$2:$B$137,$B12,DETAIL!$F$2:$F$137,MONTH(DATE(YEAR(SUMMARY!$C$6),MONTH(SUMMARY!$C$6)+1,1)))/SUMIFS(DETAIL!$M$2:$M$137,DETAIL!$B$2:$B$137,$B12,DETAIL!$F$2:$F$137,MONTH(DATE(YEAR(SUMMARY!$C$6),MONTH(SUMMARY!$C$6)+1,1))))/$C$5+$C$3*(SUMIFS(DETAIL!$T$2:$T$137,DETAIL!$B$2:$B$137,$B12,DETAIL!$F$2:$F$137,MONTH(DATE(YEAR(SUMMARY!$C$6),MONTH(SUMMARY!$C$6)+1,1)))/SUMIFS(DETAIL!$M$2:$M$137,DETAIL!$B$2:$B$137,$B12,DETAIL!$F$2:$F$137,MONTH(DATE(YEAR(SUMMARY!$C$6),MONTH(SUMMARY!$C$6)+1,1))))/$C$6,"-") -> - | P12: =IFERROR($C$2*(SUMIFS(DETAIL!$R$2:$R$137,DETAIL!$B$2:$B$137,$B12,DETAIL!$F$2:$F$137,MONTH(DATE(YEAR(SUMMARY!$C$6),MONTH(SUMMARY!$C$6)+2,1)))/SUMIFS(DETAIL!$M$2:$M$137,DETAIL!$B$2:$B$137,$B12,DETAIL!$F$2:$F$137,MONTH(DATE(YEAR(SUMMARY!$C$6),MONTH(SUMMARY!$C$6)+2,1))))/$C$5+$C$3*(SUMIFS(DETAIL!$T$2:$T$137,DETAIL!$B$2:$B$137,$B12,DETAIL!$F$2:$F$137,MONTH(DATE(YEAR(SUMMARY!$C$6),MONTH(SUMMARY!$C$6)+2,1)))/SUMIFS(DETAIL!$M$2:$M$137,DETAIL!$B$2:$B$137,$B12,DETAIL!$F$2:$F$137,MONTH(DATE(YEAR(SUMMARY!$C$6),MONTH(SUMMARY!$C$6)+2,1))))/$C$6,"-") -> 0.57911303 | Q12: =IFERROR($C$2*(SUMIFS(DETAIL!$R$2:$R$137,DETAIL!$B$2:$B$137,$B12,DETAIL!$F$2:$F$137,MONTH(DATE(YEAR(SUMMARY!$C$6),MONTH(SUMMARY!$C$6)+3,1)))/SUMIFS(DETAIL!$M$2:$M$137,DETAIL!$B$2:$B$137,$B12,DETAIL!$F$2:$F$137,MONTH(DATE(YEAR(SUMMARY!$C$6),MONTH(SUMMARY!$C$6)+3,1))))/$C$5+$C$3*(SUMIFS(DETAIL!$T$2:$T$137,DETAIL!$B$2:$B$137,$B12,DETAIL!$F$2:$F$137,MONTH(DATE(YEAR(SUMMARY!$C$6),MONTH(SUMMARY!$C$6)+3,1)))/SUMIFS(DETAIL!$M$2:$M$137,DETAIL!$B$2:$B$137,$B12,DETAIL!$F$2:$F$137,MONTH(DATE(YEAR(SUMMARY!$C$6),MONTH(SUMMARY!$C$6)+3,1))))/$C$6,"-") -> 0.79030085 | R12: =IFERROR(INDEX(EVALUASI!$W$79:$W$132,MATCH($B12,EVALUASI!$C$79:$C$132,0)),"-") -> 82.7 | S12: =IFERROR(INDEX(EVALUASI!$X$79:$X$132,MATCH($B12,EVALUASI!$C$79:$C$132,0)),"-") -> Baik | T12: =J12-ROW()/1000000 -> 0.70709365
A13: 4 | B13: =PEMAGANG!C6 -> NELLA DIFA SALSABILAH | C13: =PEMAGANG!D6 -> AHMAD JALALUDDIN BASYAR | D13: =PEMAGANG!F6 -> PGS SM OF DIGITAL BUSSINES | E13: =SUMIFS(DETAIL!$M$2:$M$137,DETAIL!$B$2:$B$137,$B13) -> 84 | F13: =SUMIFS(DETAIL!$R$2:$R$137,DETAIL!$B$2:$B$137,$B13) -> 168 | G13: =SUMIFS(DETAIL!$T$2:$T$137,DETAIL!$B$2:$B$137,$B13) -> 1426 | H13: =IFERROR(F13/E13,0) -> 2 | I13: =IFERROR(G13/E13,0) -> 16.97619 | J13: =IFERROR($C$2*H13/$C$5+$C$3*I13/$C$6,0) -> 0.64718601 | K13: =MIN(1,IFERROR(J13/$C$4,0)) -> 0.64718601 | L13: =IF(E13=0,"-",IF(F13=0,"Tidak ada laporan",IF(J13>=$E$2,"Sangat Tinggi",IF(J13>=$E$3,"Tinggi",IF(J13>=$E$4,"Sedang","Rendah"))))) -> Rendah | M13: =RANK(T13,$T$10:$T$43) -> 21 | N13: =IFERROR($C$2*(SUMIFS(DETAIL!$R$2:$R$137,DETAIL!$B$2:$B$137,$B13,DETAIL!$F$2:$F$137,MONTH(DATE(YEAR(SUMMARY!$C$6),MONTH(SUMMARY!$C$6)+0,1)))/SUMIFS(DETAIL!$M$2:$M$137,DETAIL!$B$2:$B$137,$B13,DETAIL!$F$2:$F$137,MONTH(DATE(YEAR(SUMMARY!$C$6),MONTH(SUMMARY!$C$6)+0,1))))/$C$5+$C$3*(SUMIFS(DETAIL!$T$2:$T$137,DETAIL!$B$2:$B$137,$B13,DETAIL!$F$2:$F$137,MONTH(DATE(YEAR(SUMMARY!$C$6),MONTH(SUMMARY!$C$6)+0,1)))/SUMIFS(DETAIL!$M$2:$M$137,DETAIL!$B$2:$B$137,$B13,DETAIL!$F$2:$F$137,MONTH(DATE(YEAR(SUMMARY!$C$6),MONTH(SUMMARY!$C$6)+0,1))))/$C$6,"-") -> 0.62250529 | O13: =IFERROR($C$2*(SUMIFS(DETAIL!$R$2:$R$137,DETAIL!$B$2:$B$137,$B13,DETAIL!$F$2:$F$137,MONTH(DATE(YEAR(SUMMARY!$C$6),MONTH(SUMMARY!$C$6)+1,1)))/SUMIFS(DETAIL!$M$2:$M$137,DETAIL!$B$2:$B$137,$B13,DETAIL!$F$2:$F$137,MONTH(DATE(YEAR(SUMMARY!$C$6),MONTH(SUMMARY!$C$6)+1,1))))/$C$5+$C$3*(SUMIFS(DETAIL!$T$2:$T$137,DETAIL!$B$2:$B$137,$B13,DETAIL!$F$2:$F$137,MONTH(DATE(YEAR(SUMMARY!$C$6),MONTH(SUMMARY!$C$6)+1,1)))/SUMIFS(DETAIL!$M$2:$M$137,DETAIL!$B$2:$B$137,$B13,DETAIL!$F$2:$F$137,MONTH(DATE(YEAR(SUMMARY!$C$6),MONTH(SUMMARY!$C$6)+1,1))))/$C$6,"-") -> 0.68051237 | P13: =IFERROR($C$2*(SUMIFS(DETAIL!$R$2:$R$137,DETAIL!$B$2:$B$137,$B13,DETAIL!$F$2:$F$137,MONTH(DATE(YEAR(SUMMARY!$C$6),MONTH(SUMMARY!$C$6)+2,1)))/SUMIFS(DETAIL!$M$2:$M$137,DETAIL!$B$2:$B$137,$B13,DETAIL!$F$2:$F$137,MONTH(DATE(YEAR(SUMMARY!$C$6),MONTH(SUMMARY!$C$6)+2,1))))/$C$5+$C$3*(SUMIFS(DETAIL!$T$2:$T$137,DETAIL!$B$2:$B$137,$B13,DETAIL!$F$2:$F$137,MONTH(DATE(YEAR(SUMMARY!$C$6),MONTH(SUMMARY!$C$6)+2,1)))/SUMIFS(DETAIL!$M$2:$M$137,DETAIL!$B$2:$B$137,$B13,DETAIL!$F$2:$F$137,MONTH(DATE(YEAR(SUMMARY!$C$6),MONTH(SUMMARY!$C$6)+2,1))))/$C$6,"-") -> 0.64459981 | Q13: =IFERROR($C$2*(SUMIFS(DETAIL!$R$2:$R$137,DETAIL!$B$2:$B$137,$B13,DETAIL!$F$2:$F$137,MONTH(DATE(YEAR(SUMMARY!$C$6),MONTH(SUMMARY!$C$6)+3,1)))/SUMIFS(DETAIL!$M$2:$M$137,DETAIL!$B$2:$B$137,$B13,DETAIL!$F$2:$F$137,MONTH(DATE(YEAR(SUMMARY!$C$6),MONTH(SUMMARY!$C$6)+3,1))))/$C$5+$C$3*(SUMIFS(DETAIL!$T$2:$T$137,DETAIL!$B$2:$B$137,$B13,DETAIL!$F$2:$F$137,MONTH(DATE(YEAR(SUMMARY!$C$6),MONTH(SUMMARY!$C$6)+3,1)))/SUMIFS(DETAIL!$M$2:$M$137,DETAIL!$B$2:$B$137,$B13,DETAIL!$F$2:$F$137,MONTH(DATE(YEAR(SUMMARY!$C$6),MONTH(SUMMARY!$C$6)+3,1))))/$C$6,"-") -> 0.63701536 | R13: =IFERROR(INDEX(EVALUASI!$W$79:$W$132,MATCH($B13,EVALUASI!$C$79:$C$132,0)),"-") -> 88.2 | S13: =IFERROR(INDEX(EVALUASI!$X$79:$X$132,MATCH($B13,EVALUASI!$C$79:$C$132,0)),"-") -> Baik | T13: =J13-ROW()/1000000 -> 0.64717301
A14: 5 | B14: =PEMAGANG!C7 -> SYAKIRAH TSALTSA FITRIAH | C14: =PEMAGANG!D7 -> AHMAD JALALUDDIN BASYAR | D14: =PEMAGANG!F7 -> PGS SM OF DIGITAL BUSSINES | E14: =SUMIFS(DETAIL!$M$2:$M$137,DETAIL!$B$2:$B$137,$B14) -> 36 | F14: =SUMIFS(DETAIL!$R$2:$R$137,DETAIL!$B$2:$B$137,$B14) -> 80 | G14: =SUMIFS(DETAIL!$T$2:$T$137,DETAIL!$B$2:$B$137,$B14) -> 10052 | H14: =IFERROR(F14/E14,0) -> 2.2222222 | I14: =IFERROR(G14/E14,0) -> 279.22222 | J14: =IFERROR($C$2*H14/$C$5+$C$3*I14/$C$6,0) -> 2.0590616 | K14: =MIN(1,IFERROR(J14/$C$4,0)) -> 1 | L14: =IF(E14=0,"-",IF(F14=0,"Tidak ada laporan",IF(J14>=$E$2,"Sangat Tinggi",IF(J14>=$E$3,"Tinggi",IF(J14>=$E$4,"Sedang","Rendah"))))) -> Sangat Tinggi | M14: =RANK(T14,$T$10:$T$43) -> 2 | N14: =IFERROR($C$2*(SUMIFS(DETAIL!$R$2:$R$137,DETAIL!$B$2:$B$137,$B14,DETAIL!$F$2:$F$137,MONTH(DATE(YEAR(SUMMARY!$C$6),MONTH(SUMMARY!$C$6)+0,1)))/SUMIFS(DETAIL!$M$2:$M$137,DETAIL!$B$2:$B$137,$B14,DETAIL!$F$2:$F$137,MONTH(DATE(YEAR(SUMMARY!$C$6),MONTH(SUMMARY!$C$6)+0,1))))/$C$5+$C$3*(SUMIFS(DETAIL!$T$2:$T$137,DETAIL!$B$2:$B$137,$B14,DETAIL!$F$2:$F$137,MONTH(DATE(YEAR(SUMMARY!$C$6),MONTH(SUMMARY!$C$6)+0,1)))/SUMIFS(DETAIL!$M$2:$M$137,DETAIL!$B$2:$B$137,$B14,DETAIL!$F$2:$F$137,MONTH(DATE(YEAR(SUMMARY!$C$6),MONTH(SUMMARY!$C$6)+0,1))))/$C$6,"-") -> - | O14: =IFERROR($C$2*(SUMIFS(DETAIL!$R$2:$R$137,DETAIL!$B$2:$B$137,$B14,DETAIL!$F$2:$F$137,MONTH(DATE(YEAR(SUMMARY!$C$6),MONTH(SUMMARY!$C$6)+1,1)))/SUMIFS(DETAIL!$M$2:$M$137,DETAIL!$B$2:$B$137,$B14,DETAIL!$F$2:$F$137,MONTH(DATE(YEAR(SUMMARY!$C$6),MONTH(SUMMARY!$C$6)+1,1))))/$C$5+$C$3*(SUMIFS(DETAIL!$T$2:$T$137,DETAIL!$B$2:$B$137,$B14,DETAIL!$F$2:$F$137,MONTH(DATE(YEAR(SUMMARY!$C$6),MONTH(SUMMARY!$C$6)+1,1)))/SUMIFS(DETAIL!$M$2:$M$137,DETAIL!$B$2:$B$137,$B14,DETAIL!$F$2:$F$137,MONTH(DATE(YEAR(SUMMARY!$C$6),MONTH(SUMMARY!$C$6)+1,1))))/$C$6,"-") -> - | P14: =IFERROR($C$2*(SUMIFS(DETAIL!$R$2:$R$137,DETAIL!$B$2:$B$137,$B14,DETAIL!$F$2:$F$137,MONTH(DATE(YEAR(SUMMARY!$C$6),MONTH(SUMMARY!$C$6)+2,1)))/SUMIFS(DETAIL!$M$2:$M$137,DETAIL!$B$2:$B$137,$B14,DETAIL!$F$2:$F$137,MONTH(DATE(YEAR(SUMMARY!$C$6),MONTH(SUMMARY!$C$6)+2,1))))/$C$5+$C$3*(SUMIFS(DETAIL!$T$2:$T$137,DETAIL!$B$2:$B$137,$B14,DETAIL!$F$2:$F$137,MONTH(DATE(YEAR(SUMMARY!$C$6),MONTH(SUMMARY!$C$6)+2,1)))/SUMIFS(DETAIL!$M$2:$M$137,DETAIL!$B$2:$B$137,$B14,DETAIL!$F$2:$F$137,MONTH(DATE(YEAR(SUMMARY!$C$6),MONTH(SUMMARY!$C$6)+2,1))))/$C$6,"-") -> 1.9624055 | Q14: =IFERROR($C$2*(SUMIFS(DETAIL!$R$2:$R$137,DETAIL!$B$2:$B$137,$B14,DETAIL!$F$2:$F$137,MONTH(DATE(YEAR(SUMMARY!$C$6),MONTH(SUMMARY!$C$6)+3,1)))/SUMIFS(DETAIL!$M$2:$M$137,DETAIL!$B$2:$B$137,$B14,DETAIL!$F$2:$F$137,MONTH(DATE(YEAR(SUMMARY!$C$6),MONTH(SUMMARY!$C$6)+3,1))))/$C$5+$C$3*(SUMIFS(DETAIL!$T$2:$T$137,DETAIL!$B$2:$B$137,$B14,DETAIL!$F$2:$F$137,MONTH(DATE(YEAR(SUMMARY!$C$6),MONTH(SUMMARY!$C$6)+3,1)))/SUMIFS(DETAIL!$M$2:$M$137,DETAIL!$B$2:$B$137,$B14,DETAIL!$F$2:$F$137,MONTH(DATE(YEAR(SUMMARY!$C$6),MONTH(SUMMARY!$C$6)+3,1))))/$C$6,"-") -> 2.12057 | R14: =IFERROR(INDEX(EVALUASI!$W$79:$W$132,MATCH($B14,EVALUASI!$C$79:$C$132,0)),"-") -> 97.8 | S14: =IFERROR(INDEX(EVALUASI!$X$79:$X$132,MATCH($B14,EVALUASI!$C$79:$C$132,0)),"-") -> Sangat Baik | T14: =J14-ROW()/1000000 -> 2.0590476
