Workbook

Sheet WILAYAH
A1: REKAP EVALUASI HANDBOOK OPERASIONAL SID PER WILAYAH
B2: Data per tanggal | C2: =IFERROR(MAX(DATA!$B$2:$B$1001),"") -> 46314.354
A4: No | B4: Uraian | C4: Jumlah | I4: Persentase | N4: Prioritas | O4: Tindak Lanjut
C5: Jawa Barat | D5: Jawa Tengah | E5: Jawa Timur | F5: Luar Pulau | G5: Total | I5: Jawa Barat | J5: Jawa Tengah | K5: Jawa Timur | L5: Luar Pulau | M5: Total
B6: Partisipasi
A7: 1 | B7: Jumlah pegawai | C7: =SUMIF(PROGRES!$A$2:$A$92,C$5,PROGRES!$C$2:$C$92) -> 99 | D7: =SUMIF(PROGRES!$A$2:$A$92,D$5,PROGRES!$C$2:$C$92) -> 158 | E7: =SUMIF(PROGRES!$A$2:$A$92,E$5,PROGRES!$C$2:$C$92) -> 215 | F7: =SUMIF(PROGRES!$A$2:$A$92,F$5,PROGRES!$C$2:$C$92) -> 40 | G7: =SUM(C7:F7) -> 512
A8: 2 | B8: Jumlah yang mengisi | C8: =COUNTIF(DATA!$F$2:$F$1001,C$5) -> 48 | D8: =COUNTIF(DATA!$F$2:$F$1001,D$5) -> 92 | E8: =COUNTIF(DATA!$F$2:$F$1001,E$5) -> 64 | F8: =COUNTIF(DATA!$F$2:$F$1001,F$5) -> 38 | G8: =COUNT(DATA!$A$2:$A$1001) -> 242 | I8: =IFERROR(C8/C$7,0) -> 0.48484848 | J8: =IFERROR(D8/D$7,0) -> 0.58227848 | K8: =IFERROR(E8/E$7,0) -> 0.29767442 | L8: =IFERROR(F8/F$7,0) -> 0.95 | M8: =IFERROR(G8/G$7,0) -> 0.47265625
A9: 3 | B9: Jumlah orang (NIK unik) | C9: =SUMIFS(DATA!$T$2:$T$1001,DATA!$F$2:$F$1001,C$5) -> 48 | D9: =SUMIFS(DATA!$T$2:$T$1001,DATA!$F$2:$F$1001,D$5) -> 90 | E9: =SUMIFS(DATA!$T$2:$T$1001,DATA!$F$2:$F$1001,E$5) -> 63 | F9: =SUMIFS(DATA!$T$2:$T$1001,DATA!$F$2:$F$1001,F$5) -> 36 | G9: =SUM(DATA!$T$2:$T$1001) -> 237
A10: 4 | B10: BM | C10: =COUNTIFS(DATA!$F$2:$F$1001,C$5,DATA!$H$2:$H$1001,"BM") -> 11 | D10: =COUNTIFS(DATA!$F$2:$F$1001,D$5,DATA!$H$2:$H$1001,"BM") -> 22 | E10: =COUNTIFS(DATA!$F$2:$F$1001,E$5,DATA!$H$2:$H$1001,"BM") -> 14 | F10: =COUNTIFS(DATA!$F$2:$F$1001,F$5,DATA!$H$2:$H$1001,"BM") -> 9 | G10: =COUNTIF(DATA!$H$2:$H$1001,"BM") -> 56 | I10: =IFERROR(C10/C$8,0) -> 0.22916667 | J10: =IFERROR(D10/D$8,0) -> 0.23913043 | K10: =IFERROR(E10/E$8,0) -> 0.21875 | L10: =IFERROR(F10/F$8,0) -> 0.23684211 | M10: =IFERROR(G10/G$8,0) -> 0.23140496
A11: 5 | B11: CRO | C11: =COUNTIFS(DATA!$F$2:$F$1001,C$5,DATA!$H$2:$H$1001,"CRO") -> 29 | D11: =COUNTIFS(DATA!$F$2:$F$1001,D$5,DATA!$H$2:$H$1001,"CRO") -> 50 | E11: =COUNTIFS(DATA!$F$2:$F$1001,E$5,DATA!$H$2:$H$1001,"CRO") -> 34 | F11: =COUNTIFS(DATA!$F$2:$F$1001,F$5,DATA!$H$2:$H$1001,"CRO") -> 20 | G11: =COUNTIF(DATA!$H$2:$H$1001,"CRO") -> 133 | I11: =IFERROR(C11/C$8,0) -> 0.60416667 | J11: =IFERROR(D11/D$8,0) -> 0.54347826 | K11: =IFERROR(E11/E$8,0) -> 0.53125 | L11: =IFERROR(F11/F$8,0) -> 0.52631579 | M11: =IFERROR(G11/G$8,0) -> 0.54958678
A12: 6 | B12: BAO | C12: =COUNTIFS(DATA!$F$2:$F$1001,C$5,DATA!$H$2:$H$1001,"BAO") -> 8 | D12: =COUNTIFS(DATA!$F$2:$F$1001,D$5,DATA!$H$2:$H$1001,"BAO") -> 20 | E12: =COUNTIFS(DATA!$F$2:$F$1001,E$5,DATA!$H$2:$H$1001,"BAO") -> 16 | F12: =COUNTIFS(DATA!$F$2:$F$1001,F$5,DATA!$H$2:$H$1001,"BAO") -> 9 | G12: =COUNTIF(DATA!$H$2:$H$1001,"BAO") -> 53 | I12: =IFERROR(C12/C$8,0) -> 0.16666667 | J12: =IFERROR(D12/D$8,0) -> 0.2173913 | K12: =IFERROR(E12/E$8,0) -> 0.25 | L12: =IFERROR(F12/F$8,0) -> 0.23684211 | M12: =IFERROR(G12/G$8,0) -> 0.21900826
B13: Navigasi & struktur menu
A14: 7 | B14: Mudah | C14: =COUNTIFS(DATA!$F$2:$F$1001,C$5,DATA!$I$2:$I$1001,"MUDAH") -> 33 | D14: =COUNTIFS(DATA!$F$2:$F$1001,D$5,DATA!$I$2:$I$1001,"MUDAH") -> 49 | E14: =COUNTIFS(DATA!$F$2:$F$1001,E$5,DATA!$I$2:$I$1001,"MUDAH") -> 42 | F14: =COUNTIFS(DATA!$F$2:$F$1001,F$5,DATA!$I$2:$I$1001,"MUDAH") -> 29 | G14: =COUNTIF(DATA!$I$2:$I$1001,"MUDAH") -> 153 | I14: =IFERROR(C14/C$8,0) -> 0.6875 | J14: =IFERROR(D14/D$8,0) -> 0.5326087 | K14: =IFERROR(E14/E$8,0) -> 0.65625 | L14: =IFERROR(F14/F$8,0) -> 0.76315789 | M14: =IFERROR(G14/G$8,0) -> 0.6322314
A15: 8 | B15: Cukup | C15: =COUNTIFS(DATA!$F$2:$F$1001,C$5,DATA!$I$2:$I$1001,"CUKUP") -> 14 | D15: =COUNTIFS(DATA!$F$2:$F$1001,D$5,DATA!$I$2:$I$1001,"CUKUP") -> 43 | E15: =COUNTIFS(DATA!$F$2:$F$1001,E$5,DATA!$I$2:$I$1001,"CUKUP") -> 22 | F15: =COUNTIFS(DATA!$F$2:$F$1001,F$5,DATA!$I$2:$I$1001,"CUKUP") -> 9 | G15: =COUNTIF(DATA!$I$2:$I$1001,"CUKUP") -> 88 | I15: =IFERROR(C15/C$8,0) -> 0.29166667 | J15: =IFERROR(D15/D$8,0) -> 0.4673913 | K15: =IFERROR(E15/E$8,0) -> 0.34375 | L15: =IFERROR(F15/F$8,0) -> 0.23684211 | M15: =IFERROR(G15/G$8,0) -> 0.36363636
A16: 9 | B16: Sulit | C16: =COUNTIFS(DATA!$F$2:$F$1001,C$5,DATA!$I$2:$I$1001,"SULIT") -> 1 | D16: =COUNTIFS(DATA!$F$2:$F$1001,D$5,DATA!$I$2:$I$1001,"SULIT") -> 0 | E16: =COUNTIFS(DATA!$F$2:$F$1001,E$5,DATA!$I$2:$I$1001,"SULIT") -> 0 | F16: =COUNTIFS(DATA!$F$2:$F$1001,F$5,DATA!$I$2:$I$1001,"SULIT") -> 0 | G16: =COUNTIF(DATA!$I$2:$I$1001,"SULIT") -> 1 | I16: =IFERROR(C16/C$8,0) -> 0.020833333 | J16: =IFERROR(D16/D$8,0) -> 0 | K16: =IFERROR(E16/E$8,0) -> 0 | L16: =IFERROR(F16/F$8,0) -> 0 | M16: =IFERROR(G16/G$8,0) -> 0.0041322314
B17: Tampilan di HP
A18: 10 | B18: Ya, responsif | C18: =COUNTIFS(DATA!$F$2:$F$1001,C$5,DATA!$J$2:$J$1001,"YA") -> 32 | D18: =COUNTIFS(DATA!$F$2:$F$1001,D$5,DATA!$J$2:$J$1001,"YA") -> 49 | E18: =COUNTIFS(DATA!$F$2:$F$1001,E$5,DATA!$J$2:$J$1001,"YA") -> 53 | F18: =COUNTIFS(DATA!$F$2:$F$1001,F$5,DATA!$J$2:$J$1001,"YA") -> 31 | G18: =COUNTIF(DATA!$J$2:$J$1001,"YA") -> 165 | I18: =IFERROR(C18/C$8,0) -> 0.66666667 | J18: =IFERROR(D18/D$8,0) -> 0.5326087 | K18: =IFERROR(E18/E$8,0) -> 0.828125 | L18: =IFERROR(F18/F$8,0) -> 0.81578947 | M18: =IFERROR(G18/G$8,0) -> 0.68181818
A19: 11 | B19: Cukup | C19: =COUNTIFS(DATA!$F$2:$F$1001,C$5,DATA!$J$2:$J$1001,"CUKUP") -> 15 | D19: =COUNTIFS(DATA!$F$2:$F$1001,D$5,DATA!$J$2:$J$1001,"CUKUP") -> 42 | E19: =COUNTIFS(DATA!$F$2:$F$1001,E$5,DATA!$J$2:$J$1001,"CUKUP") -> 10 | F19: =COUNTIFS(DATA!$F$2:$F$1001,F$5,DATA!$J$2:$J$1001,"CUKUP") -> 7 | G19: =COUNTIF(DATA!$J$2:$J$1001,"CUKUP") -> 74 | I19: =IFERROR(C19/C$8,0) -> 0.3125 | J19: =IFERROR(D19/D$8,0) -> 0.45652174 | K19: =IFERROR(E19/E$8,0) -> 0.15625 | L19: =IFERROR(F19/F$8,0) -> 0.18421053 | M19: =IFERROR(G19/G$8,0) -> 0.30578512
A20: 12 | B20: Kurang | C20: =COUNTIFS(DATA!$F$2:$F$1001,C$5,DATA!$J$2:$J$1001,"KURANG") -> 1 | D20: =COUNTIFS(DATA!$F$2:$F$1001,D$5,DATA!$J$2:$J$1001,"KURANG") -> 1 | E20: =COUNTIFS(DATA!$F$2:$F$1001,E$5,DATA!$J$2:$J$1001,"KURANG") -> 1 | F20: =COUNTIFS(DATA!$F$2:$F$1001,F$5,DATA!$J$2:$J$1001,"KURANG") -> 0 | G20: =COUNTIF(DATA!$J$2:$J$1001,"KURANG") -> 3 | I20: =IFERROR(C20/C$8,0) -> 0.020833333 | J20: =IFERROR(D20/D$8,0) -> 0.010869565 | K20: =IFERROR(E20/E$8,0) -> 0.015625 | L20: =IFERROR(F20/F$8,0) -> 0 | M20: =IFERROR(G20/G$8,0) -> 0.012396694
B21: Kejelasan materi / SOP
A22: 13 | B22: Mudah | C22: =COUNTIFS(DATA!$F$2:$F$1001,C$5,DATA!$K$2:$K$1001,"MUDAH") -> 23 | D22: =COUNTIFS(DATA!$F$2:$F$1001,D$5,DATA!$K$2:$K$1001,"MUDAH") -> 48 | E22: =COUNTIFS(DATA!$F$2:$F$1001,E$5,DATA!$K$2:$K$1001,"MUDAH") -> 38 | F22: =COUNTIFS(DATA!$F$2:$F$1001,F$5,DATA!$K$2:$K$1001,"MUDAH") -> 24 | G22: =COUNTIF(DATA!$K$2:$K$1001,"MUDAH") -> 133 | I22: =IFERROR(C22/C$8,0) -> 0.47916667 | J22: =IFERROR(D22/D$8,0) -> 0.52173913 | K22: =IFERROR(E22/E$8,0) -> 0.59375 | L22: =IFERROR(F22/F$8,0) -> 0.63157895 | M22: =IFERROR(G22/G$8,0) -> 0.54958678
A23: 14 | B23: Cukup | C23: =COUNTIFS(DATA!$F$2:$F$1001,C$5,DATA!$K$2:$K$1001,"CUKUP") -> 25 | D23: =COUNTIFS(DATA!$F$2:$F$1001,D$5,DATA!$K$2:$K$1001,"CUKUP") -> 44 | E23: =COUNTIFS(DATA!$F$2:$F$1001,E$5,DATA!$K$2:$K$1001,"CUKUP") -> 25 | F23: =COUNTIFS(DATA!$F$2:$F$1001,F$5,DATA!$K$2:$K$1001,"CUKUP") -> 14 | G23: =COUNTIF(DATA!$K$2:$K$1001,"CUKUP") -> 108 | I23: =IFERROR(C23/C$8,0) -> 0.52083333 | J23: =IFERROR(D23/D$8,0) -> 0.47826087 | K23: =IFERROR(E23/E$8,0) -> 0.390625 | L23: =IFERROR(F23/F$8,0) -> 0.36842105 | M23: =IFERROR(G23/G$8,0) -> 0.44628099
A24: 15 | B24: Sulit | C24: =COUNTIFS(DATA!$F$2:$F$1001,C$5,DATA!$K$2:$K$1001,"SULIT") -> 0 | D24: =COUNTIFS(DATA!$F$2:$F$1001,D$5,DATA!$K$2:$K$1001,"SULIT") -> 0 | E24: =COUNTIFS(DATA!$F$2:$F$1001,E$5,DATA!$K$2:$K$1001,"SULIT") -> 1 | F24: =COUNTIFS(DATA!$F$2:$F$1001,F$5,DATA!$K$2:$K$1001,"SULIT") -> 0 | G24: =COUNTIF(DATA!$K$2:$K$1001,"SULIT") -> 1 | I24: =IFERROR(C24/C$8,0) -> 0 | J24: =IFERROR(D24/D$8,0) -> 0 | K24: =IFERROR(E24/E$8,0) -> 0.015625 | L24: =IFERROR(F24/F$8,0) -> 0 | M24: =IFERROR(G24/G$8,0) -> 0.0041322314
B25: Materi paling membantu
A26: 16 | B26: Aktivitas Harian | C26: =SUMIFS(DATA!$L$2:$L$1001,DATA!$F$2:$F$1001,C$5) -> 37 | D26: =SUMIFS(DATA!$L$2:$L$1001,DATA!$F$2:$F$1001,D$5) -> 75 | E26: =SUMIFS(DATA!$L$2:$L$1001,DATA!$F$2:$F$1001,E$5) -> 49 | F26: =SUMIFS(DATA!$L$2:$L$1001,DATA!$F$2:$F$1001,F$5) -> 32 | G26: =SUM(DATA!$L$2:$L$1001) -> 193 | I26: =IFERROR(C26/C$8,0) -> 0.77083333 | J26: =IFERROR(D26/D$8,0) -> 0.81521739 | K26: =IFERROR(E26/E$8,0) -> 0.765625 | L26: =IFERROR(F26/F$8,0) -> 0.84210526 | M26: =IFERROR(G26/G$8,0) -> 0.79752066
A27: 17 | B27: Aktivitas Mingguan | C27: =SUMIFS(DATA!$M$2:$M$1001,DATA!$F$2:$F$1001,C$5) -> 13 | D27: =SUMIFS(DATA!$M$2:$M$1001,DATA!$F$2:$F$1001,D$5) -> 36 | E27: =SUMIFS(DATA!$M$2:$M$1001,DATA!$F$2:$F$1001,E$5) -> 22 | F27: =SUMIFS(DATA!$M$2:$M$1001,DATA!$F$2:$F$1001,F$5) -> 15 | G27: =SUM(DATA!$M$2:$M$1001) -> 86 | I27: =IFERROR(C27/C$8,0) -> 0.27083333 | J27: =IFERROR(D27/D$8,0) -> 0.39130435 | K27: =IFERROR(E27/E$8,0) -> 0.34375 | L27: =IFERROR(F27/F$8,0) -> 0.39473684 | M27: =IFERROR(G27/G$8,0) -> 0.3553719
A28: 18 | B28: Aktivitas Bulanan | C28: =SUMIFS(DATA!$N$2:$N$1001,DATA!$F$2:$F$1001,C$5) -> 17 | D28: =SUMIFS(DATA!$N$2:$N$1001,DATA!$F$2:$F$1001,D$5) -> 31 | E28: =SUMIFS(DATA!$N$2:$N$1001,DATA!$F$2:$F$1001,E$5) -> 17 | F28: =SUMIFS(DATA!$N$2:$N$1001,DATA!$F$2:$F$1001,F$5) -> 15 | G28: =SUM(DATA!$N$2:$N$1001) -> 80 | I28: =IFERROR(C28/C$8,0) -> 0.35416667 | J28: =IFERROR(D28/D$8,0) -> 0.33695652 | K28: =IFERROR(E28/E$8,0) -> 0.265625 | L28: =IFERROR(F28/F$8,0) -> 0.39473684 | M28: =IFERROR(G28/G$8,0) -> 0.33057851
A29: 19 | B29: Overview Cabang / Prinsip Kerja | C29: =SUMIFS(DATA!$O$2:$O$1001,DATA!$F$2:$F$1001,C$5) -> 12 | D29: =SUMIFS(DATA!$O$2:$O$1001,DATA!$F$2:$F$1001,D$5) -> 27 | E29: =SUMIFS(DATA!$O$2:$O$1001,DATA!$F$2:$F$1001,E$5) -> 15 | F29: =SUMIFS(DATA!$O$2:$O$1001,DATA!$F$2:$F$1001,F$5) -> 15 | G29: =SUM(DATA!$O$2:$O$1001) -> 69 | I29: =IFERROR(C29/C$8,0) -> 0.25 | J29: =IFERROR(D29/D$8,0) -> 0.29347826 | K29: =IFERROR(E29/E$8,0) -> 0.234375 | L29: =IFERROR(F29/F$8,0) -> 0.39473684 | M29: =IFERROR(G29/G$8,0) -> 0.28512397
B30: Skor rata-rata (1 - 3)
A31: 20 | B31: Navigasi | C31: =IFERROR(AVERAGEIFS(DATA!$P$2:$P$1001,DATA!$F$2:$F$1001,C$5),0) -> 2.6666667 | D31: =IFERROR(AVERAGEIFS(DATA!$P$2:$P$1001,DATA!$F$2:$F$1001,D$5),0) -> 2.5326087 | E31: =IFERROR(AVERAGEIFS(DATA!$P$2:$P$1001,DATA!$F$2:$F$1001,E$5),0) -> 2.65625 | F31: =IFERROR(AVERAGEIFS(DATA!$P$2:$P$1001,DATA!$F$2:$F$1001,F$5),0) -> 2.7631579 | G31: =IFERROR(AVERAGE(DATA!$P$2:$P$1001),0) -> 2.6280992
A32: 21 | B32: Tampilan HP | C32: =IFERROR(AVERAGEIFS(DATA!$Q$2:$Q$1001,DATA!$F$2:$F$1001,C$5),0) -> 2.6458333 | D32: =IFERROR(AVERAGEIFS(DATA!$Q$2:$Q$1001,DATA!$F$2:$F$1001,D$5),0) -> 2.5217391 | E32: =IFERROR(AVERAGEIFS(DATA!$Q$2:$Q$1001,DATA!$F$2:$F$1001,E$5),0) -> 2.8125 | F32: =IFERROR(AVERAGEIFS(DATA!$Q$2:$Q$1001,DATA!$F$2:$F$1001,F$5),0) -> 2.8157895 | G32: =IFERROR(AVERAGE(DATA!$Q$2:$Q$1001),0) -> 2.6694215
A33: 22 | B33: Materi / SOP | C33: =IFERROR(AVERAGEIFS(DATA!$R$2:$R$1001,DATA!$F$2:$F$1001,C$5),0) -> 2.4791667 | D33: =IFERROR(AVERAGEIFS(DATA!$R$2:$R$1001,DATA!$F$2:$F$1001,D$5),0) -> 2.5217391 | E33: =IFERROR(AVERAGEIFS(DATA!$R$2:$R$1001,DATA!$F$2:$F$1001,E$5),0) -> 2.578125 | F33: =IFERROR(AVERAGEIFS(DATA!$R$2:$R$1001,DATA!$F$2:$F$1001,F$5),0) -> 2.6315789 | G33: =IFERROR(AVERAGE(DATA!$R$2:$R$1001),0) -> 2.5454545
A34: 23 | B34: Rata-rata keseluruhan | C34: =IFERROR(AVERAGEIFS(DATA!$S$2:$S$1001,DATA!$F$2:$F$1001,C$5),0) -> 2.5972222 | D34: =IFERROR(AVERAGEIFS(DATA!$S$2:$S$1001,DATA!$F$2:$F$1001,D$5),0) -> 2.5253623 | E34: =IFERROR(AVERAGEIFS(DATA!$S$2:$S$1001,DATA!$F$2:$F$1001,E$5),0) -> 2.6822917 | F34: =IFERROR(AVERAGEIFS(DATA!$S$2:$S$1001,DATA!$F$2:$F$1001,F$5),0) -> 2.7368421 | G34: =IFERROR(AVERAGE(DATA!$S$2:$S$1001),0) -> 2.6143251
B35: Masukan & Saran (gabungan 3 pertanyaan saran - 1 orang dihitung 1x per topik)
B36: A. Tampilan & Akses Website
A37: 24 | B37: Kecepatan & Akses Website | C37: =SUMIFS(DATA!$AK$2:$AK$1001,DATA!$F$2:$F$1001,C$5) -> 2 | D37: =SUMIFS(DATA!$AK$2:$AK$1001,DATA!$F$2:$F$1001,D$5) -> 7 | E37: =SUMIFS(DATA!$AK$2:$AK$1001,DATA!$F$2:$F$1001,E$5) -> 3 | F37: =SUMIFS(DATA!$AK$2:$AK$1001,DATA!$F$2:$F$1001,F$5) -> 1 | G37: =SUM(DATA!$AK$2:$AK$1001) -> 13 | I37: =IFERROR(C37/C$8,0) -> 0.041666667 | J37: =IFERROR(D37/D$8,0) -> 0.076086957 | K37: =IFERROR(E37/E$8,0) -> 0.046875 | L37: =IFERROR(F37/F$8,0) -> 0.026315789 | M37: =IFERROR(G37/G$8,0) -> 0.053719008 | N37: =IF(G37=0,"-",IF(G37/G$57>=15%,"Tinggi",IF(G37/G$57>=8%,"Sedang","Rendah"))) -> Sedang | O37: Optimasi kecepatan muat halaman (kompres gambar, cache), tingkatkan kapasitas server/hosting saat banyak pengguna, uji di area sinyal lemah.
A38: 25 | B38: Tampilan di HP (Responsif) | C38: =SUMIFS(DATA!$AL$2:$AL$1001,DATA!$F$2:$F$1001,C$5) -> 1 | D38: =SUMIFS(DATA!$AL$2:$AL$1001,DATA!$F$2:$F$1001,D$5) -> 1 | E38: =SUMIFS(DATA!$AL$2:$AL$1001,DATA!$F$2:$F$1001,E$5) -> 2 | F38: =SUMIFS(DATA!$AL$2:$AL$1001,DATA!$F$2:$F$1001,F$5) -> 0 | G38: =SUM(DATA!$AL$2:$AL$1001) -> 4 | I38: =IFERROR(C38/C$8,0) -> 0.020833333 | J38: =IFERROR(D38/D$8,0) -> 0.010869565 | K38: =IFERROR(E38/E$8,0) -> 0.03125 | L38: =IFERROR(F38/F$8,0) -> 0 | M38: =IFERROR(G38/G$8,0) -> 0.016528926 | N38: =IF(G38=0,"-",IF(G38/G$57>=15%,"Tinggi",IF(G38/G$57>=8%,"Sedang","Rendah"))) -> Rendah | O38: Perbaiki tampilan mobile: lebar halaman menyesuaikan layar HP, tidak perlu geser ke samping.
A39: 26 | B39: Desain, Warna & Font | C39: =SUMIFS(DATA!$AM$2:$AM$1001,DATA!$F$2:$F$1001,C$5) -> 7 | D39: =SUMIFS(DATA!$AM$2:$AM$1001,DATA!$F$2:$F$1001,D$5) -> 18 | E39: =SUMIFS(DATA!$AM$2:$AM$1001,DATA!$F$2:$F$1001,E$5) -> 4 | F39: =SUMIFS(DATA!$AM$2:$AM$1001,DATA!$F$2:$F$1001,F$5) -> 2 | G39: =SUM(DATA!$AM$2:$AM$1001) -> 31 | I39: =IFERROR(C39/C$8,0) -> 0.14583333 | J39: =IFERROR(D39/D$8,0) -> 0.19565217 | K39: =IFERROR(E39/E$8,0) -> 0.0625 | L39: =IFERROR(F39/F$8,0) -> 0.052631579 | M39: =IFERROR(G39/G$8,0) -> 0.12809917 | N39: =IF(G39=0,"-",IF(G39/G$57>=15%,"Tinggi",IF(G39/G$57>=8%,"Sedang","Rendah"))) -> Tinggi | O39: Perbarui desain agar lebih menarik dan tidak kaku: kontras warna teks (hindari abu-abu), font nyaman dibaca, tambah logo SID.
A40: 27 | B40: Menu per Jabatan / Navigasi | C40: =SUMIFS(DATA!$AN$2:$AN$1001,DATA!$F$2:$F$1001,C$5) -> 0 | D40: =SUMIFS(DATA!$AN$2:$AN$1001,DATA!$F$2:$F$1001,D$5) -> 2 | E40: =SUMIFS(DATA!$AN$2:$AN$1001,DATA!$F$2:$F$1001,E$5) -> 2 | F40: =SUMIFS(DATA!$AN$2:$AN$1001,DATA!$F$2:$F$1001,F$5) -> 0 | G40: =SUM(DATA!$AN$2:$AN$1001) -> 4 | I40: =IFERROR(C40/C$8,0) -> 0 | J40: =IFERROR(D40/D$8,0) -> 0.02173913 | K40: =IFERROR(E40/E$8,0) -> 0.03125 | L40: =IFERROR(F40/F$8,0) -> 0 | M40: =IFERROR(G40/G$8,0) -> 0.016528926 | N40: =IF(G40=0,"-",IF(G40/G$57>=15%,"Tinggi",IF(G40/G$57>=8%,"Sedang","Rendah"))) -> Rendah | O40: Buat menu/jalur terpisah untuk BM, CRO, dan BAO di halaman awal.
A41: 28 | B41: Integrasi dengan SACS / Aplikasi Kerja | C41: =SUMIFS(DATA!$AO$2:$AO$1001,DATA!$F$2:$F$1001,C$5) -> 3 | D41: =SUMIFS(DATA!$AO$2:$AO$1001,DATA!$F$2:$F$1001,D$5) -> 6 | E41: =SUMIFS(DATA!$AO$2:$AO$1001,DATA!$F$2:$F$1001,E$5) -> 3 | F41: =SUMIFS(DATA!$AO$2:$AO$1001,DATA!$F$2:$F$1001,F$5) -> 1 | G41: =SUM(DATA!$AO$2:$AO$1001) -> 13 | I41: =IFERROR(C41/C$8,0) -> 0.0625 | J41: =IFERROR(D41/D$8,0) -> 0.065217391 | K41: =IFERROR(E41/E$8,0) -> 0.046875 | L41: =IFERROR(F41/F$8,0) -> 0.026315789 | M41: =IFERROR(G41/G$8,0) -> 0.053719008 | N41: =IF(G41=0,"-",IF(G41/G$57>=15%,"Tinggi",IF(G41/G$57>=8%,"Sedang","Rendah"))) -> Sedang | O41: Pasang link/menu handbook di SACS atau aplikasi kerja agar bisa diakses tanpa buka website terpisah.
...

Sheet CABANG
A1: REKAP PENGISIAN PER CABANG
A3: No | B3: Cabang | C3: Jml Pegawai | D3: Sudah Isi | E3: % | F3: BM | G3: CRO | H3: BAO | I3: Navigasi Mudah | J3: HP Responsif | K3: SOP Mudah | L3: Skor | M3: Keterangan
A4: JAWA BARAT
A5: 1 | B5: =PROGRES!B2 -> PURWAKARTA | C5: =PROGRES!C2 -> 3 | D5: =COUNTIF(DATA!$E$2:$E$1001,$B5) -> 0 | E5: =IFERROR(D5/C5,0) -> 0 | F5: =COUNTIFS(DATA!$E$2:$E$1001,$B5,DATA!$H$2:$H$1001,"BM") -> 0 | G5: =COUNTIFS(DATA!$E$2:$E$1001,$B5,DATA!$H$2:$H$1001,"CRO") -> 0 | H5: =COUNTIFS(DATA!$E$2:$E$1001,$B5,DATA!$H$2:$H$1001,"BAO") -> 0 | I5: =IF($D5=0,"-",COUNTIFS(DATA!$E$2:$E$1001,$B5,DATA!$I$2:$I$1001,"MUDAH")/$D5) -> - | J5: =IF($D5=0,"-",COUNTIFS(DATA!$E$2:$E$1001,$B5,DATA!$J$2:$J$1001,"YA")/$D5) -> - | K5: =IF($D5=0,"-",COUNTIFS(DATA!$E$2:$E$1001,$B5,DATA!$K$2:$K$1001,"MUDAH")/$D5) -> - | L5: =IFERROR(AVERAGEIFS(DATA!$S$2:$S$1001,DATA!$E$2:$E$1001,$B5),"-") -> - | M5: =IF(D5=0,"Belum isi","") -> Belum isi
A6: 2 | B6: =PROGRES!B3 -> SUKABUMI II | C6: =PROGRES!C3 -> 6 | D6: =COUNTIF(DATA!$E$2:$E$1001,$B6) -> 3 | E6: =IFERROR(D6/C6,0) -> 0.5 | F6: =COUNTIFS(DATA!$E$2:$E$1001,$B6,DATA!$H$2:$H$1001,"BM") -> 0 | G6: =COUNTIFS(DATA!$E$2:$E$1001,$B6,DATA!$H$2:$H$1001,"CRO") -> 2 | H6: =COUNTIFS(DATA!$E$2:$E$1001,$B6,DATA!$H$2:$H$1001,"BAO") -> 1 | I6: =IF($D6=0,"-",COUNTIFS(DATA!$E$2:$E$1001,$B6,DATA!$I$2:$I$1001,"MUDAH")/$D6) -> 0.66666667 | J6: =IF($D6=0,"-",COUNTIFS(DATA!$E$2:$E$1001,$B6,DATA!$J$2:$J$1001,"YA")/$D6) -> 0.33333333 | K6: =IF($D6=0,"-",COUNTIFS(DATA!$E$2:$E$1001,$B6,DATA!$K$2:$K$1001,"MUDAH")/$D6) -> 0.66666667 | L6: =IFERROR(AVERAGEIFS(DATA!$S$2:$S$1001,DATA!$E$2:$E$1001,$B6),"-") -> 2.5555556 | M6: =IF(D6=0,"Belum isi","")
A7: 3 | B7: =PROGRES!B4 -> PANGANDARAN | C7: =PROGRES!C4 -> 3 | D7: =COUNTIF(DATA!$E$2:$E$1001,$B7) -> 0 | E7: =IFERROR(D7/C7,0) -> 0 | F7: =COUNTIFS(DATA!$E$2:$E$1001,$B7,DATA!$H$2:$H$1001,"BM") -> 0 | G7: =COUNTIFS(DATA!$E$2:$E$1001,$B7,DATA!$H$2:$H$1001,"CRO") -> 0 | H7: =COUNTIFS(DATA!$E$2:$E$1001,$B7,DATA!$H$2:$H$1001,"BAO") -> 0 | I7: =IF($D7=0,"-",COUNTIFS(DATA!$E$2:$E$1001,$B7,DATA!$I$2:$I$1001,"MUDAH")/$D7) -> - | J7: =IF($D7=0,"-",COUNTIFS(DATA!$E$2:$E$1001,$B7,DATA!$J$2:$J$1001,"YA")/$D7) -> - | K7: =IF($D7=0,"-",COUNTIFS(DATA!$E$2:$E$1001,$B7,DATA!$K$2:$K$1001,"MUDAH")/$D7) -> - | L7: =IFERROR(AVERAGEIFS(DATA!$S$2:$S$1001,DATA!$E$2:$E$1001,$B7),"-") -> - | M7: =IF(D7=0,"Belum isi","") -> Belum isi
A8: 4 | B8: =PROGRES!B5 -> BANDUNG | C8: =PROGRES!C5 -> 7 | D8: =COUNTIF(DATA!$E$2:$E$1001,$B8) -> 0 | E8: =IFERROR(D8/C8,0) -> 0 | F8: =COUNTIFS(DATA!$E$2:$E$1001,$B8,DATA!$H$2:$H$1001,"BM") -> 0 | G8: =COUNTIFS(DATA!$E$2:$E$1001,$B8,DATA!$H$2:$H$1001,"CRO") -> 0 | H8: =COUNTIFS(DATA!$E$2:$E$1001,$B8,DATA!$H$2:$H$1001,"BAO") -> 0 | I8: =IF($D8=0,"-",COUNTIFS(DATA!$E$2:$E$1001,$B8,DATA!$I$2:$I$1001,"MUDAH")/$D8) -> - | J8: =IF($D8=0,"-",COUNTIFS(DATA!$E$2:$E$1001,$B8,DATA!$J$2:$J$1001,"YA")/$D8) -> - | K8: =IF($D8=0,"-",COUNTIFS(DATA!$E$2:$E$1001,$B8,DATA!$K$2:$K$1001,"MUDAH")/$D8) -> - | L8: =IFERROR(AVERAGEIFS(DATA!$S$2:$S$1001,DATA!$E$2:$E$1001,$B8),"-") -> - | M8: =IF(D8=0,"Belum isi","") -> Belum isi
A9: 5 | B9: =PROGRES!B6 -> BANJAR | C9: =PROGRES!C6 -> 4 | D9: =COUNTIF(DATA!$E$2:$E$1001,$B9) -> 3 | E9: =IFERROR(D9/C9,0) -> 0.75 | F9: =COUNTIFS(DATA!$E$2:$E$1001,$B9,DATA!$H$2:$H$1001,"BM") -> 1 | G9: =COUNTIFS(DATA!$E$2:$E$1001,$B9,DATA!$H$2:$H$1001,"CRO") -> 2 | H9: =COUNTIFS(DATA!$E$2:$E$1001,$B9,DATA!$H$2:$H$1001,"BAO") -> 0 | I9: =IF($D9=0,"-",COUNTIFS(DATA!$E$2:$E$1001,$B9,DATA!$I$2:$I$1001,"MUDAH")/$D9) -> 1 | J9: =IF($D9=0,"-",COUNTIFS(DATA!$E$2:$E$1001,$B9,DATA!$J$2:$J$1001,"YA")/$D9) -> 1 | K9: =IF($D9=0,"-",COUNTIFS(DATA!$E$2:$E$1001,$B9,DATA!$K$2:$K$1001,"MUDAH")/$D9) -> 0.66666667 | L9: =IFERROR(AVERAGEIFS(DATA!$S$2:$S$1001,DATA!$E$2:$E$1001,$B9),"-") -> 2.8888889 | M9: =IF(D9=0,"Belum isi","")
A10: 6 | B10: =PROGRES!B7 -> CIANJUR | C10: =PROGRES!C7 -> 7 | D10: =COUNTIF(DATA!$E$2:$E$1001,$B10) -> 6 | E10: =IFERROR(D10/C10,0) -> 0.85714286 | F10: =COUNTIFS(DATA!$E$2:$E$1001,$B10,DATA!$H$2:$H$1001,"BM") -> 1 | G10: =COUNTIFS(DATA!$E$2:$E$1001,$B10,DATA!$H$2:$H$1001,"CRO") -> 4 | H10: =COUNTIFS(DATA!$E$2:$E$1001,$B10,DATA!$H$2:$H$1001,"BAO") -> 1 | I10: =IF($D10=0,"-",COUNTIFS(DATA!$E$2:$E$1001,$B10,DATA!$I$2:$I$1001,"MUDAH")/$D10) -> 0.66666667 | J10: =IF($D10=0,"-",COUNTIFS(DATA!$E$2:$E$1001,$B10,DATA!$J$2:$J$1001,"YA")/$D10) -> 0.5 | K10: =IF($D10=0,"-",COUNTIFS(DATA!$E$2:$E$1001,$B10,DATA!$K$2:$K$1001,"MUDAH")/$D10) -> 0.5 | L10: =IFERROR(AVERAGEIFS(DATA!$S$2:$S$1001,DATA!$E$2:$E$1001,$B10),"-") -> 2.4444444 | M10: =IF(D10=0,"Belum isi","")
A11: 7 | B11: =PROGRES!B8 -> CIREBON | C11: =PROGRES!C8 -> 8 | D11: =COUNTIF(DATA!$E$2:$E$1001,$B11) -> 7 | E11: =IFERROR(D11/C11,0) -> 0.875 | F11: =COUNTIFS(DATA!$E$2:$E$1001,$B11,DATA!$H$2:$H$1001,"BM") -> 1 | G11: =COUNTIFS(DATA!$E$2:$E$1001,$B11,DATA!$H$2:$H$1001,"CRO") -> 5 | H11: =COUNTIFS(DATA!$E$2:$E$1001,$B11,DATA!$H$2:$H$1001,"BAO") -> 1 | I11: =IF($D11=0,"-",COUNTIFS(DATA!$E$2:$E$1001,$B11,DATA!$I$2:$I$1001,"MUDAH")/$D11) -> 0.85714286 | J11: =IF($D11=0,"-",COUNTIFS(DATA!$E$2:$E$1001,$B11,DATA!$J$2:$J$1001,"YA")/$D11) -> 0.71428571 | K11: =IF($D11=0,"-",COUNTIFS(DATA!$E$2:$E$1001,$B11,DATA!$K$2:$K$1001,"MUDAH")/$D11) -> 0.57142857 | L11: =IFERROR(AVERAGEIFS(DATA!$S$2:$S$1001,DATA!$E$2:$E$1001,$B11),"-") -> 2.7142857 | M11: =IF(D11=0,"Belum isi","")
A12: 8 | B12: =PROGRES!B9 -> INDRAMAYU | C12: =PROGRES!C9 -> 6 | D12: =COUNTIF(DATA!$E$2:$E$1001,$B12) -> 0 | E12: =IFERROR(D12/C12,0) -> 0 | F12: =COUNTIFS(DATA!$E$2:$E$1001,$B12,DATA!$H$2:$H$1001,"BM") -> 0 | G12: =COUNTIFS(DATA!$E$2:$E$1001,$B12,DATA!$H$2:$H$1001,"CRO") -> 0 | H12: =COUNTIFS(DATA!$E$2:$E$1001,$B12,DATA!$H$2:$H$1001,"BAO") -> 0 | I12: =IF($D12=0,"-",COUNTIFS(DATA!$E$2:$E$1001,$B12,DATA!$I$2:$I$1001,"MUDAH")/$D12) -> - | J12: =IF($D12=0,"-",COUNTIFS(DATA!$E$2:$E$1001,$B12,DATA!$J$2:$J$1001,"YA")/$D12) -> - | K12: =IF($D12=0,"-",COUNTIFS(DATA!$E$2:$E$1001,$B12,DATA!$K$2:$K$1001,"MUDAH")/$D12) -> - | L12: =IFERROR(AVERAGEIFS(DATA!$S$2:$S$1001,DATA!$E$2:$E$1001,$B12),"-") -> - | M12: =IF(D12=0,"Belum isi","") -> Belum isi
A13: 9 | B13: =PROGRES!B10 -> KARAWANG | C13: =PROGRES!C10 -> 5 | D13: =COUNTIF(DATA!$E$2:$E$1001,$B13) -> 1 | E13: =IFERROR(D13/C13,0) -> 0.2 | F13: =COUNTIFS(DATA!$E$2:$E$1001,$B13,DATA!$H$2:$H$1001,"BM") -> 1 | G13: =COUNTIFS(DATA!$E$2:$E$1001,$B13,DATA!$H$2:$H$1001,"CRO") -> 0 | H13: =COUNTIFS(DATA!$E$2:$E$1001,$B13,DATA!$H$2:$H$1001,"BAO") -> 0 | I13: =IF($D13=0,"-",COUNTIFS(DATA!$E$2:$E$1001,$B13,DATA!$I$2:$I$1001,"MUDAH")/$D13) -> 1 | J13: =IF($D13=0,"-",COUNTIFS(DATA!$E$2:$E$1001,$B13,DATA!$J$2:$J$1001,"YA")/$D13) -> 1 | K13: =IF($D13=0,"-",COUNTIFS(DATA!$E$2:$E$1001,$B13,DATA!$K$2:$K$1001,"MUDAH")/$D13) -> 1 | L13: =IFERROR(AVERAGEIFS(DATA!$S$2:$S$1001,DATA!$E$2:$E$1001,$B13),"-") -> 3 | M13: =IF(D13=0,"Belum isi","")
A14: 10 | B14: =PROGRES!B11 -> MAJALENGKA | C14: =PROGRES!C11 -> 5 | D14: =COUNTIF(DATA!$E$2:$E$1001,$B14) -> 4 | E14: =IFERROR(D14/C14,0) -> 0.8 | F14: =COUNTIFS(DATA!$E$2:$E$1001,$B14,DATA!$H$2:$H$1001,"BM") -> 1 | G14: =COUNTIFS(DATA!$E$2:$E$1001,$B14,DATA!$H$2:$H$1001,"CRO") -> 2 | H14: =COUNTIFS(DATA!$E$2:$E$1001,$B14,DATA!$H$2:$H$1001,"BAO") -> 1 | I14: =IF($D14=0,"-",COUNTIFS(DATA!$E$2:$E$1001,$B14,DATA!$I$2:$I$1001,"MUDAH")/$D14) -> 0.75 | J14: =IF($D14=0,"-",COUNTIFS(DATA!$E$2:$E$1001,$B14,DATA!$J$2:$J$1001,"YA")/$D14) -> 1 | K14: =IF($D14=0,"-",COUNTIFS(DATA!$E$2:$E$1001,$B14,DATA!$K$2:$K$1001,"MUDAH")/$D14) -> 0.25 | L14: =IFERROR(AVERAGEIFS(DATA!$S$2:$S$1001,DATA!$E$2:$E$1001,$B14),"-") -> 2.6666667 | M14: =IF(D14=0,"Belum isi","")
A15: 11 | B15: =PROGRES!B12 -> PADALARANG | C15: =PROGRES!C12 -> 3 | D15: =COUNTIF(DATA!$E$2:$E$1001,$B15) -> 0 | E15: =IFERROR(D15/C15,0) -> 0 | F15: =COUNTIFS(DATA!$E$2:$E$1001,$B15,DATA!$H$2:$H$1001,"BM") -> 0 | G15: =COUNTIFS(DATA!$E$2:$E$1001,$B15,DATA!$H$2:$H$1001,"CRO") -> 0 | H15: =COUNTIFS(DATA!$E$2:$E$1001,$B15,DATA!$H$2:$H$1001,"BAO") -> 0 | I15: =IF($D15=0,"-",COUNTIFS(DATA!$E$2:$E$1001,$B15,DATA!$I$2:$I$1001,"MUDAH")/$D15) -> - | J15: =IF($D15=0,"-",COUNTIFS(DATA!$E$2:$E$1001,$B15,DATA!$J$2:$J$1001,"YA")/$D15) -> - | K15: =IF($D15=0,"-",COUNTIFS(DATA!$E$2:$E$1001,$B15,DATA!$K$2:$K$1001,"MUDAH")/$D15) -> - | L15: =IFERROR(AVERAGEIFS(DATA!$S$2:$S$1001,DATA!$E$2:$E$1001,$B15),"-") -> - | M15: =IF(D15=0,"Belum isi","") -> Belum isi
A16: 12 | B16: =PROGRES!B13 -> SUBANG | C16: =PROGRES!C13 -> 4 | D16: =COUNTIF(DATA!$E$2:$E$1001,$B16) -> 4 | E16: =IFERROR(D16/C16,0) -> 1 | F16: =COUNTIFS(DATA!$E$2:$E$1001,$B16,DATA!$H$2:$H$1001,"BM") -> 1 | G16: =COUNTIFS(DATA!$E$2:$E$1001,$B16,DATA!$H$2:$H$1001,"CRO") -> 2 | H16: =COUNTIFS(DATA!$E$2:$E$1001,$B16,DATA!$H$2:$H$1001,"BAO") -> 1 | I16: =IF($D16=0,"-",COUNTIFS(DATA!$E$2:$E$1001,$B16,DATA!$I$2:$I$1001,"MUDAH")/$D16) -> 0.25 | J16: =IF($D16=0,"-",COUNTIFS(DATA!$E$2:$E$1001,$B16,DATA!$J$2:$J$1001,"YA")/$D16) -> 0.5 | K16: =IF($D16=0,"-",COUNTIFS(DATA!$E$2:$E$1001,$B16,DATA!$K$2:$K$1001,"MUDAH")/$D16) -> 0.5 | L16: =IFERROR(AVERAGEIFS(DATA!$S$2:$S$1001,DATA!$E$2:$E$1001,$B16),"-") -> 2.4166667 | M16: =IF(D16=0,"Belum isi","")
... A25: 21 | B25: =PROGRES!B22 -> TANGERANG | C25: =PROGRES!C22 -> 6 | D25: =COUNTIF(DATA!$E$2:$E$1001,$B25) -> 2 | E25: =IFERROR(D25/C25,0) -> 0.33333333 | F25: =COUNTIFS(DATA!$E$2:$E$1001,$B25,DATA!$H$2:$H$1001,"BM") -> 0 | G25: =COUNTIFS(DATA!$E$2:$E$1001,$B25,DATA!$H$2:$H$1001,"CRO") -> 2 | H25: =COUNTIFS(DATA!$E$2:$E$1001,$B25,DATA!$H$2:$H$1001,"BAO") -> 0 | I25: =IF($D25=0,"-",COUNTIFS(DATA!$E$2:$E$1001,$B25,DATA!$I$2:$I$1001,"MUDAH")/$D25) -> 1 | J25: =IF($D25=0,"-",COUNTIFS(DATA!$E$2:$E$1001,$B25,DATA!$J$2:$J$1001,"YA")/$D25) -> 0.5 | K25: =IF($D25=0,"-",COUNTIFS(DATA!$E$2:$E$1001,$B25,DATA!$K$2:$K$1001,"MUDAH")/$D25) -> 0 | L25: =IFERROR(AVERAGEIFS(DATA!$S$2:$S$1001,DATA!$E$2:$E$1001,$B25),"-") -> 2.5 | M25: =IF(D25=0,"Belum isi","")
B26: Subtotal Jawa Barat | C26: =SUM(C5:C25) -> 99 | D26: =SUM(D5:D25) -> 48 | E26: =IFERROR(D26/C26,0) -> 0.48484848 | F26: =SUM(F5:F25) -> 11 | G26: =SUM(G5:G25) -> 29 | H26: =SUM(H5:H25) -> 8 | I26: =IFERROR(COUNTIFS(DATA!$F$2:$F$1001,"Jawa Barat",DATA!$I$2:$I$1001,"MUDAH")/$D26,"-") -> 0.6875 | J26: =IFERROR(COUNTIFS(DATA!$F$2:$F$1001,"Jawa Barat",DATA!$J$2:$J$1001,"YA")/$D26,"-") -> 0.66666667 | K26: =IFERROR(COUNTIFS(DATA!$F$2:$F$1001,"Jawa Barat",DATA!$K$2:$K$1001,"MUDAH")/$D26,"-") -> 0.47916667 | L26: =IFERROR(AVERAGEIFS(DATA!$S$2:$S$1001,DATA!$F$2:$F$1001,"Jawa Barat"),"-") -> 2.5972222 | M26: =COUNTIF(M5:M25,"Belum isi")&" cabang belum isi" -> 8 cabang belum isi
A28: JAWA TENGAH
A29: 1 | B29: =PROGRES!B23 -> BLORA | C29: =PROGRES!C23 -> 5 | D29: =COUNTIF(DATA!$E$2:$E$1001,$B29) -> 4 | E29: =IFERROR(D29/C29,0) -> 0.8 | F29: =COUNTIFS(DATA!$E$2:$E$1001,$B29,DATA!$H$2:$H$1001,"BM") -> 1 | G29: =COUNTIFS(DATA!$E$2:$E$1001,$B29,DATA!$H$2:$H$1001,"CRO") -> 2 | H29: =COUNTIFS(DATA!$E$2:$E$1001,$B29,DATA!$H$2:$H$1001,"BAO") -> 1 | I29: =IF($D29=0,"-",COUNTIFS(DATA!$E$2:$E$1001,$B29,DATA!$I$2:$I$1001,"MUDAH")/$D29) -> 0.5 | J29: =IF($D29=0,"-",COUNTIFS(DATA!$E$2:$E$1001,$B29,DATA!$J$2:$J$1001,"YA")/$D29) -> 0.5 | K29: =IF($D29=0,"-",COUNTIFS(DATA!$E$2:$E$1001,$B29,DATA!$K$2:$K$1001,"MUDAH")/$D29) -> 0.5 | L29: =IFERROR(AVERAGEIFS(DATA!$S$2:$S$1001,DATA!$E$2:$E$1001,$B29),"-") -> 2.5 | M29: =IF(D29=0,"Belum isi","")
A30: 2 | B30: =PROGRES!B24 -> CEPU | C30: =PROGRES!C24 -> 2 | D30: =COUNTIF(DATA!$E$2:$E$1001,$B30) -> 3 | E30: =IFERROR(D30/C30,0) -> 1.5 | F30: =COUNTIFS(DATA!$E$2:$E$1001,$B30,DATA!$H$2:$H$1001,"BM") -> 1 | G30: =COUNTIFS(DATA!$E$2:$E$1001,$B30,DATA!$H$2:$H$1001,"CRO") -> 1 | H30: =COUNTIFS(DATA!$E$2:$E$1001,$B30,DATA!$H$2:$H$1001,"BAO") -> 1 | I30: =IF($D30=0,"-",COUNTIFS(DATA!$E$2:$E$1001,$B30,DATA!$I$2:$I$1001,"MUDAH")/$D30) -> 0.66666667 | J30: =IF($D30=0,"-",COUNTIFS(DATA!$E$2:$E$1001,$B30,DATA!$J$2:$J$1001,"YA")/$D30) -> 0.66666667 | K30: =IF($D30=0,"-",COUNTIFS(DATA!$E$2:$E$1001,$B30,DATA!$K$2:$K$1001,"MUDAH")/$D30) -> 0.66666667 | L30: =IFERROR(AVERAGEIFS(DATA!$S$2:$S$1001,DATA!$E$2:$E$1001,$B30),"-") -> 2.6666667 | M30: =IF(D30=0,"Belum isi","")
A31: 3 | B31: =PROGRES!B25 -> DEMAK | C31: =PROGRES!C25 -> 5 | D31: =COUNTIF(DATA!$E$2:$E$1001,$B31) -> 0 | E31: =IFERROR(D31/C31,0) -> 0 | F31: =COUNTIFS(DATA!$E$2:$E$1001,$B31,DATA!$H$2:$H$1001,"BM") -> 0 | G31: =COUNTIFS(DATA!$E$2:$E$1001,$B31,DATA!$H$2:$H$1001,"CRO") -> 0 | H31: =COUNTIFS(DATA!$E$2:$E$1001,$B31,DATA!$H$2:$H$1001,"BAO") -> 0 | I31: =IF($D31=0,"-",COUNTIFS(DATA!$E$2:$E$1001,$B31,DATA!$I$2:$I$1001,"MUDAH")/$D31) -> - | J31: =IF($D31=0,"-",COUNTIFS(DATA!$E$2:$E$1001,$B31,DATA!$J$2:$J$1001,"YA")/$D31) -> - | K31: =IF($D31=0,"-",COUNTIFS(DATA!$E$2:$E$1001,$B31,DATA!$K$2:$K$1001,"MUDAH")/$D31) -> - | L31: =IFERROR(AVERAGEIFS(DATA!$S$2:$S$1001,DATA!$E$2:$E$1001,$B31),"-") -> - | M31: =IF(D31=0,"Belum isi","") -> Belum isi
A32: 4 | B32: =PROGRES!B26 -> JEPARA | C32: =PROGRES!C26 -> 4 | D32: =COUNTIF(DATA!$E$2:$E$1001,$B32) -> 0 | E32: =IFERROR(D32/C32,0) -> 0 | F32: =COUNTIFS(DATA!$E$2:$E$1001,$B32,DATA!$H$2:$H$1001,"BM") -> 0 | G32: =COUNTIFS(DATA!$E$2:$E$1001,$B32,DATA!$H$2:$H$1001,"CRO") -> 0 | H32: =COUNTIFS(DATA!$E$2:$E$1001,$B32,DATA!$H$2:$H$1001,"BAO") -> 0 | I32: =IF($D32=0,"-",COUNTIFS(DATA!$E$2:$E$1001,$B32,DATA!$I$2:$I$1001,"MUDAH")/$D32) -> - | J32: =IF($D32=0,"-",COUNTIFS(DATA!$E$2:$E$1001,$B32,DATA!$J$2:$J$1001,"YA")/$D32) -> - | K32: =IF($D32=0,"-",COUNTIFS(DATA!$E$2:$E$1001,$B32,DATA!$K$2:$K$1001,"MUDAH")/$D32) -> - | L32: =IFERROR(AVERAGEIFS(DATA!$S$2:$S$1001,DATA!$E$2:$E$1001,$B32),"-") -> - | M32: =IF(D32=0,"Belum isi","") -> Belum isi
A33: 5 | B33: =PROGRES!B27 -> KENDAL | C33: =PROGRES!C27 -> 4 | D33: =COUNTIF(DATA!$E$2:$E$1001,$B33) -> 0 | E33: =IFERROR(D33/C33,0) -> 0 | F33: =COUNTIFS(DATA!$E$2:$E$1001,$B33,DATA!$H$2:$H$1001,"BM") -> 0 | G33: =COUNTIFS(DATA!$E$2:$E$1001,$B33,DATA!$H$2:$H$1001,"CRO") -> 0 | H33: =COUNTIFS(DATA!$E$2:$E$1001,$B33,DATA!$H$2:$H$1001,"BAO") -> 0 | I33: =IF($D33=0,"-",COUNTIFS(DATA!$E$2:$E$1001,$B33,DATA!$I$2:$I$1001,"MUDAH")/$D33) -> - | J33: =IF($D33=0,"-",COUNTIFS(DATA!$E$2:$E$1001,$B33,DATA!$J$2:$J$1001,"YA")/$D33) -> - | K33: =IF($D33=0,"-",COUNTIFS(DATA!$E$2:$E$1001,$B33,DATA!$K$2:$K$1001,"MUDAH")/$D33) -> - | L33: =IFERROR(AVERAGEIFS(DATA!$S$2:$S$1001,DATA!$E$2:$E$1001,$B33),"-") -> - | M33: =IF(D33=0,"Belum isi","") -> Belum isi
A34: 6 | B34: =PROGRES!B28 -> PATI | C34: =PROGRES!C28 -> 5 | D34: =COUNTIF(DATA!$E$2:$E$1001,$B34) -> 3 | E34: =IFERROR(D34/C34,0) -> 0.6 | F34: =COUNTIFS(DATA!$E$2:$E$1001,$B34,DATA!$H$2:$H$1001,"BM") -> 1 | G34: =COUNTIFS(DATA!$E$2:$E$1001,$B34,DATA!$H$2:$H$1001,"CRO") -> 2 | H34: =COUNTIFS(DATA!$E$2:$E$1001,$B34,DATA!$H$2:$H$1001,"BAO") -> 0 | I34: =IF($D34=0,"-",COUNTIFS(DATA!$E$2:$E$1001,$B34,DATA!$I$2:$I$1001,"MUDAH")/$D34) -> 1 | J34: =IF($D34=0,"-",COUNTIFS(DATA!$E$2:$E$1001,$B34,DATA!$J$2:$J$1001,"YA")/$D34) -> 0 | K34: =IF($D34=0,"-",COUNTIFS(DATA!$E$2:$E$1001,$B34,DATA!$K$2:$K$1001,"MUDAH")/$D34) -> 0.66666667 | L34: =IFERROR(AVERAGEIFS(DATA!$S$2:$S$1001,DATA!$E$2:$E$1001,$B34),"-") -> 2.5555556 | M34: =IF(D34=0,"Belum isi","")
A35: 7 | B35: =PROGRES!B29 -> PEKALONGAN | C35: =PROGRES!C29 -> 5 | D35: =COUNTIF(DATA!$E$2:$E$1001,$B35) -> 5 | E35: =IFERROR(D35/C35,0) -> 1 | F35: =COUNTIFS(DATA!$E$2:$E$1001,$B35,DATA!$H$2:$H$1001,"BM") -> 1 | G35: =COUNTIFS(DATA!$E$2:$E$1001,$B35,DATA!$H$2:$H$1001,"CRO") -> 3 | H35: =COUNTIFS(DATA!$E$2:$E$1001,$B35,DATA!$H$2:$H$1001,"BAO") -> 1 | I35: =IF($D35=0,"-",COUNTIFS(DATA!$E$2:$E$1001,$B35,DATA!$I$2:$I$1001,"MUDAH")/$D35) -> 0.8 | J35: =IF($D35=0,"-",COUNTIFS(DATA!$E$2:$E$1001,$B35,DATA!$J$2:$J$1001,"YA")/$D35) -> 0.6 | K35: =IF($D35=0,"-",COUNTIFS(DATA!$E$2:$E$1001,$B35,DATA!$K$2:$K$1001,"MUDAH")/$D35) -> 0.8 | L35: =IFERROR(AVERAGEIFS(DATA!$S$2:$S$1001,DATA!$E$2:$E$1001,$B35),"-") -> 2.7333333 | M35: =IF(D35=0,"Belum isi","")
A36: 8 | B36: =PROGRES!B30 -> PURWODADI | C36: =PROGRES!C30 -> 6 | D36: =COUNTIF(DATA!$E$2:$E$1001,$B36) -> 0 | E36: =IFERROR(D36/C36,0) -> 0 | F36: =COUNTIFS(DATA!$E$2:$E$1001,$B36,DATA!$H$2:$H$1001,"BM") -> 0 | G36: =COUNTIFS(DATA!$E$2:$E$1001,$B36,DATA!$H$2:$H$1001,"CRO") -> 0 | H36: =COUNTIFS(DATA!$E$2:$E$1001,$B36,DATA!$H$2:$H$1001,"BAO") -> 0 | I36: =IF($D36=0,"-",COUNTIFS(DATA!$E$2:$E$1001,$B36,DATA!$I$2:$I$1001,"MUDAH")/$D36) -> - | J36: =IF($D36=0,"-",COUNTIFS(DATA!$E$2:$E$1001,$B36,DATA!$J$2:$J$1001,"YA")/$D36) -> - | K36: =IF($D36=0,"-",COUNTIFS(DATA!$E$2:$E$1001,$B36,DATA!$K$2:$K$1001,"MUDAH")/$D36) -> - | L36: =IFERROR(AVERAGEIFS(DATA!$S$2:$S$1001,DATA!$E$2:$E$1001,$B36),"-") -> - | M36: =IF(D36=0,"Belum isi","") -> Belum isi
A37: 9 | B37: =PROGRES!B31 -> REMBANG | C37: =PROGRES!C31 -> 7 | D37: =COUNTIF(DATA!$E$2:$E$1001,$B37) -> 0 | E37: =IFERROR(D37/C37,0) -> 0 | F37: =COUNTIFS(DATA!$E$2:$E$1001,$B37,DATA!$H$2:$H$1001,"BM") -> 0 | G37: =COUNTIFS(DATA!$E$2:$E$1001,$B37,DATA!$H$2:$H$1001,"CRO") -> 0 | H37: =COUNTIFS(DATA!$E$2:$E$1001,$B37,DATA!$H$2:$H$1001,"BAO") -> 0 | I37: =IF($D37=0,"-",COUNTIFS(DATA!$E$2:$E$1001,$B37,DATA!$I$2:$I$1001,"MUDAH")/$D37) -> - | J37: =IF($D37=0,"-",COUNTIFS(DATA!$E$2:$E$1001,$B37,DATA!$J$2:$J$1001,"YA")/$D37) -> - | K37: =IF($D37=0,"-",COUNTIFS(DATA!$E$2:$E$1001,$B37,DATA!$K$2:$K$1001,"MUDAH")/$D37) -> - | L37: =IFERROR(AVERAGEIFS(DATA!$S$2:$S$1001,DATA!$E$2:$E$1001,$B37),"-") -> - | M37: =IF(D37=0,"Belum isi","") -> Belum isi
A38: 10 | B38: =PROGRES!B32 -> SALATIGA | C38: =PROGRES!C32 -> 7 | D38: =COUNTIF(DATA!$E$2:$E$1001,$B38) -> 5 | E38: =IFERROR(D38/C38,0) -> 0.71428571 | F38: =COUNTIFS(DATA!$E$2:$E$1001,$B38,DATA!$H$2:$H$1001,"BM") -> 1 | G38: =COUNTIFS(DATA!$E$2:$E$1001,$B38,DATA!$H$2:$H$1001,"CRO") -> 3 | H38: =COUNTIFS(DATA!$E$2:$E$1001,$B38,DATA!$H$2:$H$1001,"BAO") -> 1 | I38: =IF($D38=0,"-",COUNTIFS(DATA!$E$2:$E$1001,$B38,DATA!$I$2:$I$1001,"MUDAH")/$D38) -> 0.6 | J38: =IF($D38=0,"-",COUNTIFS(DATA!$E$2:$E$1001,$B38,DATA!$J$2:$J$1001,"YA")/$D38) -> 0.6 | K38: =IF($D38=0,"-",COUNTIFS(DATA!$E$2:$E$1001,$B38,DATA!$K$2:$K$1001,"MUDAH")/$D38) -> 0.4 | L38: =IFERROR(AVERAGEIFS(DATA!$S$2:$S$1001,DATA!$E$2:$E$1001,$B38),"-") -> 2.5333333 | M38: =IF(D38=0,"Belum isi","")
A39: 11 | B39: =PROGRES!B33 -> SAYUNG | C39: =PROGRES!C33 -> 9 | D39: =COUNTIF(DATA!$E$2:$E$1001,$B39) -> 5 | E39: =IFERROR(D39/C39,0) -> 0.55555556 | F39: =COUNTIFS(DATA!$E$2:$E$1001,$B39,DATA!$H$2:$H$1001,"BM") -> 1 | G39: =COUNTIFS(DATA!$E$2:$E$1001,$B39,DATA!$H$2:$H$1001,"CRO") -> 3 | H39: =COUNTIFS(DATA!$E$2:$E$1001,$B39,DATA!$H$2:$H$1001,"BAO") -> 1 | I39: =IF($D39=0,"-",COUNTIFS(DATA!$E$2:$E$1001,$B39,DATA!$I$2:$I$1001,"MUDAH")/$D39) -> 0.4 | J39: =IF($D39=0,"-",COUNTIFS(DATA!$E$2:$E$1001,$B39,DATA!$J$2:$J$1001,"YA")/$D39) -> 0.6 | K39: =IF($D39=0,"-",COUNTIFS(DATA!$E$2:$E$1001,$B39,DATA!$K$2:$K$1001,"MUDAH")/$D39) -> 0.6 | L39: =IFERROR(AVERAGEIFS(DATA!$S$2:$S$1001,DATA!$E$2:$E$1001,$B39),"-") -> 2.5333333 | M39: =IF(D39=0,"Belum isi","")
A40: 12 | B40: =PROGRES!B34 -> TEGAL | C40: =PROGRES!C34 -> 5 | D40: =COUNTIF(DATA!$E$2:$E$1001,$B40) -> 0 | E40: =IFERROR(D40/C40,0) -> 0 | F40: =COUNTIFS(DATA!$E$2:$E$1001,$B40,DATA!$H$2:$H$1001,"BM") -> 0 | G40: =COUNTIFS(DATA!$E$2:$E$1001,$B40,DATA!$H$2:$H$1001,"CRO") -> 0 | H40: =COUNTIFS(DATA!$E$2:$E$1001,$B40,DATA!$H$2:$H$1001,"BAO") -> 0 | I40: =IF($D40=0,"-",COUNTIFS(DATA!$E$2:$E$1001,$B40,DATA!$I$2:$I$1001,"MUDAH")/$D40) -> - | J40: =IF($D40=0,"-",COUNTIFS(DATA!$E$2:$E$1001,$B40,DATA!$J$2:$J$1001,"YA")/$D40) -> - | K40: =IF($D40=0,"-",COUNTIFS(DATA!$E$2:$E$1001,$B40,DATA!$K$2:$K$1001,"MUDAH")/$D40) -> - | L40: =IFERROR(AVERAGEIFS(DATA!$S$2:$S$1001,DATA!$E$2:$E$1001,$B40),"-") -> - | M40: =IF(D40=0,"Belum isi","") -> Belum isi
... A56: 28 | B56: =PROGRES!B50 -> WONOGIRI | C56: =PROGRES!C50 -> 5 | D56: =COUNTIF(DATA!$E$2:$E$1001,$B56) -> 3 | E56: =IFERROR(D56/C56,0) -> 0.6 | F56: =COUNTIFS(DATA!$E$2:$E$1001,$B56,DATA!$H$2:$H$1001,"BM") -> 1 | G56: =COUNTIFS(DATA!$E$2:$E$1001,$B56,DATA!$H$2:$H$1001,"CRO") -> 1 | H56: =COUNTIFS(DATA!$E$2:$E$1001,$B56,DATA!$H$2:$H$1001,"BAO") -> 1 | I56: =IF($D56=0,"-",COUNTIFS(DATA!$E$2:$E$1001,$B56,DATA!$I$2:$I$1001,"MUDAH")/$D56) -> 1 | J56: =IF($D56=0,"-",COUNTIFS(DATA!$E$2:$E$1001,$B56,DATA!$J$2:$J$1001,"YA")/$D56) -> 1 | K56: =IF($D56=0,"-",COUNTIFS(DATA!$E$2:$E$1001,$B56,DATA!$K$2:$K$1001,"MUDAH")/$D56) -> 0.66666667 | L56: =IFERROR(AVERAGEIFS(DATA!$S$2:$S$1001,DATA!$E$2:$E$1001,$B56),"-") -> 2.8888889 | M56: =IF(D56=0,"Belum isi","")
B57: Subtotal Jawa Tengah | C57: =SUM(C29:C56) -> 158 | D57: =SUM(D29:D56) -> 92 | E57: =IFERROR(D57/C57,0) -> 0.58227848 | F57: =SUM(F29:F56) -> 22 | G57: =SUM(G29:G56) -> 50 | H57: =SUM(H29:H56) -> 20 | I57: =IFERROR(COUNTIFS(DATA!$F$2:$F$1001,"Jawa Tengah",DATA!$I$2:$I$1001,"MUDAH")/$D57,"-") -> 0.5326087 | J57: =IFERROR(COUNTIFS(DATA!$F$2:$F$1001,"Jawa Tengah",DATA!$J$2:$J$1001,"YA")/$D57,"-") -> 0.5326087 | K57: =IFERROR(COUNTIFS(DATA!$F$2:$F$1001,"Jawa Tengah",DATA!$K$2:$K$1001,"MUDAH")/$D57,"-") -> 0.52173913 | L57: =IFERROR(AVERAGEIFS(DATA!$S$2:$S$1001,DATA!$F$2:$F$1001,"Jawa Tengah"),"-") -> 2.5253623 | M57: =COUNTIF(M29:M56,"Belum isi")&" cabang belum isi" -> 6 cabang belum isi
A59: JAWA TIMUR
A60: 1 | B60: =PROGRES!B51 -> GOLOMANTUNG | C60: =PROGRES!C51 -> 6 | D60: =COUNTIF(DATA!$E$2:$E$1001,$B60) -> 4 | E60: =IFERROR(D60/C60,0) -> 0.66666667 | F60: =COUNTIFS(DATA!$E$2:$E$1001,$B60,DATA!$H$2:$H$1001,"BM") -> 1 | G60: =COUNTIFS(DATA!$E$2:$E$1001,$B60,DATA!$H$2:$H$1001,"CRO") -> 2 | H60: =COUNTIFS(DATA!$E$2:$E$1001,$B60,DATA!$H$2:$H$1001,"BAO") -> 1 | I60: =IF($D60=0,"-",COUNTIFS(DATA!$E$2:$E$1001,$B60,DATA!$I$2:$I$1001,"MUDAH")/$D60) -> 0.75 | J60: =IF($D60=0,"-",COUNTIFS(DATA!$E$2:$E$1001,$B60,DATA!$J$2:$J$1001,"YA")/$D60) -> 0.75 | K60: =IF($D60=0,"-",COUNTIFS(DATA!$E$2:$E$1001,$B60,DATA!$K$2:$K$1001,"MUDAH")/$D60) -> 0.75 | L60: =IFERROR(AVERAGEIFS(DATA!$S$2:$S$1001,DATA!$E$2:$E$1001,$B60),"-") -> 2.6666667 | M60: =IF(D60=0,"Belum isi","")
A61: 2 | B61: =PROGRES!B52 -> MOJOKERTO | C61: =PROGRES!C52 -> 6 | D61: =COUNTIF(DATA!$E$2:$E$1001,$B61) -> 0 | E61: =IFERROR(D61/C61,0) -> 0 | F61: =COUNTIFS(DATA!$E$2:$E$1001,$B61,DATA!$H$2:$H$1001,"BM") -> 0 | G61: =COUNTIFS(DATA!$E$2:$E$1001,$B61,DATA!$H$2:$H$1001,"CRO") -> 0 | H61: =COUNTIFS(DATA!$E$2:$E$1001,$B61,DATA!$H$2:$H$1001,"BAO") -> 0 | I61: =IF($D61=0,"-",COUNTIFS(DATA!$E$2:$E$1001,$B61,DATA!$I$2:$I$1001,"MUDAH")/$D61) -> - | J61: =IF($D61=0,"-",COUNTIFS(DATA!$E$2:$E$1001,$B61,DATA!$J$2:$J$1001,"YA")/$D61) -> - | K61: =IF($D61=0,"-",COUNTIFS(DATA!$E$2:$E$1001,$B61,DATA!$K$2:$K$1001,"MUDAH")/$D61) -> - | L61: =IFERROR(AVERAGEIFS(DATA!$S$2:$S$1001,DATA!$E$2:$E$1001,$B61),"-") -> - | M61: =IF(D61=0,"Belum isi","") -> Belum isi
A62: 3 | B62: =PROGRES!B53 -> PAMEKASAN | C62: =PROGRES!C53 -> 5 | D62: =COUNTIF(DATA!$E$2:$E$1001,$B62) -> 1 | E62: =IFERROR(D62/C62,0) -> 0.2 | F62: =COUNTIFS(DATA!$E$2:$E$1001,$B62,DATA!$H$2:$H$1001,"BM") -> 0 | G62: =COUNTIFS(DATA!$E$2:$E$1001,$B62,DATA!$H$2:$H$1001,"CRO") -> 0 | H62: =COUNTIFS(DATA!$E$2:$E$1001,$B62,DATA!$H$2:$H$1001,"BAO") -> 1 | I62: =IF($D62=0,"-",COUNTIFS(DATA!$E$2:$E$1001,$B62,DATA!$I$2:$I$1001,"MUDAH")/$D62) -> 1 | J62: =IF($D62=0,"-",COUNTIFS(DATA!$E$2:$E$1001,$B62,DATA!$J$2:$J$1001,"YA")/$D62) -> 1 | K62: =IF($D62=0,"-",COUNTIFS(DATA!$E$2:$E$1001,$B62,DATA!$K$2:$K$1001,"MUDAH")/$D62) -> 1 | L62: =IFERROR(AVERAGEIFS(DATA!$S$2:$S$1001,DATA!$E$2:$E$1001,$B62),"-") -> 3 | M62: =IF(D62=0,"Belum isi","")
A63: 4 | B63: =PROGRES!B54 -> SAMPANG | C63: =PROGRES!C54 -> 5 | D63: =COUNTIF(DATA!$E$2:$E$1001,$B63) -> 2 | E63: =IFERROR(D63/C63,0) -> 0.4 | F63: =COUNTIFS(DATA!$E$2:$E$1001,$B63,DATA!$H$2:$H$1001,"BM") -> 1 | G63: =COUNTIFS(DATA!$E$2:$E$1001,$B63,DATA!$H$2:$H$1001,"CRO") -> 0 | H63: =COUNTIFS(DATA!$E$2:$E$1001,$B63,DATA!$H$2:$H$1001,"BAO") -> 1 | I63: =IF($D63=0,"-",COUNTIFS(DATA!$E$2:$E$1001,$B63,DATA!$I$2:$I$1001,"MUDAH")/$D63) -> 0.5 | J63: =IF($D63=0,"-",COUNTIFS(DATA!$E$2:$E$1001,$B63,DATA!$J$2:$J$1001,"YA")/$D63) -> 1 | K63: =IF($D63=0,"-",COUNTIFS(DATA!$E$2:$E$1001,$B63,DATA!$K$2:$K$1001,"MUDAH")/$D63) -> 0.5 | L63: =IFERROR(AVERAGEIFS(DATA!$S$2:$S$1001,DATA!$E$2:$E$1001,$B63),"-") -> 2.6666667 | M63: =IF(D63=0,"Belum isi","")
A64: 5 | B64: =PROGRES!B55 -> SIDAYU | C64: =PROGRES!C55 -> 5 | D64: =COUNTIF(DATA!$E$2:$E$1001,$B64) -> 2 | E64: =IFERROR(D64/C64,0) -> 0.4 | F64: =COUNTIFS(DATA!$E$2:$E$1001,$B64,DATA!$H$2:$H$1001,"BM") -> 1 | G64: =COUNTIFS(DATA!$E$2:$E$1001,$B64,DATA!$H$2:$H$1001,"CRO") -> 1 | H64: =COUNTIFS(DATA!$E$2:$E$1001,$B64,DATA!$H$2:$H$1001,"BAO") -> 0 | I64: =IF($D64=0,"-",COUNTIFS(DATA!$E$2:$E$1001,$B64,DATA!$I$2:$I$1001,"MUDAH")/$D64) -> 0.5 | J64: =IF($D64=0,"-",COUNTIFS(DATA!$E$2:$E$1001,$B64,DATA!$J$2:$J$1001,"YA")/$D64) -> 1 | K64: =IF($D64=0,"-",COUNTIFS(DATA!$E$2:$E$1001,$B64,DATA!$K$2:$K$1001,"MUDAH")/$D64) -> 0 | L64: =IFERROR(AVERAGEIFS(DATA!$S$2:$S$1001,DATA!$E$2:$E$1001,$B64),"-") -> 2.5 | M64: =IF(D64=0,"Belum isi","")
A65: 6 | B65: =PROGRES!B56 -> SIDOARJO | C65: =PROGRES!C56 -> 8 | D65: =COUNTIF(DATA!$E$2:$E$1001,$B65) -> 0 | E65: =IFERROR(D65/C65,0) -> 0 | F65: =COUNTIFS(DATA!$E$2:$E$1001,$B65,DATA!$H$2:$H$1001,"BM") -> 0 | G65: =COUNTIFS(DATA!$E$2:$E$1001,$B65,DATA!$H$2:$H$1001,"CRO") -> 0 | H65: =COUNTIFS(DATA!$E$2:$E$1001,$B65,DATA!$H$2:$H$1001,"BAO") -> 0 | I65: =IF($D65=0,"-",COUNTIFS(DATA!$E$2:$E$1001,$B65,DATA!$I$2:$I$1001,"MUDAH")/$D65) -> - | J65: =IF($D65=0,"-",COUNTIFS(DATA!$E$2:$E$1001,$B65,DATA!$J$2:$J$1001,"YA")/$D65) -> - | K65: =IF($D65=0,"-",COUNTIFS(DATA!$E$2:$E$1001,$B65,DATA!$K$2:$K$1001,"MUDAH")/$D65) -> - | L65: =IFERROR(AVERAGEIFS(DATA!$S$2:$S$1001,DATA!$E$2:$E$1001,$B65),"-") -> - | M65: =IF(D65=0,"Belum isi","") -> Belum isi
A66: 7 | B66: =PROGRES!B57 -> SUMENEP | C66: =PROGRES!C57 -> 4 | D66: =COUNTIF(DATA!$E$2:$E$1001,$B66) -> 4 | E66: =IFERROR(D66/C66,0) -> 1 | F66: =COUNTIFS(DATA!$E$2:$E$1001,$B66,DATA!$H$2:$H$1001,"BM") -> 1 | G66: =COUNTIFS(DATA!$E$2:$E$1001,$B66,DATA!$H$2:$H$1001,"CRO") -> 2 | H66: =COUNTIFS(DATA!$E$2:$E$1001,$B66,DATA!$H$2:$H$1001,"BAO") -> 1 | I66: =IF($D66=0,"-",COUNTIFS(DATA!$E$2:$E$1001,$B66,DATA!$I$2:$I$1001,"MUDAH")/$D66) -> 0.5 | J66: =IF($D66=0,"-",COUNTIFS(DATA!$E$2:$E$1001,$B66,DATA!$J$2:$J$1001,"YA")/$D66) -> 1 | K66: =IF($D66=0,"-",COUNTIFS(DATA!$E$2:$E$1001,$B66,DATA!$K$2:$K$1001,"MUDAH")/$D66) -> 0.75 | L66: =IFERROR(AVERAGEIFS(DATA!$S$2:$S$1001,DATA!$E$2:$E$1001,$B66),"-") -> 2.75 | M66: =IF(D66=0,"Belum isi","")
...

Sheet DATA
A1: No | B1: Tanggal | C1: Nama | D1: NIK | E1: Cabang | F1: Wilayah | G1: Wilayah (Form) | H1: Jabatan | I1: Navigasi | J1: Tampilan HP | K1: Materi SOP | L1: Harian | M1: Mingguan | N1: Bulanan | O1: Overview | P1: Skor Navigasi | Q1: Skor HP | R1: Skor SOP | S1: Rata-rata | T1: Unik | U1: Cek | V1: Kritik/Saran Tampilan | W1: SOP Belum Ada | X1: Saran Lainnya | Y1: urut | Z1: Kategori Tampilan | AA1: Kategori SOP | AB1: Kategori Saran | AH1: Wilayah | AI1: Wilayah di Form | AK1: Gab: Kecepatan & Akses Website | AL1: Gab: Tampilan di HP (Responsif) | AM1: Gab: Desain, Warna & Font | AN1: Gab: Menu per Jabatan / Navigasi | AO1: Gab: Integrasi dengan SACS / Aplikasi Kerja | AP1: Gab: Fitur Baru (Dashboard / KPI / Database) | AQ1: Gab: Penyederhanaan & Ringkas Isi | AR1: Gab: Penambahan Isi, Materi & Template | AS1: Gab: Tambah Video / Gambar / Flowchart | AT1: Gab: Kontak PIC, Struktur Organisasi & Eskalasi | AU1: Gab: Update & Notifikasi Perubahan SOP | AV1: Gab: Sanksi & Pelanggaran SOP | AW1: Gab: Piutang & Pelanggan Bermasalah | AX1: Gab: Pengiriman, Retur & Logistik | AY1: Gab: Panduan Laporan & Alur Kerja | AZ1: Gab: Saran Umum Peningkatan | BA1: Gab: Lainnya (perlu dibaca manual) | BB1: Gab: Ada Masukan
A2: =IF(INDEX(FORM!$A:$A,ROW())="","",ROW()-1) -> 1 | B2: =IF($A2="","",INDEX(FORM!$A:$A,ROW())) -> 46307.478 | C2: =IF($A2="","",TRIM(INDEX(FORM!$B:$B,ROW()))) -> Pradana Rifti Meidiansyah | D2: =IF($A2="","",TRIM(INDEX(FORM!$C:$C,ROW())&"")) -> 1510669 | E2: =IF($A2="","",UPPER(TRIM(INDEX(FORM!$D:$D,ROW())))) -> MAGETAN | F2: =IF($A2="","",IFERROR(INDEX(PROGRES!$A$2:$A$92,MATCH(E2,PROGRES!$B$2:$B$92,0)),"-")) -> Jawa Timur | G2: =IF($A2="","",UPPER(TRIM(INDEX(FORM!$F:$F,ROW())))) -> JATIM | H2: =IF($A2="","",UPPER(TRIM(INDEX(FORM!$E:$E,ROW())))) -> CRO | I2: =IF($A2="","",UPPER(TRIM(INDEX(FORM!$G:$G,ROW())))) -> MUDAH | J2: =IF($A2="","",IF(ISNUMBER(SEARCH("Ya,",INDEX(FORM!$H:$H,ROW()))),"YA",IF(ISNUMBER(SEARCH("Cukup,",INDEX(FORM!$H:$H,ROW()))),"CUKUP",IF(ISNUMBER(SEARCH("Kurang,",INDEX(FORM!$H:$H,ROW()))),"KURANG","")))) -> YA | K2: =IF($A2="","",UPPER(TRIM(INDEX(FORM!$J:$J,ROW())))) -> MUDAH | L2: =IF($A2="","",IF(ISNUMBER(SEARCH("Aktivitas Harian",INDEX(FORM!$K:$K,ROW()))),1,0)) -> 0 | M2: =IF($A2="","",IF(ISNUMBER(SEARCH("Aktivitas Mingguan",INDEX(FORM!$K:$K,ROW()))),1,0)) -> 0 | N2: =IF($A2="","",IF(ISNUMBER(SEARCH("Aktivitas Bulanan",INDEX(FORM!$K:$K,ROW()))),1,0)) -> 0 | O2: =IF($A2="","",IF(ISNUMBER(SEARCH("Overview Cabang",INDEX(FORM!$K:$K,ROW()))),1,0)) -> 1 | P2: =IF($A2="","",IFERROR(VLOOKUP(I2,DATA!$AH$9:$AI$13,2,0),"")) -> 3 | Q2: =IF($A2="","",IFERROR(VLOOKUP(J2,DATA!$AH$9:$AI$13,2,0),"")) -> 3 | R2: =IF($A2="","",IFERROR(VLOOKUP(K2,DATA!$AH$9:$AI$13,2,0),"")) -> 3 | S2: =IF($A2="","",IFERROR(AVERAGE(P2:R2),"")) -> 3 | T2: =IF($A2="","",IF(COUNTIF($D$2:D2,D2)=1,1,0)) -> 1 | U2: =IF($A2="","",IF(F2="-","Cabang tdk ada",IF(IFERROR(VLOOKUP(G2,#REF!,1,0),"")="","",IF(INDEX(DATA!$AH$2:$AH$5,MATCH(G2,DATA!$AI$2:$AI$5,0))<>F2,"Wilayah beda","OK")))) | V2: =IF($A2="","",TRIM(INDEX(FORM!$I:$I,ROW())&"")) -> Sudah cukup baik untuk tampilan | W2: =IF($A2="","",TRIM(INDEX(FORM!$L:$L,ROW())&"")) -> Semua sudah di terapkan sesuai SOP yang ada | X2: =IF($A2="","",TRIM(INDEX(FORM!$M:$M,ROW())&"")) -> Sudah sangat mudah untuk diakses dan dipahami | Y2: =IF($A2="","",IFERROR(MATCH(F2,DATA!$AH$2:$AH$5,0),9)*10000+A2) -> 30001 | Z2: =IF($A2="","",IF(LEN(SUBSTITUTE(SUBSTITUTE(SUBSTITUTE(V2,"-",""),".",""),"?",""))<2,"Tidak ada masukan / sudah baik",IF(OR(ISNUMBER(SEARCH("memang harus",V2&" "))),"Tidak ada masukan / sudah baik",IF(OR(ISNUMBER(SEARCH("lemot",V2&" ")),ISNUMBER(SEARCH("loading",V2&" ")),ISNUMBER(SEARCH("lambat",V2&" ")),ISNUMBER(SEARCH("kecepatan",V2&" ")),ISNUMBER(SEARCH("koneksi",V2&" ")),ISNUMBER(SEARCH("eroro",V2&" ")),ISNUMBER(SEARCH("error",V2&" ")),ISNUMBER(SEARCH("ketutup",V2&" "))),"Kecepatan & Loading Website",IF(OR(ISNUMBER(SEARCH("kontak",V2&" ")),ISNUMBER(SEARCH("pic",V2&" ")),ISNUMBER(SEARCH("darurat",V2&" "))),"Kontak & Informasi PIC",IF(OR(ISNUMBER(SEARCH("sacs",V2&" ")),ISNUMBER(SEARCH("aplikasi",V2&" ")),ISNUMBER(SEARCH("kinerja",V2&" ")),ISNUMBER(SEARCH("seluruh cabang",V2&" "))),"Integrasi dengan SACS / Aplikasi",IF(OR(ISNUMBER(SEARCH("mobile",V2&" ")),ISNUMBER(SEARCH("lebih responsif",V2&" ")),ISNUMBER(SEARCH("scroll",V2&" ")),ISNUMBER(SEARCH("melebar",V2&" "))),"Tampilan di HP (Responsif)",IF(OR(ISNUMBER(SEARCH("simpel",V2&" ")),ISNUMBER(SEARCH("simple",V2&" ")),ISNUMBER(SEARCH("sederhana",V2&" ")),ISNUMBER(SEARCH("ringkas",V2&" ")),ISNUMBER(SEARCH("intinya",V2&" ")),ISNUMBER(SEARCH("panjang lebar",V2&" ")),ISNUMBER(SEARCH("mudah dipahami lagi",V2&" ")),ISNUMBER(SEARCH("tata letak",V2&" ")),ISNUMBER(SEARCH("harus mencari",V2&" "))),"Penyederhanaan & Ringkas Isi",IF(OR(ISNUMBER(SEARCH("menu ",V2&" ")),ISNUMBER(SEARCH("tiap posisi",V2&" ")),ISNUMBER(SEARCH("pilihan antara",V2&" "))),"Menu per Jabatan / Navigasi",IF(OR(ISNUMBER(SEARCH("video",V2&" ")),ISNUMBER(SEARCH("vidio",V2&" ")),ISNUMBER(SEARCH("bagan",V2&" ")),ISNUMBER(SEARCH("gambar",V2&" ")),ISNUMBER(SEARCH("qna",V2&" "))),"Tambah Video / Bagan",IF(OR(ISNUMBER(SEARCH("menarik",V2&" ")),ISNUMBER(SEARCH("design",V2&" ")),ISNUMBER(SEARCH("desain",V2&" ")),ISNUMBER(SEARCH("font",V2&" ")),ISNUMBER(SEARCH("warna",V2&" ")),ISNUMBER(SEARCH("soft",V2&" ")),ISNUMBER(SEARCH("kaku",V2&" ")),ISNUMBER(SEARCH("elegan",V2&" ")),ISNUMBER(SEARCH("grafis",V2&" ")),ISNUMBER(SEARCH("visual",V2&" ")),ISNUMBER(SEARCH("logo",V2&" ")),ISNUMBER(SEARCH("jenuh",V2&" ")),ISNUMBER(SEARCH("abu",V2&" ")),ISNUMBER(SEARCH("tampilannya",V2&" ")),ISNUMBER(SEARCH("tampilan dibuat",V2&" ")),ISNUMBER(SEARCH("tamoilan",V2&" ")),ISNUMBER(SEARCH("lebih user friendly",V2&" "))),"Desain, Warna & Font",IF(OR(ISNUMBER(SEARCH("perbanyak",V2&" ")),ISNUMBER(SEARCH("jabarkan",V2&" ")),ISNUMBER(SEARCH("jobdesk",V2&" ")),ISNUMBER(SEARCH("pengajuan",V2&" ")),ISNUMBER(SEARCH("informasi",V2&" "))),"Penambahan Isi / Penjelasan",IF(OR(ISNUMBER(SEARCH("tingkat",V2&" ")),ISNUMBER(SEARCH("kembang",V2&" ")),ISNUMBER(SEARCH("lebih baik lagi",V2&" ")),ISNUMBER(SEARCH("maksimal",V2&" ")),ISNUMBER(SEARCH("penikatan",V2&" "))),"Saran Umum Peningkatan",IF(OR(ISNUMBER(SEARCH("tidak",V2&" ")),ISNUMBER(SEARCH("tdk",V2&" ")),ISNUMBER(SEARCH("sudah",V2&" ")),ISNUMBER(SEARCH("sdh",V2&" ")),ISNUMBER(SEARCH("cukup",V2&" ")),ISNUMBER(SEARCH("baik",V2&" ")),ISNUMBER(SEARCH("bagus",V2&" ")),ISNUMBER(SEARCH("ok",V2&" ")),ISNUMBER(SEARCH("good",V2&" ")),ISNUMBER(SEARCH("aman",V2&" ")),ISNUMBER(SEARCH("lanjut",V2&" ")),ISNUMBER(SEARCH("mantap",V2&" ")),ISNUMBER(SEARCH("josjis",V2&" ")),ISNUMBER(SEARCH("lumayan",V2&" ")),ISNUMBER(SEARCH("mudah",V2&" ")),ISNUMBER(SEARCH("belum",V2&" ")),ISNUMBER(SEARCH("membantu",V2&" ")),ISNUMBER(SEARCH("comment",V2&" ")),ISNUMBER(SEARCH("lengkap",V2&" ")),ISNUMBER(SEARCH("tercakup",V2&" ")),ISNUMBER(SEARCH("mencakup",V2&" ")),ISNUMBER(SEARCH("semua",V2&" ")),ISNUMBER(SEARCH("penting",V2&" ")),ISNUMBER(SEARCH("terangkum",V2&" ")),ISNUMBER(SEARCH("pas",V2&" ")),ISNUMBER(SEARCH("berjalan",V2&" ")),ISNUMBER(SEARCH("sesuai",V2&" "))),"Tidak ada masukan / sudah baik","Lainnya (perlu dibaca manual)")))))))))))))) -> Tidak ada masukan / sudah baik | AA2: =IF($A2="","",IF(LEN(SUBSTITUTE(SUBSTITUTE(SUBSTITUTE(W2,"-",""),".",""),"?",""))<2,"Tidak ada masukan / sudah baik",IF(OR(ISNUMBER(SEARCH("tampilan",W2&" ")),ISNUMBER(SEARCH("lemot",W2&" "))),"Bukan Terkait SOP (Tampilan / Akses)",IF(OR(ISNUMBER(SEARCH("sanksi",W2&" ")),ISNUMBER(SEARCH("pelanggaran",W2&" ")),ISNUMBER(SEARCH("larangan",W2&" ")),ISNUMBER(SEARCH("rekening pribadi",W2&" "))),"Sanksi & Pelanggaran SOP",IF(OR(ISNUMBER(SEARCH("npl",W2&" ")),ISNUMBER(SEARCH("piutang",W2&" ")),ISNUMBER(SEARCH("rekon",W2&" ")),ISNUMBER(SEARCH("overdue",W2&" ")),ISNUMBER(SEARCH("restruk",W2&" ")),ISNUMBER(SEARCH("tempo",W2&" "))),"Piutang & Pelanggan Bermasalah",IF(OR(ISNUMBER(SEARCH("kiriman",W2&" ")),ISNUMBER(SEARCH("pengiriman",W2&" ")),ISNUMBER(SEARCH("retur",W2&" ")),ISNUMBER(SEARCH("barang",W2&" "))),"Pengiriman, Retur & Logistik",IF(OR(ISNUMBER(SEARCH("contact",W2&" ")),ISNUMBER(SEARCH("kontak",W2&" ")),ISNUMBER(SEARCH("pic",W2&" ")),ISNUMBER(SEARCH("berwenang",W2&" ")),ISNUMBER(SEARCH("follow up",W2&" ")),ISNUMBER(SEARCH("eskalasi",W2&" "))),"Kontak PIC & Eskalasi",IF(OR(ISNUMBER(SEARCH("laporan evaluasi",W2&" ")),ISNUMBER(SEARCH("aplikasi cp",W2&" ")),ISNUMBER(SEARCH("flowchart",W2&" ")),ISNUMBER(SEARCH("acuan",W2&" ")),ISNUMBER(SEARCH("poa",W2&" ")),ISNUMBER(SEARCH("aktifitas",W2&" ")),ISNUMBER(SEARCH("aktivitas",W2&" "))),"Panduan Laporan & Alur Kerja",IF(OR(ISNUMBER(SEARCH("notifikasi",W2&" ")),ISNUMBER(SEARCH("pembaruan",W2&" ")),ISNUMBER(SEARCH("perubahan",W2&" ")),ISNUMBER(SEARCH("update",W2&" "))),"Pembaruan & Notifikasi SOP",IF(OR(ISNUMBER(SEARCH("tidak",W2&" ")),ISNUMBER(SEARCH("tdk",W2&" ")),ISNUMBER(SEARCH("sudah",W2&" ")),ISNUMBER(SEARCH("sdh",W2&" ")),ISNUMBER(SEARCH("cukup",W2&" ")),ISNUMBER(SEARCH("baik",W2&" ")),ISNUMBER(SEARCH("bagus",W2&" ")),ISNUMBER(SEARCH("ok",W2&" ")),ISNUMBER(SEARCH("good",W2&" ")),ISNUMBER(SEARCH("aman",W2&" ")),ISNUMBER(SEARCH("lanjut",W2&" ")),ISNUMBER(SEARCH("mantap",W2&" ")),ISNUMBER(SEARCH("josjis",W2&" ")),ISNUMBER(SEARCH("lumayan",W2&" ")),ISNUMBER(SEARCH("mudah",W2&" ")),ISNUMBER(SEARCH("belum",W2&" ")),ISNUMBER(SEARCH("membantu",W2&" ")),ISNUMBER(SEARCH("comment",W2&" ")),ISNUMBER(SEARCH("lengkap",W2&" ")),ISNUMBER(SEARCH("tercakup",W2&" ")),ISNUMBER(SEARCH("mencakup",W2&" ")),ISNUMBER(SEARCH("semua",W2&" ")),ISNUMBER(SEARCH("penting",W2&" ")),ISNUMBER(SEARCH("terangkum",W2&" ")),ISNUMBER(SEARCH("pas",W2&" ")),ISNUMBER(SEARCH("berjalan",W2&" ")),ISNUMBER(SEARCH("sesuai",W2&" "))),"Tidak ada masukan / sudah baik","Lainnya (perlu dibaca manual)")))))))))) -> Tidak ada masukan / sudah baik | AB2: =IF($A2="","",IF(LEN(SUBSTITUTE(SUBSTITUTE(SUBSTITUTE(X2,"-",""),".",""),"?",""))<2,"Tidak ada masukan / sudah baik",IF(OR(ISNUMBER(SEARCH("urgent",X2&" "))),"Lainnya (perlu dibaca manual)",IF(OR(ISNUMBER(SEARCH("struktur organisasi",X2&" ")),ISNUMBER(SEARCH("pic",X2&" ")),ISNUMBER(SEARCH("cp",X2&" ")),ISNUMBER(SEARCH("personil",X2&" ")),ISNUMBER(SEARCH("sales",X2&" ")),ISNUMBER(SEARCH("muka",X2&" ")),ISNUMBER(SEARCH("eskalasi",X2&" "))),"Struktur Organisasi, PIC & Tim",IF(OR(ISNUMBER(SEARCH("lemot",X2&" ")),ISNUMBER(SEARCH("lambat",X2&" ")),ISNUMBER(SEARCH("memuat",X2&" ")),ISNUMBER(SEARCH("koneksi",X2&" "))),"Kecepatan Akses Website",IF(OR(ISNUMBER(SEARCH("sacs",X2&" ")),ISNUMBER(SEARCH("aplikasi",X2&" "))),"Integrasi ke SACS / Aplikasi Kerja",IF(OR(ISNUMBER(SEARCH("dashboard",X2&" ")),ISNUMBER(SEARCH("kpi",X2&" ")),ISNUMBER(SEARCH("database",X2&" ")),ISNUMBER(SEARCH("kinerja",X2&" ")),ISNUMBER(SEARCH("seluruh cabang",X2&" "))),"Fitur Baru (Dashboard / KPI / Database)",IF(OR(ISNUMBER(SEARCH("video",X2&" ")),ISNUMBER(SEARCH("gambar",X2&" ")),ISNUMBER(SEARCH("jpg",X2&" ")),ISNUMBER(SEARCH("flowchart",X2&" ")),ISNUMBER(SEARCH("tutorial",X2&" "))),"Tambah Video / Gambar / Flowchart",IF(OR(ISNUMBER(SEARCH("template",X2&" ")),ISNUMBER(SEARCH("surat",X2&" ")),ISNUMBER(SEARCH("korin",X2&" ")),ISNUMBER(SEARCH("overdue",X2&" ")),ISNUMBER(SEARCH("restruk",X2&" ")),ISNUMBER(SEARCH("tempo",X2&" ")),ISNUMBER(SEARCH("larangan",X2&" ")),ISNUMBER(SEARCH("posisi lain",X2&" ")),ISNUMBER(SEARCH("jobdesk",X2&" ")),ISNUMBER(SEARCH("jobdisk",X2&" ")),ISNUMBER(SEARCH("langkah",X2&" ")),ISNUMBER(SEARCH("detail",X2&" ")),ISNUMBER(SEARCH("panduan",X2&" ")),ISNUMBER(SEARCH("lengkap lagi",X2&" ")),ISNUMBER(SEARCH("tips",X2&" "))),"Penambahan Materi & Template",IF(OR(ISNUMBER(SEARCH("simpel",X2&" ")),ISNUMBER(SEARCH("simple",X2&" ")),ISNUMBER(SEARCH("ringkas",X2&" ")),ISNUMBER(SEARCH("monoton",X2&" ")),ISNUMBER(SEARCH("penataan",X2&" "))),"Penyederhanaan Isi",IF(OR(ISNUMBER(SEARCH("menarik",X2&" ")),ISNUMBER(SEARCH("design",X2&" ")),ISNUMBER(SEARCH("desain",X2&" ")),ISNUMBER(SEARCH("tampilan",X2&" ")),ISNUMBER(SEARCH("kaku",X2&" ")),ISNUMBER(SEARCH("user friendly",X2&" "))),"Desain Tampilan",IF(OR(ISNUMBER(SEARCH("update",X2&" ")),ISNUMBER(SEARCH("terbaru",X2&" ")),ISNUMBER(SEARCH("terkini",X2&" ")),ISNUMBER(SEARCH("uptodate",X2&" "))),"Update Informasi Berkala",IF(OR(ISNUMBER(SEARCH("tingkat",X2&" ")),ISNUMBER(SEARCH("kembang",X2&" ")),ISNUMBER(SEARCH("inovasi",X2&" ")),ISNUMBER(SEARCH("maintenance",X2&" "))),"Saran Umum Peningkatan",IF(OR(ISNUMBER(SEARCH("tidak",X2&" ")),ISNUMBER(SEARCH("tdk",X2&" ")),ISNUMBER(SEARCH("sudah",X2&" ")),ISNUMBER(SEARCH("sdh",X2&" ")),ISNUMBER(SEARCH("cukup",X2&" ")),ISNUMBER(SEARCH("baik",X2&" ")),ISNUMBER(SEARCH("bagus",X2&" ")),ISNUMBER(SEARCH("ok",X2&" ")),ISNUMBER(SEARCH("good",X2&" ")),ISNUMBER(SEARCH("aman",X2&" ")),ISNUMBER(SEARCH("lanjut",X2&" ")),ISNUMBER(SEARCH("mantap",X2&" ")),ISNUMBER(SEARCH("josjis",X2&" ")),ISNUMBER(SEARCH("lumayan",X2&" ")),ISNUMBER(SEARCH("mudah",X2&" ")),ISNUMBER(SEARCH("belum",X2&" ")),ISNUMBER(SEARCH("membantu",X2&" ")),ISNUMBER(SEARCH("comment",X2&" ")),ISNUMBER(SEARCH("lengkap",X2&" ")),ISNUMBER(SEARCH("tercakup",X2&" ")),ISNUMBER(SEARCH("mencakup",X2&" ")),ISNUMBER(SEARCH("semua",X2&" ")),ISNUMBER(SEARCH("penting",X2&" ")),ISNUMBER(SEARCH("terangkum",X2&" ")),ISNUMBER(SEARCH("pas",X2&" ")),ISNUMBER(SEARCH("berjalan",X2&" ")),ISNUMBER(SEARCH("sesuai",X2&" "))),"Tidak ada masukan / sudah baik","Lainnya (perlu dibaca manual)")))))))))))))) -> Tidak ada masukan / sudah baik | AH2: Jawa Barat | AI2: JABAR DKI BANTEN | AK2: =IF($A2="","",IF(OR($Z2="Kecepatan & Loading Website",$AB2="Kecepatan Akses Website",AND($AA2="Bukan Terkait SOP (Tampilan / Akses)",OR(ISNUMBER(SEARCH("lemot",$W2)),ISNUMBER(SEARCH("loading",$W2)),ISNUMBER(SEARCH("lambat",$W2))))),1,0)) -> 0 | AL2: =IF($A2="","",IF(OR($Z2="Tampilan di HP (Responsif)"),1,0)) -> 0 | AM2: =IF($A2="","",IF(OR($Z2="Desain, Warna & Font",$AB2="Desain Tampilan",AND($AA2="Bukan Terkait SOP (Tampilan / Akses)",NOT(OR(ISNUMBER(SEARCH("lemot",$W2)),ISNUMBER(SEARCH("loading",$W2)),ISNUMBER(SEARCH("lambat",$W2)))))),1,0)) -> 0 | AN2: =IF($A2="","",IF(OR($Z2="Menu per Jabatan / Navigasi"),1,0)) -> 0 | AO2: =IF($A2="","",IF(OR($Z2="Integrasi dengan SACS / Aplikasi",$AB2="Integrasi ke SACS / Aplikasi Kerja"),1,0)) -> 0 | AP2: =IF($A2="","",IF(OR($AB2="Fitur Baru (Dashboard / KPI / Database)"),1,0)) -> 0 | AQ2: =IF($A2="","",IF(OR($Z2="Penyederhanaan & Ringkas Isi",$AB2="Penyederhanaan Isi"),1,0)) -> 0 | AR2: =IF($A2="","",IF(OR($Z2="Penambahan Isi / Penjelasan",$AB2="Penambahan Materi & Template"),1,0)) -> 0 | AS2: =IF($A2="","",IF(OR($Z2="Tambah Video / Bagan",$AB2="Tambah Video / Gambar / Flowchart"),1,0)) -> 0 | AT2: =IF($A2="","",IF(OR($Z2="Kontak & Informasi PIC",$AA2="Kontak PIC & Eskalasi",$AB2="Struktur Organisasi, PIC & Tim"),1,0)) -> 0 | AU2: =IF($A2="","",IF(OR($AA2="Pembaruan & Notifikasi SOP",$AB2="Update Informasi Berkala"),1,0)) -> 0 | AV2: =IF($A2="","",IF(OR($AA2="Sanksi & Pelanggaran SOP"),1,0)) -> 0 | AW2: =IF($A2="","",IF(OR($AA2="Piutang & Pelanggan Bermasalah"),1,0)) -> 0 | AX2: =IF($A2="","",IF(OR($AA2="Pengiriman, Retur & Logistik"),1,0)) -> 0 | AY2: =IF($A2="","",IF(OR($AA2="Panduan Laporan & Alur Kerja"),1,0)) -> 0 | AZ2: =IF($A2="","",IF(OR($Z2="Saran Umum Peningkatan",$AB2="Saran Umum Peningkatan"),1,0)) -> 0 | BA2: =IF($A2="","",IF(OR($Z2="Lainnya (perlu dibaca manual)",$AA2="Lainnya (perlu dibaca manual)",$AB2="Lainnya (perlu dibaca manual)"),1,0)) -> 0 | BB2: =IF($A2="","",IF(AND($Z2="Tidak ada masukan / sudah baik",$AA2="Tidak ada masukan / sudah baik",$AB2="Tidak ada masukan / sudah baik"),0,1)) -> 0
